Workbook

Sheet Dashboard
B2: R5B AMP KITTING CONTROL | P2: DATE | Q2: =TODAY() -> 46300
B3: CONTRACT ▸ | D3: E2A-R12P-T5-C | G3: TOTAL REPS | H3: =IFERROR(INDEX(Contracts!$F$6:$F$65,MATCH(Dashboard!$D$3,Contracts!$A$6:$A$65,0)),0) -> 109 | I3: AMPS / REP | J3: =IFERROR(INDEX(Contracts!$E$6:$E$65,MATCH(Dashboard!$D$3,Contracts!$A$6:$A$65,0)),0) -> 12 | P3: AS OF ▸ | Q3: =Q2-WEEKDAY(Q2,2)+1 -> 46300 | S3: =IFERROR(N(INDEX(Contracts!$Q$6:$Q$65,MATCH(Dashboard!$D$3,Contracts!$A$6:$A$65,0))),2) -> 2
B4: =IFERROR(INDEX(Contracts!$B$6:$B$65,MATCH(Dashboard!$D$3,Contracts!$A$6:$A$65,0))&" · top code "&INDEX(Contracts!$C$6:$C$65,MATCH(Dashboard!$D$3,Contracts!$A$6:$A$65,0))&" · "&INDEX(Contracts!$D$6:$D$65,MATCH(Dashboard!$D$3,Contracts!$A$6:$A$65,0))&"FP · "&INDEX(Contracts!$H$6:$H$65,MATCH(Dashboard!$D$3,Contracts!$A$6:$A$65,0))&" sub-assemblies per repeater"&IF(INDEX(Contracts!$G$6:$G$65,MATCH(Dashboard!$D$3,Contracts!$A$6:$A$65,0))&""="",""," · "&INDEX(Contracts!$G$6:$G$65,MATCH(Dashboard!$D$3,Contracts!$A$6:$A$65,0))),"Pick a contract") -> E2A · top code 92ERP12548A++ · 12FP · 14 sub-assemblies per repeater | Q4: ="Week "&_xlfn.ISOWEEKNUM(Q3) -> Week 41
B6: REPEATERS KITTED | D6: AMPS KITTED | E6: PLAN TO DATE | H6: VS PLAN | L6: NEXT 4 WEEKS | O6: LAST RELEASE
B7: =IF(INDEX(Contracts!$H$6:$H$65,MATCH(Dashboard!$D$3,Contracts!$A$6:$A$65,0))=0,"–",INDEX(Contracts!$I$6:$I$65,MATCH(Dashboard!$D$3,Contracts!$A$6:$A$65,0))&" / "&$H$3) -> 13 / 109 | D7: =IFERROR(INDEX(Contracts!$J$6:$J$65,MATCH(Dashboard!$D$3,Contracts!$A$6:$A$65,0)),0) -> 156 | E7: =IFERROR(INDEX(Contracts!$K$6:$K$65,MATCH(Dashboard!$D$3,Contracts!$A$6:$A$65,0)),0) -> 31 | H7: =IFERROR(IF(INDEX(Contracts!$H$6:$H$65,MATCH(Dashboard!$D$3,Contracts!$A$6:$A$65,0))=0,"–",IF(INDEX(Contracts!$L$6:$L$65,MATCH(Dashboard!$D$3,Contracts!$A$6:$A$65,0))>0,"+"&INDEX(Contracts!$L$6:$L$65,MATCH(Dashboard!$D$3,Contracts!$A$6:$A$65,0)),INDEX(Contracts!$L$6:$L$65,MATCH(Dashboard!$D$3,Contracts!$A$6:$A$65,0)))),"–") -> -18 | L7: =SUMIFS('Weekly Plan'!$D$6:$D$1505,'Weekly Plan'!$A$6:$A$1505,Dashboard!$D$3,'Weekly Plan'!$E$6:$E$1505,">"&($Q$3+7*$S$3),'Weekly Plan'!$E$6:$E$1505,"<="&($Q$3+7*$S$3+28)) -> 2 | O7: =IFERROR(INDEX(Contracts!$P$6:$P$65,MATCH(Dashboard!$D$3,Contracts!$A$6:$A$65,0)),"–") -> 46297
B8: =IFERROR(TEXT(INDEX(Contracts!$N$6:$N$65,MATCH(Dashboard!$D$3,Contracts!$A$6:$A$65,0)),"0%")&" of contract · "&($H$3-IFERROR(INDEX(Contracts!$I$6:$I$65,MATCH(Dashboard!$D$3,Contracts!$A$6:$A$65,0)),0))&" to go","add a kit list for this contract") -> 12% of contract · 96 to go | D8: ="of "&TEXT($H$3*$J$3,"#,##0")&" amps ("&$J$3&" per repeater)" -> of 1,308 amps (12 per repeater) | E8: ="kits due by "&$Q$4&" (housing "&"W"&_xlfn.ISOWEEKNUM($Q$3+7*$S$3)&", "&$S$3&"-wk lead)" -> kits due by Week 41 (housing W43, 2-wk lead) | H8: =IFERROR(INDEX(Contracts!$O$6:$O$65,MATCH(Dashboard!$D$3,Contracts!$A$6:$A$65,0)),"") -> BEHIND -18 | L8: ="repeaters to kit next 4 weeks" -> repeaters to kit next 4 weeks | O8: =COUNTIF('Release Log'!$B$6:$B$4005,Dashboard!$D$3)&" release lines logged" -> 182 release lines logged
B10: CONTRACT PROGRESS | D10: =IFERROR(INDEX(Contracts!$N$6:$N$65,MATCH(Dashboard!$D$3,Contracts!$A$6:$A$65,0)),0) -> 0.11926606
B12: SUB-ASSEMBLIES | F12: RELEASE TARGET ▸ | I12: =IFERROR(INDEX(Contracts!$K$6:$K$65,MATCH(D3,Contracts!$A$6:$A$65,0))+L7,0) -> 33 | J12: reps · type to override | L12: PLAN VS KITTED (repeaters, cumulative)
B13: Sequence | C13: Assy Code | D13: Description | E13: Qty / Rep | F13: Released | G13: Repeaters | H13: Toward Next | I13: Needed for Target | J13: To Release
B14: =IFERROR(INDEX('Kit Lists'!$B$6:$B$605,MATCH(Dashboard!$D$3&"|"&1,'Kit Lists'!$G$6:$G$605,0)),"") -> LASER ASSY | C14: =IFERROR(INDEX('Kit Lists'!$C$6:$C$605,MATCH(Dashboard!$D$3&"|"&1,'Kit Lists'!$G$6:$G$605,0)),"") -> 92YLS00548BAA | D14: =IFERROR(INDEX('Kit Lists'!$D$6:$D$605,MATCH(Dashboard!$D$3&"|"&1,'Kit Lists'!$G$6:$G$605,0)),"") -> R5B LASER ASSEMBLY 4P BOAT 1 - E2A | E14: =IFERROR(INDEX('Kit Lists'!$E$6:$E$605,MATCH(Dashboard!$D$3&"|"&1,'Kit Lists'!$G$6:$G$605,0)),"") -> 1 | F14: =IFERROR(INDEX('Kit Lists'!$H$6:$H$605,MATCH(Dashboard!$D$3&"|"&1,'Kit Lists'!$G$6:$G$605,0)),"") -> 13 | G14: =IF(C14="","",INT(F14/E14)) -> 13 | H14: =IF(C14="","",MOD(F14,E14)&" / "&E14) -> 0 / 1 | I14: =IF(C14="","",$I$12*E14) -> 33 | J14: =IF(C14="","",MAX(0,I14-F14)) -> 20
B15: =IFERROR(INDEX('Kit Lists'!$B$6:$B$605,MATCH(Dashboard!$D$3&"|"&2,'Kit Lists'!$G$6:$G$605,0)),"") -> LASER ASSY | C15: =IFERROR(INDEX('Kit Lists'!$C$6:$C$605,MATCH(Dashboard!$D$3&"|"&2,'Kit Lists'!$G$6:$G$605,0)),"") -> 92YLS00548BBA | D15: =IFERROR(INDEX('Kit Lists'!$D$6:$D$605,MATCH(Dashboard!$D$3&"|"&2,'Kit Lists'!$G$6:$G$605,0)),"") -> R5B LASER ASSEMBLY 4P BOAT 2/3 - E2A | E15: =IFERROR(INDEX('Kit Lists'!$E$6:$E$605,MATCH(Dashboard!$D$3&"|"&2,'Kit Lists'!$G$6:$G$605,0)),"") -> 2 | F15: =IFERROR(INDEX('Kit Lists'!$H$6:$H$605,MATCH(Dashboard!$D$3&"|"&2,'Kit Lists'!$G$6:$G$605,0)),"") -> 26 | G15: =IF(C15="","",INT(F15/E15)) -> 13 | H15: =IF(C15="","",MOD(F15,E15)&" / "&E15) -> 0 / 2 | I15: =IF(C15="","",$I$12*E15) -> 66 | J15: =IF(C15="","",MAX(0,I15-F15)) -> 40
B16: =IFERROR(INDEX('Kit Lists'!$B$6:$B$605,MATCH(Dashboard!$D$3&"|"&3,'Kit Lists'!$G$6:$G$605,0)),"") -> PSB ASSY | C16: =IFERROR(INDEX('Kit Lists'!$C$6:$C$605,MATCH(Dashboard!$D$3&"|"&3,'Kit Lists'!$G$6:$G$605,0)),"") -> 91YAF03404AAA | D16: =IFERROR(INDEX('Kit Lists'!$D$6:$D$605,MATCH(Dashboard!$D$3&"|"&3,'Kit Lists'!$G$6:$G$605,0)),"") -> R5B PSB SUB ASSEMBLY 4P-4FP | E16: =IFERROR(INDEX('Kit Lists'!$E$6:$E$605,MATCH(Dashboard!$D$3&"|"&3,'Kit Lists'!$G$6:$G$605,0)),"") -> 3 | F16: =IFERROR(INDEX('Kit Lists'!$H$6:$H$605,MATCH(Dashboard!$D$3&"|"&3,'Kit Lists'!$G$6:$G$605,0)),"") -> 39 | G16: =IF(C16="","",INT(F16/E16)) -> 13 | H16: =IF(C16="","",MOD(F16,E16)&" / "&E16) -> 0 / 3 | I16: =IF(C16="","",$I$12*E16) -> 99 | J16: =IF(C16="","",MAX(0,I16-F16)) -> 60
B17: =IFERROR(INDEX('Kit Lists'!$B$6:$B$605,MATCH(Dashboard!$D$3&"|"&4,'Kit Lists'!$G$6:$G$605,0)),"") -> OPF ASSY | C17: =IFERROR(INDEX('Kit Lists'!$C$6:$C$605,MATCH(Dashboard!$D$3&"|"&4,'Kit Lists'!$G$6:$G$605,0)),"") -> 92YFD04548BAA | D17: =IFERROR(INDEX('Kit Lists'!$D$6:$D$605,MATCH(Dashboard!$D$3&"|"&4,'Kit Lists'!$G$6:$G$605,0)),"") -> R5B OPF ASSEMBLY (4P-4FP) BOAT 1 - E2A | E17: =IFERROR(INDEX('Kit Lists'!$E$6:$E$605,MATCH(Dashboard!$D$3&"|"&4,'Kit Lists'!$G$6:$G$605,0)),"") -> 1 | F17: =IFERROR(INDEX('Kit Lists'!$H$6:$H$605,MATCH(Dashboard!$D$3&"|"&4,'Kit Lists'!$G$6:$G$605,0)),"") -> 13 | G17: =IF(C17="","",INT(F17/E17)) -> 13 | H17: =IF(C17="","",MOD(F17,E17)&" / "&E17) -> 0 / 1 | I17: =IF(C17="","",$I$12*E17) -> 33 | J17: =IF(C17="","",MAX(0,I17-F17)) -> 20
B18: =IFERROR(INDEX('Kit Lists'!$B$6:$B$605,MATCH(Dashboard!$D$3&"|"&5,'Kit Lists'!$G$6:$G$605,0)),"") -> OPF ASSY | C18: =IFERROR(INDEX('Kit Lists'!$C$6:$C$605,MATCH(Dashboard!$D$3&"|"&5,'Kit Lists'!$G$6:$G$605,0)),"") -> 92YFD04548BBA | D18: =IFERROR(INDEX('Kit Lists'!$D$6:$D$605,MATCH(Dashboard!$D$3&"|"&5,'Kit Lists'!$G$6:$G$605,0)),"") -> R5B OPF ASSEMBLY (4P-4FP) BOAT 2/3 - E2A | E18: =IFERROR(INDEX('Kit Lists'!$E$6:$E$605,MATCH(Dashboard!$D$3&"|"&5,'Kit Lists'!$G$6:$G$605,0)),"") -> 2 | F18: =IFERROR(INDEX('Kit Lists'!$H$6:$H$605,MATCH(Dashboard!$D$3&"|"&5,'Kit Lists'!$G$6:$G$605,0)),"") -> 26 | G18: =IF(C18="","",INT(F18/E18)) -> 13 | H18: =IF(C18="","",MOD(F18,E18)&" / "&E18) -> 0 / 2 | I18: =IF(C18="","",$I$12*E18) -> 66 | J18: =IF(C18="","",MAX(0,I18-F18)) -> 40
B19: =IFERROR(INDEX('Kit Lists'!$B$6:$B$605,MATCH(Dashboard!$D$3&"|"&6,'Kit Lists'!$G$6:$G$605,0)),"") -> POB ASSY | C19: =IFERROR(INDEX('Kit Lists'!$C$6:$C$605,MATCH(Dashboard!$D$3&"|"&6,'Kit Lists'!$G$6:$G$605,0)),"") -> 92YWS04548AAA | D19: =IFERROR(INDEX('Kit Lists'!$D$6:$D$605,MATCH(Dashboard!$D$3&"|"&6,'Kit Lists'!$G$6:$G$605,0)),"") -> R5B 4FP POB LUMENTUM SUB ASSEMBLY - E2A | E19: =IFERROR(INDEX('Kit Lists'!$E$6:$E$605,MATCH(Dashboard!$D$3&"|"&6,'Kit Lists'!$G$6:$G$605,0)),"") -> 3 | F19: =IFERROR(INDEX('Kit Lists'!$H$6:$H$605,MATCH(Dashboard!$D$3&"|"&6,'Kit Lists'!$G$6:$G$605,0)),"") -> 39 | G19: =IF(C19="","",INT(F19/E19)) -> 13 | H19: =IF(C19="","",MOD(F19,E19)&" / "&E19) -> 0 / 3 | I19: =IF(C19="","",$I$12*E19) -> 99 | J19: =IF(C19="","",MAX(0,I19-F19)) -> 60
B20: =IFERROR(INDEX('Kit Lists'!$B$6:$B$605,MATCH(Dashboard!$D$3&"|"&7,'Kit Lists'!$G$6:$G$605,0)),"") -> ERBIUM ASSY | C20: =IFERROR(INDEX('Kit Lists'!$C$6:$C$605,MATCH(Dashboard!$D$3&"|"&7,'Kit Lists'!$G$6:$G$605,0)),"") -> 92RRA00548AAA | D20: =IFERROR(INDEX('Kit Lists'!$D$6:$D$605,MATCH(Dashboard!$D$3&"|"&7,'Kit Lists'!$G$6:$G$605,0)),"") -> R5B ERBIUM SPOOL ASSEMBLY - E2A | E20: =IFERROR(INDEX('Kit Lists'!$E$6:$E$605,MATCH(Dashboard!$D$3&"|"&7,'Kit Lists'!$G$6:$G$605,0)),"") -> 24 | F20: =IFERROR(INDEX('Kit Lists'!$H$6:$H$605,MATCH(Dashboard!$D$3&"|"&7,'Kit Lists'!$G$6:$G$605,0)),"") -> 312 | G20: =IF(C20="","",INT(F20/E20)) -> 13 | H20: =IF(C20="","",MOD(F20,E20)&" / "&E20) -> 0 / 24 | I20: =IF(C20="","",$I$12*E20) -> 792 | J20: =IF(C20="","",MAX(0,I20-F20)) -> 480
B21: =IFERROR(INDEX('Kit Lists'!$B$6:$B$605,MATCH(Dashboard!$D$3&"|"&8,'Kit Lists'!$G$6:$G$605,0)),"") -> ERBIUM ASSY | C21: =IFERROR(INDEX('Kit Lists'!$C$6:$C$605,MATCH(Dashboard!$D$3&"|"&8,'Kit Lists'!$G$6:$G$605,0)),"") -> 92YRA01548AAA | D21: =IFERROR(INDEX('Kit Lists'!$D$6:$D$605,MATCH(Dashboard!$D$3&"|"&8,'Kit Lists'!$G$6:$G$605,0)),"") -> R5B ERBIUM ASSEMBLY POSITION 1 | E21: =IFERROR(INDEX('Kit Lists'!$E$6:$E$605,MATCH(Dashboard!$D$3&"|"&8,'Kit Lists'!$G$6:$G$605,0)),"") -> 3 | F21: =IFERROR(INDEX('Kit Lists'!$H$6:$H$605,MATCH(Dashboard!$D$3&"|"&8,'Kit Lists'!$G$6:$G$605,0)),"") -> 39 | G21: =IF(C21="","",INT(F21/E21)) -> 13 | H21: =IF(C21="","",MOD(F21,E21)&" / "&E21) -> 0 / 3 | I21: =IF(C21="","",$I$12*E21) -> 99 | J21: =IF(C21="","",MAX(0,I21-F21)) -> 60
B22: =IFERROR(INDEX('Kit Lists'!$B$6:$B$605,MATCH(Dashboard!$D$3&"|"&9,'Kit Lists'!$G$6:$G$605,0)),"") -> ERBIUM ASSY | C22: =IFERROR(INDEX('Kit Lists'!$C$6:$C$605,MATCH(Dashboard!$D$3&"|"&9,'Kit Lists'!$G$6:$G$605,0)),"") -> 92YRA02548AAA | D22: =IFERROR(INDEX('Kit Lists'!$D$6:$D$605,MATCH(Dashboard!$D$3&"|"&9,'Kit Lists'!$G$6:$G$605,0)),"") -> R5B ERBIUM ASSEMBLY POSITION 2 | E22: =IFERROR(INDEX('Kit Lists'!$E$6:$E$605,MATCH(Dashboard!$D$3&"|"&9,'Kit Lists'!$G$6:$G$605,0)),"") -> 3 | F22: =IFERROR(INDEX('Kit Lists'!$H$6:$H$605,MATCH(Dashboard!$D$3&"|"&9,'Kit Lists'!$G$6:$G$605,0)),"") -> 39 | G22: =IF(C22="","",INT(F22/E22)) -> 13 | H22: =IF(C22="","",MOD(F22,E22)&" / "&E22) -> 0 / 3 | I22: =IF(C22="","",$I$12*E22) -> 99 | J22: =IF(C22="","",MAX(0,I22-F22)) -> 60
B23: =IFERROR(INDEX('Kit Lists'!$B$6:$B$605,MATCH(Dashboard!$D$3&"|"&10,'Kit Lists'!$G$6:$G$605,0)),"") -> ERBIUM ASSY | C23: =IFERROR(INDEX('Kit Lists'!$C$6:$C$605,MATCH(Dashboard!$D$3&"|"&10,'Kit Lists'!$G$6:$G$605,0)),"") -> 92YRA03548AAA | D23: =IFERROR(INDEX('Kit Lists'!$D$6:$D$605,MATCH(Dashboard!$D$3&"|"&10,'Kit Lists'!$G$6:$G$605,0)),"") -> R5B ERBIUM ASSEMBLY POSITION 3 | E23: =IFERROR(INDEX('Kit Lists'!$E$6:$E$605,MATCH(Dashboard!$D$3&"|"&10,'Kit Lists'!$G$6:$G$605,0)),"") -> 3 | F23: =IFERROR(INDEX('Kit Lists'!$H$6:$H$605,MATCH(Dashboard!$D$3&"|"&10,'Kit Lists'!$G$6:$G$605,0)),"") -> 39 | G23: =IF(C23="","",INT(F23/E23)) -> 13 | H23: =IF(C23="","",MOD(F23,E23)&" / "&E23) -> 0 / 3 | I23: =IF(C23="","",$I$12*E23) -> 99 | J23: =IF(C23="","",MAX(0,I23-F23)) -> 60
B24: =IFERROR(INDEX('Kit Lists'!$B$6:$B$605,MATCH(Dashboard!$D$3&"|"&11,'Kit Lists'!$G$6:$G$605,0)),"") -> ERBIUM ASSY | C24: =IFERROR(INDEX('Kit Lists'!$C$6:$C$605,MATCH(Dashboard!$D$3&"|"&11,'Kit Lists'!$G$6:$G$605,0)),"") -> 92YRA04548AAA | D24: =IFERROR(INDEX('Kit Lists'!$D$6:$D$605,MATCH(Dashboard!$D$3&"|"&11,'Kit Lists'!$G$6:$G$605,0)),"") -> R5B ERBIUM ASSEMBLY POSITION 4 | E24: =IFERROR(INDEX('Kit Lists'!$E$6:$E$605,MATCH(Dashboard!$D$3&"|"&11,'Kit Lists'!$G$6:$G$605,0)),"") -> 3 | F24: =IFERROR(INDEX('Kit Lists'!$H$6:$H$605,MATCH(Dashboard!$D$3&"|"&11,'Kit Lists'!$G$6:$G$605,0)),"") -> 39 | G24: =IF(C24="","",INT(F24/E24)) -> 13 | H24: =IF(C24="","",MOD(F24,E24)&" / "&E24) -> 0 / 3 | I24: =IF(C24="","",$I$12*E24) -> 99 | J24: =IF(C24="","",MAX(0,I24-F24)) -> 60
B25: =IFERROR(INDEX('Kit Lists'!$B$6:$B$605,MATCH(Dashboard!$D$3&"|"&12,'Kit Lists'!$G$6:$G$605,0)),"") -> BOAT ASSY | C25: =IFERROR(INDEX('Kit Lists'!$C$6:$C$605,MATCH(Dashboard!$D$3&"|"&12,'Kit Lists'!$G$6:$G$605,0)),"") -> 92UAP04548BAA | D25: =IFERROR(INDEX('Kit Lists'!$D$6:$D$605,MATCH(Dashboard!$D$3&"|"&12,'Kit Lists'!$G$6:$G$605,0)),"") -> R5B BOAT 1 ASSY (4P-4FP) | E25: =IFERROR(INDEX('Kit Lists'!$E$6:$E$605,MATCH(Dashboard!$D$3&"|"&12,'Kit Lists'!$G$6:$G$605,0)),"") -> 1 | F25: =IFERROR(INDEX('Kit Lists'!$H$6:$H$605,MATCH(Dashboard!$D$3&"|"&12,'Kit Lists'!$G$6:$G$605,0)),"") -> 13 | G25: =IF(C25="","",INT(F25/E25)) -> 13 | H25: =IF(C25="","",MOD(F25,E25)&" / "&E25) -> 0 / 1 | I25: =IF(C25="","",$I$12*E25) -> 33 | J25: =IF(C25="","",MAX(0,I25-F25)) -> 20
B26: =IFERROR(INDEX('Kit Lists'!$B$6:$B$605,MATCH(Dashboard!$D$3&"|"&13,'Kit Lists'!$G$6:$G$605,0)),"") -> BOAT ASSY | C26: =IFERROR(INDEX('Kit Lists'!$C$6:$C$605,MATCH(Dashboard!$D$3&"|"&13,'Kit Lists'!$G$6:$G$605,0)),"") -> 92UAP04548BBA | D26: =IFERROR(INDEX('Kit Lists'!$D$6:$D$605,MATCH(Dashboard!$D$3&"|"&13,'Kit Lists'!$G$6:$G$605,0)),"") -> R5B BOAT 2 ASSY (4P-4FP) | E26: =IFERROR(INDEX('Kit Lists'!$E$6:$E$605,MATCH(Dashboard!$D$3&"|"&13,'Kit Lists'!$G$6:$G$605,0)),"") -> 1 | F26: =IFERROR(INDEX('Kit Lists'!$H$6:$H$605,MATCH(Dashboard!$D$3&"|"&13,'Kit Lists'!$G$6:$G$605,0)),"") -> 13 | G26: =IF(C26="","",INT(F26/E26)) -> 13 | H26: =IF(C26="","",MOD(F26,E26)&" / "&E26) -> 0 / 1 | I26: =IF(C26="","",$I$12*E26) -> 33 | J26: =IF(C26="","",MAX(0,I26-F26)) -> 20
B27: =IFERROR(INDEX('Kit Lists'!$B$6:$B$605,MATCH(Dashboard!$D$3&"|"&14,'Kit Lists'!$G$6:$G$605,0)),"") -> BOAT ASSY | C27: =IFERROR(INDEX('Kit Lists'!$C$6:$C$605,MATCH(Dashboard!$D$3&"|"&14,'Kit Lists'!$G$6:$G$605,0)),"") -> 92UAP04548BCA | D27: =IFERROR(INDEX('Kit Lists'!$D$6:$D$605,MATCH(Dashboard!$D$3&"|"&14,'Kit Lists'!$G$6:$G$605,0)),"") -> R5B BOAT 3 ASSY (4P-4FP) | E27: =IFERROR(INDEX('Kit Lists'!$E$6:$E$605,MATCH(Dashboard!$D$3&"|"&14,'Kit Lists'!$G$6:$G$605,0)),"") -> 1 | F27: =IFERROR(INDEX('Kit Lists'!$H$6:$H$605,MATCH(Dashboard!$D$3&"|"&14,'Kit Lists'!$G$6:$G$605,0)),"") -> 13 | G27: =IF(C27="","",INT(F27/E27)) -> 13 | H27: =IF(C27="","",MOD(F27,E27)&" / "&E27) -> 0 / 1 | I27: =IF(C27="","",$I$12*E27) -> 33 | J27: =IF(C27="","",MAX(0,I27-F27)) -> 20
B28: =IFERROR(INDEX('Kit Lists'!$B$6:$B$605,MATCH(Dashboard!$D$3&"|"&15,'Kit Lists'!$G$6:$G$605,0)),"") | C28: =IFERROR(INDEX('Kit Lists'!$C$6:$C$605,MATCH(Dashboard!$D$3&"|"&15,'Kit Lists'!$G$6:$G$605,0)),"") | D28: =IFERROR(INDEX('Kit Lists'!$D$6:$D$605,MATCH(Dashboard!$D$3&"|"&15,'Kit Lists'!$G$6:$G$605,0)),"") | E28: =IFERROR(INDEX('Kit Lists'!$E$6:$E$605,MATCH(Dashboard!$D$3&"|"&15,'Kit Lists'!$G$6:$G$605,0)),"") | F28: =IFERROR(INDEX('Kit Lists'!$H$6:$H$605,MATCH(Dashboard!$D$3&"|"&15,'Kit Lists'!$G$6:$G$605,0)),"") | G28: =IF(C28="","",INT(F28/E28)) | H28: =IF(C28="","",MOD(F28,E28)&" / "&E28) | I28: =IF(C28="","",$I$12*E28) | J28: =IF(C28="","",MAX(0,I28-F28))
B29: =IFERROR(INDEX('Kit Lists'!$B$6:$B$605,MATCH(Dashboard!$D$3&"|"&16,'Kit Lists'!$G$6:$G$605,0)),"") | C29: =IFERROR(INDEX('Kit Lists'!$C$6:$C$605,MATCH(Dashboard!$D$3&"|"&16,'Kit Lists'!$G$6:$G$605,0)),"") | D29: =IFERROR(INDEX('Kit Lists'!$D$6:$D$605,MATCH(Dashboard!$D$3&"|"&16,'Kit Lists'!$G$6:$G$605,0)),"") | E29: =IFERROR(INDEX('Kit Lists'!$E$6:$E$605,MATCH(Dashboard!$D$3&"|"&16,'Kit Lists'!$G$6:$G$605,0)),"") | F29: =IFERROR(INDEX('Kit Lists'!$H$6:$H$605,MATCH(Dashboard!$D$3&"|"&16,'Kit Lists'!$G$6:$G$605,0)),"") | G29: =IF(C29="","",INT(F29/E29)) | H29: =IF(C29="","",MOD(F29,E29)&" / "&E29) | I29: =IF(C29="","",$I$12*E29) | J29: =IF(C29="","",MAX(0,I29-F29))
B30: =IFERROR(INDEX('Kit Lists'!$B$6:$B$605,MATCH(Dashboard!$D$3&"|"&17,'Kit Lists'!$G$6:$G$605,0)),"") | C30: =IFERROR(INDEX('Kit Lists'!$C$6:$C$605,MATCH(Dashboard!$D$3&"|"&17,'Kit Lists'!$G$6:$G$605,0)),"") | D30: =IFERROR(INDEX('Kit Lists'!$D$6:$D$605,MATCH(Dashboard!$D$3&"|"&17,'Kit Lists'!$G$6:$G$605,0)),"") | E30: =IFERROR(INDEX('Kit Lists'!$E$6:$E$605,MATCH(Dashboard!$D$3&"|"&17,'Kit Lists'!$G$6:$G$605,0)),"") | F30: =IFERROR(INDEX('Kit Lists'!$H$6:$H$605,MATCH(Dashboard!$D$3&"|"&17,'Kit Lists'!$G$6:$G$605,0)),"") | G30: =IF(C30="","",INT(F30/E30)) | H30: =IF(C30="","",MOD(F30,E30)&" / "&E30) | I30: =IF(C30="","",$I$12*E30) | J30: =IF(C30="","",MAX(0,I30-F30))
B31: =IFERROR(INDEX('Kit Lists'!$B$6:$B$605,MATCH(Dashboard!$D$3&"|"&18,'Kit Lists'!$G$6:$G$605,0)),"") | C31: =IFERROR(INDEX('Kit Lists'!$C$6:$C$605,MATCH(Dashboard!$D$3&"|"&18,'Kit Lists'!$G$6:$G$605,0)),"") | D31: =IFERROR(INDEX('Kit Lists'!$D$6:$D$605,MATCH(Dashboard!$D$3&"|"&18,'Kit Lists'!$G$6:$G$605,0)),"") | E31: =IFERROR(INDEX('Kit Lists'!$E$6:$E$605,MATCH(Dashboard!$D$3&"|"&18,'Kit Lists'!$G$6:$G$605,0)),"") | F31: =IFERROR(INDEX('Kit Lists'!$H$6:$H$605,MATCH(Dashboard!$D$3&"|"&18,'Kit Lists'!$G$6:$G$605,0)),"") | G31: =IF(C31="","",INT(F31/E31)) | H31: =IF(C31="","",MOD(F31,E31)&" / "&E31) | I31: =IF(C31="","",$I$12*E31) | J31: =IF(C31="","",MAX(0,I31-F31))
B32: =IFERROR(INDEX('Kit Lists'!$B$6:$B$605,MATCH(Dashboard!$D$3&"|"&19,'Kit Lists'!$G$6:$G$605,0)),"") | C32: =IFERROR(INDEX('Kit Lists'!$C$6:$C$605,MATCH(Dashboard!$D$3&"|"&19,'Kit Lists'!$G$6:$G$605,0)),"") | D32: =IFERROR(INDEX('Kit Lists'!$D$6:$D$605,MATCH(Dashboard!$D$3&"|"&19,'Kit Lists'!$G$6:$G$605,0)),"") | E32: =IFERROR(INDEX('Kit Lists'!$E$6:$E$605,MATCH(Dashboard!$D$3&"|"&19,'Kit Lists'!$G$6:$G$605,0)),"") | F32: =IFERROR(INDEX('Kit Lists'!$H$6:$H$605,MATCH(Dashboard!$D$3&"|"&19,'Kit Lists'!$G$6:$G$605,0)),"") | G32: =IF(C32="","",INT(F32/E32)) | H32: =IF(C32="","",MOD(F32,E32)&" / "&E32) | I32: =IF(C32="","",$I$12*E32) | J32: =IF(C32="","",MAX(0,I32-F32))
B33: =IFERROR(INDEX('Kit Lists'!$B$6:$B$605,MATCH(Dashboard!$D$3&"|"&20,'Kit Lists'!$G$6:$G$605,0)),"") | C33: =IFERROR(INDEX('Kit Lists'!$C$6:$C$605,MATCH(Dashboard!$D$3&"|"&20,'Kit Lists'!$G$6:$G$605,0)),"") | D33: =IFERROR(INDEX('Kit Lists'!$D$6:$D$605,MATCH(Dashboard!$D$3&"|"&20,'Kit Lists'!$G$6:$G$605,0)),"") | E33: =IFERROR(INDEX('Kit Lists'!$E$6:$E$605,MATCH(Dashboard!$D$3&"|"&20,'Kit Lists'!$G$6:$G$605,0)),"") | F33: =IFERROR(INDEX('Kit Lists'!$H$6:$H$605,MATCH(Dashboard!$D$3&"|"&20,'Kit Lists'!$G$6:$G$605,0)),"") | G33: =IF(C33="","",INT(F33/E33)) | H33: =IF(C33="","",MOD(F33,E33)&" / "&E33) | I33: =IF(C33="","",$I$12*E33) | J33: =IF(C33="","",MAX(0,I33-F33))
C34: TOTAL | D34: Repeaters = lowest sub-assembly (highlighted red) — it limits the count | F34: =IF(COUNT(F14:F33)=0,"",SUM(F14:F33)) -> 663 | G34: =IF(COUNT(G14:G33)=0,"",MIN(G14:G33)) -> 13 | I34: =IF(COUNT(I14:I33)=0,"",SUM(I14:I33)) -> 1683 | J34: =IF(COUNT(J14:J33)=0,"",SUM(J14:J33)) -> 1020
B36: LATEST RELEASES (this contract)
B37: Date | C37: Assy Code | D37: Description | E37: Qty | F37: Released By | G37: Note
B38: =IF(IFERROR(LARGE('Release Log'!$I$6:$I$4005,1),0)=0,"",IF(INDEX('Release Log'!$A:$A,IFERROR(LARGE('Release Log'!$I$6:$I$4005,1),0))="","",INDEX('Release Log'!$A:$A,IFERROR(LARGE('Release Log'!$I$6:$I$4005,1),0)))) -> 46297 | C38: =IF(IFERROR(LARGE('Release Log'!$I$6:$I$4005,1),0)=0,"",IF(INDEX('Release Log'!$C:$C,IFERROR(LARGE('Release Log'!$I$6:$I$4005,1),0))="","",INDEX('Release Log'!$C:$C,IFERROR(LARGE('Release Log'!$I$6:$I$4005,1),0)))) -> 92UAP04548BCA | D38: =IF(IFERROR(LARGE('Release Log'!$I$6:$I$4005,1),0)=0,"",IF(INDEX('Release Log'!$G:$G,IFERROR(LARGE('Release Log'!$I$6:$I$4005,1),0))="","",INDEX('Release Log'!$G:$G,IFERROR(LARGE('Release Log'!$I$6:$I$4005,1),0)))) -> R5B BOAT 3 ASSY (4P-4FP) | E38: =IF(IFERROR(LARGE('Release Log'!$I$6:$I$4005,1),0)=0,"",IF(INDEX('Release Log'!$D:$D,IFERROR(LARGE('Release Log'!$I$6:$I$4005,1),0))="","",INDEX('Release Log'!$D:$D,IFERROR(LARGE('Release Log'!$I$6:$I$4005,1),0)))) -> 1 | F38: =IF(IFERROR(LARGE('Release Log'!$I$6:$I$4005,1),0)=0,"",IF(INDEX('Release Log'!$E:$E,IFERROR(LARGE('Release Log'!$I$6:$I$4005,1),0))="","",INDEX('Release Log'!$E:$E,IFERROR(LARGE('Release Log'!$I$6:$I$4005,1),0)))) | G38: =IF(IFERROR(LARGE('Release Log'!$I$6:$I$4005,1),0)=0,"",IF(INDEX('Release Log'!$F:$F,IFERROR(LARGE('Release Log'!$I$6:$I$4005,1),0))="","",INDEX('Release Log'!$F:$F,IFERROR(LARGE('Release Log'!$I$6:$I$4005,1),0)))) -> Rep 13 (from COOIS)
B39: =IF(IFERROR(LARGE('Release Log'!$I$6:$I$4005,2),0)=0,"",IF(INDEX('Release Log'!$A:$A,IFERROR(LARGE('Release Log'!$I$6:$I$4005,2),0))="","",INDEX('Release Log'!$A:$A,IFERROR(LARGE('Release Log'!$I$6:$I$4005,2),0)))) -> 46297 | C39: =IF(IFERROR(LARGE('Release Log'!$I$6:$I$4005,2),0)=0,"",IF(INDEX('Release Log'!$C:$C,IFERROR(LARGE('Release Log'!$I$6:$I$4005,2),0))="","",INDEX('Release Log'!$C:$C,IFERROR(LARGE('Release Log'!$I$6:$I$4005,2),0)))) -> 92UAP04548BBA | D39: =IF(IFERROR(LARGE('Release Log'!$I$6:$I$4005,2),0)=0,"",IF(INDEX('Release Log'!$G:$G,IFERROR(LARGE('Release Log'!$I$6:$I$4005,2),0))="","",INDEX('Release Log'!$G:$G,IFERROR(LARGE('Release Log'!$I$6:$I$4005,2),0)))) -> R5B BOAT 2 ASSY (4P-4FP) | E39: =IF(IFERROR(LARGE('Release Log'!$I$6:$I$4005,2),0)=0,"",IF(INDEX('Release Log'!$D:$D,IFERROR(LARGE('Release Log'!$I$6:$I$4005,2),0))="","",INDEX('Release Log'!$D:$D,IFERROR(LARGE('Release Log'!$I$6:$I$4005,2),0)))) -> 1 | F39: =IF(IFERROR(LARGE('Release Log'!$I$6:$I$4005,2),0)=0,"",IF(INDEX('Release Log'!$E:$E,IFERROR(LARGE('Release Log'!$I$6:$I$4005,2),0))="","",INDEX('Release Log'!$E:$E,IFERROR(LARGE('Release Log'!$I$6:$I$4005,2),0)))) | G39: =IF(IFERROR(LARGE('Release Log'!$I$6:$I$4005,2),0)=0,"",IF(INDEX('Release Log'!$F:$F,IFERROR(LARGE('Release Log'!$I$6:$I$4005,2),0))="","",INDEX('Release Log'!$F:$F,IFERROR(LARGE('Release Log'!$I$6:$I$4005,2),0)))) -> Rep 13 (from COOIS)
B40: =IF(IFERROR(LARGE('Release Log'!$I$6:$I$4005,3),0)=0,"",IF(INDEX('Release Log'!$A:$A,IFERROR(LARGE('Release Log'!$I$6:$I$4005,3),0))="","",INDEX('Release Log'!$A:$A,IFERROR(LARGE('Release Log'!$I$6:$I$4005,3),0)))) -> 46297 | C40: =IF(IFERROR(LARGE('Release Log'!$I$6:$I$4005,3),0)=0,"",IF(INDEX('Release Log'!$C:$C,IFERROR(LARGE('Release Log'!$I$6:$I$4005,3),0))="","",INDEX('Release Log'!$C:$C,IFERROR(LARGE('Release Log'!$I$6:$I$4005,3),0)))) -> 92UAP04548BAA | D40: =IF(IFERROR(LARGE('Release Log'!$I$6:$I$4005,3),0)=0,"",IF(INDEX('Release Log'!$G:$G,IFERROR(LARGE('Release Log'!$I$6:$I$4005,3),0))="","",INDEX('Release Log'!$G:$G,IFERROR(LARGE('Release Log'!$I$6:$I$4005,3),0)))) -> R5B BOAT 1 ASSY (4P-4FP) | E40: =IF(IFERROR(LARGE('Release Log'!$I$6:$I$4005,3),0)=0,"",IF(INDEX('Release Log'!$D:$D,IFERROR(LARGE('Release Log'!$I$6:$I$4005,3),0))="","",INDEX('Release Log'!$D:$D,IFERROR(LARGE('Release Log'!$I$6:$I$4005,3),0)))) -> 1 | F40: =IF(IFERROR(LARGE('Release Log'!$I$6:$I$4005,3),0)=0,"",IF(INDEX('Release Log'!$E:$E,IFERROR(LARGE('Release Log'!$I$6:$I$4005,3),0))="","",INDEX('Release Log'!$E:$E,IFERROR(LARGE('Release Log'!$I$6:$I$4005,3),0)))) | G40: =IF(IFERROR(LARGE('Release Log'!$I$6:$I$4005,3),0)=0,"",IF(INDEX('Release Log'!$F:$F,IFERROR(LARGE('Release Log'!$I$6:$I$4005,3),0))="","",INDEX('Release Log'!$F:$F,IFERROR(LARGE('Release Log'!$I$6:$I$4005,3),0)))) -> Rep 13 (from COOIS)
B41: =IF(IFERROR(LARGE('Release Log'!$I$6:$I$4005,4),0)=0,"",IF(INDEX('Release Log'!$A:$A,IFERROR(LARGE('Release Log'!$I$6:$I$4005,4),0))="","",INDEX('Release Log'!$A:$A,IFERROR(LARGE('Release Log'!$I$6:$I$4005,4),0)))) -> 46297 | C41: =IF(IFERROR(LARGE('Release Log'!$I$6:$I$4005,4),0)=0,"",IF(INDEX('Release Log'!$C:$C,IFERROR(LARGE('Release Log'!$I$6:$I$4005,4),0))="","",INDEX('Release Log'!$C:$C,IFERROR(LARGE('Release Log'!$I$6:$I$4005,4),0)))) -> 92YRA04548AAA | D41: =IF(IFERROR(LARGE('Release Log'!$I$6:$I$4005,4),0)=0,"",IF(INDEX('Release Log'!$G:$G,IFERROR(LARGE('Release Log'!$I$6:$I$4005,4),0))="","",INDEX('Release Log'!$G:$G,IFERROR(LARGE('Release Log'!$I$6:$I$4005,4),0)))) -> R5B ERBIUM ASSEMBLY POSITION 4 | E41: =IF(IFERROR(LARGE('Release Log'!$I$6:$I$4005,4),0)=0,"",IF(INDEX('Release Log'!$D:$D,IFERROR(LARGE('Release Log'!$I$6:$I$4005,4),0))="","",INDEX('Release Log'!$D:$D,IFERROR(LARGE('Release Log'!$I$6:$I$4005,4),0)))) -> 3 | F41: =IF(IFERROR(LARGE('Release Log'!$I$6:$I$4005,4),0)=0,"",IF(INDEX('Release Log'!$E:$E,IFERROR(LARGE('Release Log'!$I$6:$I$4005,4),0))="","",INDEX('Release Log'!$E:$E,IFERROR(LARGE('Release Log'!$I$6:$I$4005,4),0)))) | G41: =IF(IFERROR(LARGE('Release Log'!$I$6:$I$4005,4),0)=0,"",IF(INDEX('Release Log'!$F:$F,IFERROR(LARGE('Release Log'!$I$6:$I$4005,4),0))="","",INDEX('Release Log'!$F:$F,IFERROR(LARGE('Release Log'!$I$6:$I$4005,4),0)))) -> Rep 13 (from COOIS)
B42: =IF(IFERROR(LARGE('Release Log'!$I$6:$I$4005,5),0)=0,"",IF(INDEX('Release Log'!$A:$A,IFERROR(LARGE('Release Log'!$I$6:$I$4005,5),0))="","",INDEX('Release Log'!$A:$A,IFERROR(LARGE('Release Log'!$I$6:$I$4005,5),0)))) -> 46297 | C42: =IF(IFERROR(LARGE('Release Log'!$I$6:$I$4005,5),0)=0,"",IF(INDEX('Release Log'!$C:$C,IFERROR(LARGE('Release Log'!$I$6:$I$4005,5),0))="","",INDEX('Release Log'!$C:$C,IFERROR(LARGE('Release Log'!$I$6:$I$4005,5),0)))) -> 92YRA03548AAA | D42: =IF(IFERROR(LARGE('Release Log'!$I$6:$I$4005,5),0)=0,"",IF(INDEX('Release Log'!$G:$G,IFERROR(LARGE('Release Log'!$I$6:$I$4005,5),0))="","",INDEX('Release Log'!$G:$G,IFERROR(LARGE('Release Log'!$I$6:$I$4005,5),0)))) -> R5B ERBIUM ASSEMBLY POSITION 3 | E42: =IF(IFERROR(LARGE('Release Log'!$I$6:$I$4005,5),0)=0,"",IF(INDEX('Release Log'!$D:$D,IFERROR(LARGE('Release Log'!$I$6:$I$4005,5),0))="","",INDEX('Release Log'!$D:$D,IFERROR(LARGE('Release Log'!$I$6:$I$4005,5),0)))) -> 3 | F42: =IF(IFERROR(LARGE('Release Log'!$I$6:$I$4005,5),0)=0,"",IF(INDEX('Release Log'!$E:$E,IFERROR(LARGE('Release Log'!$I$6:$I$4005,5),0))="","",INDEX('Release Log'!$E:$E,IFERROR(LARGE('Release Log'!$I$6:$I$4005,5),0)))) | G42: =IF(IFERROR(LARGE('Release Log'!$I$6:$I$4005,5),0)=0,"",IF(INDEX('Release Log'!$F:$F,IFERROR(LARGE('Release Log'!$I$6:$I$4005,5),0))="","",INDEX('Release Log'!$F:$F,IFERROR(LARGE('Release Log'!$I$6:$I$4005,5),0)))) -> Rep 13 (from COOIS)
B43: =IF(IFERROR(LARGE('Release Log'!$I$6:$I$4005,6),0)=0,"",IF(INDEX('Release Log'!$A:$A,IFERROR(LARGE('Release Log'!$I$6:$I$4005,6),0))="","",INDEX('Release Log'!$A:$A,IFERROR(LARGE('Release Log'!$I$6:$I$4005,6),0)))) -> 46297 | C43: =IF(IFERROR(LARGE('Release Log'!$I$6:$I$4005,6),0)=0,"",IF(INDEX('Release Log'!$C:$C,IFERROR(LARGE('Release Log'!$I$6:$I$4005,6),0))="","",INDEX('Release Log'!$C:$C,IFERROR(LARGE('Release Log'!$I$6:$I$4005,6),0)))) -> 92YRA02548AAA | D43: =IF(IFERROR(LARGE('Release Log'!$I$6:$I$4005,6),0)=0,"",IF(INDEX('Release Log'!$G:$G,IFERROR(LARGE('Release Log'!$I$6:$I$4005,6),0))="","",INDEX('Release Log'!$G:$G,IFERROR(LARGE('Release Log'!$I$6:$I$4005,6),0)))) -> R5B ERBIUM ASSEMBLY POSITION 2 | E43: =IF(IFERROR(LARGE('Release Log'!$I$6:$I$4005,6),0)=0,"",IF(INDEX('Release Log'!$D:$D,IFERROR(LARGE('Release Log'!$I$6:$I$4005,6),0))="","",INDEX('Release Log'!$D:$D,IFERROR(LARGE('Release Log'!$I$6:$I$4005,6),0)))) -> 3 | F43: =IF(IFERROR(LARGE('Release Log'!$I$6:$I$4005,6),0)=0,"",IF(INDEX('Release Log'!$E:$E,IFERROR(LARGE('Release Log'!$I$6:$I$4005,6),0))="","",INDEX('Release Log'!$E:$E,IFERROR(LARGE('Release Log'!$I$6:$I$4005,6),0)))) | G43: =IF(IFERROR(LARGE('Release Log'!$I$6:$I$4005,6),0)=0,"",IF(INDEX('Release Log'!$F:$F,IFERROR(LARGE('Release Log'!$I$6:$I$4005,6),0))="","",INDEX('Release Log'!$F:$F,IFERROR(LARGE('Release Log'!$I$6:$I$4005,6),0)))) -> Rep 13 (from COOIS)
B44: =IF(IFERROR(LARGE('Release Log'!$I$6:$I$4005,7),0)=0,"",IF(INDEX('Release Log'!$A:$A,IFERROR(LARGE('Release Log'!$I$6:$I$4005,7),0))="","",INDEX('Release Log'!$A:$A,IFERROR(LARGE('Release Log'!$I$6:$I$4005,7),0)))) -> 46297 | C44: =IF(IFERROR(LARGE('Release Log'!$I$6:$I$4005,7),0)=0,"",IF(INDEX('Release Log'!$C:$C,IFERROR(LARGE('Release Log'!$I$6:$I$4005,7),0))="","",INDEX('Release Log'!$C:$C,IFERROR(LARGE('Release Log'!$I$6:$I$4005,7),0)))) -> 92YRA01548AAA | D44: =IF(IFERROR(LARGE('Release Log'!$I$6:$I$4005,7),0)=0,"",IF(INDEX('Release Log'!$G:$G,IFERROR(LARGE('Release Log'!$I$6:$I$4005,7),0))="","",INDEX('Release Log'!$G:$G,IFERROR(LARGE('Release Log'!$I$6:$I$4005,7),0)))) -> R5B ERBIUM ASSEMBLY POSITION 1 | E44: =IF(IFERROR(LARGE('Release Log'!$I$6:$I$4005,7),0)=0,"",IF(INDEX('Release Log'!$D:$D,IFERROR(LARGE('Release Log'!$I$6:$I$4005,7),0))="","",INDEX('Release Log'!$D:$D,IFERROR(LARGE('Release Log'!$I$6:$I$4005,7),0)))) -> 3 | F44: =IF(IFERROR(LARGE('Release Log'!$I$6:$I$4005,7),0)=0,"",IF(INDEX('Release Log'!$E:$E,IFERROR(LARGE('Release Log'!$I$6:$I$4005,7),0))="","",INDEX('Release Log'!$E:$E,IFERROR(LARGE('Release Log'!$I$6:$I$4005,7),0)))) | G44: =IF(IFERROR(LARGE('Release Log'!$I$6:$I$4005,7),0)=0,"",IF(INDEX('Release Log'!$F:$F,IFERROR(LARGE('Release Log'!$I$6:$I$4005,7),0))="","",INDEX('Release Log'!$F:$F,IFERROR(LARGE('Release Log'!$I$6:$I$4005,7),0)))) -> Rep 13 (from COOIS)
B45: =IF(IFERROR(LARGE('Release Log'!$I$6:$I$4005,8),0)=0,"",IF(INDEX('Release Log'!$A:$A,IFERROR(LARGE('Release Log'!$I$6:$I$4005,8),0))="","",INDEX('Release Log'!$A:$A,IFERROR(LARGE('Release Log'!$I$6:$I$4005,8),0)))) -> 46297 | C45: =IF(IFERROR(LARGE('Release Log'!$I$6:$I$4005,8),0)=0,"",IF(INDEX('Release Log'!$C:$C,IFERROR(LARGE('Release Log'!$I$6:$I$4005,8),0))="","",INDEX('Release Log'!$C:$C,IFERROR(LARGE('Release Log'!$I$6:$I$4005,8),0)))) -> 92RRA00548AAA | D45: =IF(IFERROR(LARGE('Release Log'!$I$6:$I$4005,8),0)=0,"",IF(INDEX('Release Log'!$G:$G,IFERROR(LARGE('Release Log'!$I$6:$I$4005,8),0))="","",INDEX('Release Log'!$G:$G,IFERROR(LARGE('Release Log'!$I$6:$I$4005,8),0)))) -> R5B ERBIUM SPOOL ASSEMBLY - E2A | E45: =IF(IFERROR(LARGE('Release Log'!$I$6:$I$4005,8),0)=0,"",IF(INDEX('Release Log'!$D:$D,IFERROR(LARGE('Release Log'!$I$6:$I$4005,8),0))="","",INDEX('Release Log'!$D:$D,IFERROR(LARGE('Release Log'!$I$6:$I$4005,8),0)))) -> 24 | F45: =IF(IFERROR(LARGE('Release Log'!$I$6:$I$4005,8),0)=0,"",IF(INDEX('Release Log'!$E:$E,IFERROR(LARGE('Release Log'!$I$6:$I$4005,8),0))="","",INDEX('Release Log'!$E:$E,IFERROR(LARGE('Release Log'!$I$6:$I$4005,8),0)))) | G45: =IF(IFERROR(LARGE('Release Log'!$I$6:$I$4005,8),0)=0,"",IF(INDEX('Release Log'!$F:$F,IFERROR(LARGE('Release Log'!$I$6:$I$4005,8),0))="","",INDEX('Release Log'!$F:$F,IFERROR(LARGE('Release Log'!$I$6:$I$4005,8),0)))) -> Rep 13 (from COOIS)

Sheet Portfolio
B2: R5B AMP KITTING — ALL CONTRACTS
B3: ="As of "&TEXT(Dashboard!$Q$3,"dd-mmm-yy")&" · week "&_xlfn.ISOWEEKNUM(Dashboard!$Q$3)&" · "&COUNTA(Contracts!$A$6:$A$65)&" contracts" -> As of 05-Oct-26 · week 41 · 12 contracts
B5: Contract | C5: Project | D5: Top Code | E5: FP | F5: Total Reps | G5: Kitted | H5: Progress | I5: Amps Kitted | J5: Plan to Date | K5: Vs Plan | L5: Status
B6: =IF(Contracts!$A$6="","",IF(Contracts!A6="","–",Contracts!A6)) -> WKE-R24P-T1-C | C6: =IF(Contracts!$A$6="","",IF(Contracts!B6="","–",Contracts!B6)) -> Wamkelekile | D6: =IF(Contracts!$A$6="","",IF(Contracts!C6="","–",Contracts!C6)) -> 92ERP24543A++ | E6: =IF(Contracts!$A$6="","",IF(Contracts!D6="","–",Contracts!D6)) -> 24 | F6: =IF(Contracts!$A$6="","",IF(Contracts!F6="","–",Contracts!F6)) -> 255 | G6: =IF(Contracts!$A$6="","",IF(Contracts!I6="","–",Contracts!I6)) -> 0 | H6: =IF(Contracts!$A$6="","",IF(Contracts!N6="","–",Contracts!N6)) -> 0 | I6: =IF(Contracts!$A$6="","",IF(Contracts!J6="","–",Contracts!J6)) -> 0 | J6: =IF(Contracts!$A$6="","",IF(Contracts!K6="","–",Contracts!K6)) -> 0 | K6: =IF(Contracts!$A$6="","",IF(Contracts!L6="","–",Contracts!L6)) -> 0 | L6: =IF(Contracts!$A$6="","",IF(Contracts!O6="","–",Contracts!O6)) -> ON PLAN
B7: =IF(Contracts!$A$7="","",IF(Contracts!A7="","–",Contracts!A7)) -> WBA-R24P-T1-C | C7: =IF(Contracts!$A$7="","",IF(Contracts!B7="","–",Contracts!B7)) -> Waban | D7: =IF(Contracts!$A$7="","",IF(Contracts!C7="","–",Contracts!C7)) -> 92ERP24545A++ | E7: =IF(Contracts!$A$7="","",IF(Contracts!D7="","–",Contracts!D7)) -> 24 | F7: =IF(Contracts!$A$7="","",IF(Contracts!F7="","–",Contracts!F7)) -> 200 | G7: =IF(Contracts!$A$7="","",IF(Contracts!I7="","–",Contracts!I7)) -> – | H7: =IF(Contracts!$A$7="","",IF(Contracts!N7="","–",Contracts!N7)) -> – | I7: =IF(Contracts!$A$7="","",IF(Contracts!J7="","–",Contracts!J7)) -> – | J7: =IF(Contracts!$A$7="","",IF(Contracts!K7="","–",Contracts!K7)) -> 0 | K7: =IF(Contracts!$A$7="","",IF(Contracts!L7="","–",Contracts!L7)) -> – | L7: =IF(Contracts!$A$7="","",IF(Contracts!O7="","–",Contracts!O7)) -> NO KIT LIST
B8: =IF(Contracts!$A$8="","",IF(Contracts!A8="","–",Contracts!A8)) -> E2A-R4P-T1-C | C8: =IF(Contracts!$A$8="","",IF(Contracts!B8="","–",Contracts!B8)) -> E2A | D8: =IF(Contracts!$A$8="","",IF(Contracts!C8="","–",Contracts!C8)) -> 92ERP04548A++ | E8: =IF(Contracts!$A$8="","",IF(Contracts!D8="","–",Contracts!D8)) -> 4 | F8: =IF(Contracts!$A$8="","",IF(Contracts!F8="","–",Contracts!F8)) -> 39 | G8: =IF(Contracts!$A$8="","",IF(Contracts!I8="","–",Contracts!I8)) -> – | H8: =IF(Contracts!$A$8="","",IF(Contracts!N8="","–",Contracts!N8)) -> – | I8: =IF(Contracts!$A$8="","",IF(Contracts!J8="","–",Contracts!J8)) -> – | J8: =IF(Contracts!$A$8="","",IF(Contracts!K8="","–",Contracts!K8)) -> 0 | K8: =IF(Contracts!$A$8="","",IF(Contracts!L8="","–",Contracts!L8)) -> – | L8: =IF(Contracts!$A$8="","",IF(Contracts!O8="","–",Contracts!O8)) -> NO KIT LIST
B9: =IF(Contracts!$A$9="","",IF(Contracts!A9="","–",Contracts!A9)) -> E2A-R4P-T2-M | C9: =IF(Contracts!$A$9="","",IF(Contracts!B9="","–",Contracts!B9)) -> E2A | D9: =IF(Contracts!$A$9="","",IF(Contracts!C9="","–",Contracts!C9)) -> 92ERP04548B++ | E9: =IF(Contracts!$A$9="","",IF(Contracts!D9="","–",Contracts!D9)) -> 4 | F9: =IF(Contracts!$A$9="","",IF(Contracts!F9="","–",Contracts!F9)) -> 11 | G9: =IF(Contracts!$A$9="","",IF(Contracts!I9="","–",Contracts!I9)) -> – | H9: =IF(Contracts!$A$9="","",IF(Contracts!N9="","–",Contracts!N9)) -> – | I9: =IF(Contracts!$A$9="","",IF(Contracts!J9="","–",Contracts!J9)) -> – | J9: =IF(Contracts!$A$9="","",IF(Contracts!K9="","–",Contracts!K9)) -> 0 | K9: =IF(Contracts!$A$9="","",IF(Contracts!L9="","–",Contracts!L9)) -> – | L9: =IF(Contracts!$A$9="","",IF(Contracts!O9="","–",Contracts!O9)) -> NO KIT LIST
B10: =IF(Contracts!$A$10="","",IF(Contracts!A10="","–",Contracts!A10)) -> E2A-R6P-T3-M | C10: =IF(Contracts!$A$10="","",IF(Contracts!B10="","–",Contracts!B10)) -> E2A | D10: =IF(Contracts!$A$10="","",IF(Contracts!C10="","–",Contracts!C10)) -> 92ERP06548A++ | E10: =IF(Contracts!$A$10="","",IF(Contracts!D10="","–",Contracts!D10)) -> 6 | F10: =IF(Contracts!$A$10="","",IF(Contracts!F10="","–",Contracts!F10)) -> 3 | G10: =IF(Contracts!$A$10="","",IF(Contracts!I10="","–",Contracts!I10)) -> – | H10: =IF(Contracts!$A$10="","",IF(Contracts!N10="","–",Contracts!N10)) -> – | I10: =IF(Contracts!$A$10="","",IF(Contracts!J10="","–",Contracts!J10)) -> – | J10: =IF(Contracts!$A$10="","",IF(Contracts!K10="","–",Contracts!K10)) -> 0 | K10: =IF(Contracts!$A$10="","",IF(Contracts!L10="","–",Contracts!L10)) -> – | L10: =IF(Contracts!$A$10="","",IF(Contracts!O10="","–",Contracts!O10)) -> NO KIT LIST
B11: =IF(Contracts!$A$11="","",IF(Contracts!A11="","–",Contracts!A11)) -> E2A-R8P-T4-C | C11: =IF(Contracts!$A$11="","",IF(Contracts!B11="","–",Contracts!B11)) -> E2A | D11: =IF(Contracts!$A$11="","",IF(Contracts!C11="","–",Contracts!C11)) -> 92ERP08548A++ | E11: =IF(Contracts!$A$11="","",IF(Contracts!D11="","–",Contracts!D11)) -> 8 | F11: =IF(Contracts!$A$11="","",IF(Contracts!F11="","–",Contracts!F11)) -> 10 | G11: =IF(Contracts!$A$11="","",IF(Contracts!I11="","–",Contracts!I11)) -> – | H11: =IF(Contracts!$A$11="","",IF(Contracts!N11="","–",Contracts!N11)) -> – | I11: =IF(Contracts!$A$11="","",IF(Contracts!J11="","–",Contracts!J11)) -> – | J11: =IF(Contracts!$A$11="","",IF(Contracts!K11="","–",Contracts!K11)) -> 0 | K11: =IF(Contracts!$A$11="","",IF(Contracts!L11="","–",Contracts!L11)) -> – | L11: =IF(Contracts!$A$11="","",IF(Contracts!O11="","–",Contracts!O11)) -> NO KIT LIST
B12: =IF(Contracts!$A$12="","",IF(Contracts!A12="","–",Contracts!A12)) -> E2A-R12P-T5-C | C12: =IF(Contracts!$A$12="","",IF(Contracts!B12="","–",Contracts!B12)) -> E2A | D12: =IF(Contracts!$A$12="","",IF(Contracts!C12="","–",Contracts!C12)) -> 92ERP12548A++ | E12: =IF(Contracts!$A$12="","",IF(Contracts!D12="","–",Contracts!D12)) -> 12 | F12: =IF(Contracts!$A$12="","",IF(Contracts!F12="","–",Contracts!F12)) -> 109 | G12: =IF(Contracts!$A$12="","",IF(Contracts!I12="","–",Contracts!I12)) -> 13 | H12: =IF(Contracts!$A$12="","",IF(Contracts!N12="","–",Contracts!N12)) -> 0.11926606 | I12: =IF(Contracts!$A$12="","",IF(Contracts!J12="","–",Contracts!J12)) -> 156 | J12: =IF(Contracts!$A$12="","",IF(Contracts!K12="","–",Contracts!K12)) -> 31 | K12: =IF(Contracts!$A$12="","",IF(Contracts!L12="","–",Contracts!L12)) -> -18 | L12: =IF(Contracts!$A$12="","",IF(Contracts!O12="","–",Contracts!O12)) -> BEHIND -18
B13: =IF(Contracts!$A$13="","",IF(Contracts!A13="","–",Contracts!A13)) -> E2A-R12P-T6-C | C13: =IF(Contracts!$A$13="","",IF(Contracts!B13="","–",Contracts!B13)) -> E2A | D13: =IF(Contracts!$A$13="","",IF(Contracts!C13="","–",Contracts!C13)) -> 92ERP12548B++ | E13: =IF(Contracts!$A$13="","",IF(Contracts!D13="","–",Contracts!D13)) -> 12 | F13: =IF(Contracts!$A$13="","",IF(Contracts!F13="","–",Contracts!F13)) -> 5 | G13: =IF(Contracts!$A$13="","",IF(Contracts!I13="","–",Contracts!I13)) -> – | H13: =IF(Contracts!$A$13="","",IF(Contracts!N13="","–",Contracts!N13)) -> – | I13: =IF(Contracts!$A$13="","",IF(Contracts!J13="","–",Contracts!J13)) -> – | J13: =IF(Contracts!$A$13="","",IF(Contracts!K13="","–",Contracts!K13)) -> 0 | K13: =IF(Contracts!$A$13="","",IF(Contracts!L13="","–",Contracts!L13)) -> – | L13: =IF(Contracts!$A$13="","",IF(Contracts!O13="","–",Contracts!O13)) -> NO KIT LIST
B14: =IF(Contracts!$A$14="","",IF(Contracts!A14="","–",Contracts!A14)) -> E2A-R16P-T7-C | C14: =IF(Contracts!$A$14="","",IF(Contracts!B14="","–",Contracts!B14)) -> E2A | D14: =IF(Contracts!$A$14="","",IF(Contracts!C14="","–",Contracts!C14)) -> 92ERP16548A++ | E14: =IF(Contracts!$A$14="","",IF(Contracts!D14="","–",Contracts!D14)) -> 16 | F14: =IF(Contracts!$A$14="","",IF(Contracts!F14="","–",Contracts!F14)) -> 9 | G14: =IF(Contracts!$A$14="","",IF(Contracts!I14="","–",Contracts!I14)) -> – | H14: =IF(Contracts!$A$14="","",IF(Contracts!N14="","–",Contracts!N14)) -> – | I14: =IF(Contracts!$A$14="","",IF(Contracts!J14="","–",Contracts!J14)) -> – | J14: =IF(Contracts!$A$14="","",IF(Contracts!K14="","–",Contracts!K14)) -> 0 | K14: =IF(Contracts!$A$14="","",IF(Contracts!L14="","–",Contracts!L14)) -> – | L14: =IF(Contracts!$A$14="","",IF(Contracts!O14="","–",Contracts!O14)) -> NO KIT LIST
B15: =IF(Contracts!$A$15="","",IF(Contracts!A15="","–",Contracts!A15)) -> DARAJA-R8P (TBC) | C15: =IF(Contracts!$A$15="","",IF(Contracts!B15="","–",Contracts!B15)) -> Daraja Ext to SA | D15: =IF(Contracts!$A$15="","",IF(Contracts!C15="","–",Contracts!C15)) -> Not yet released | E15: =IF(Contracts!$A$15="","",IF(Contracts!D15="","–",Contracts!D15)) -> 8 | F15: =IF(Contracts!$A$15="","",IF(Contracts!F15="","–",Contracts!F15)) -> 10 | G15: =IF(Contracts!$A$15="","",IF(Contracts!I15="","–",Contracts!I15)) -> – | H15: =IF(Contracts!$A$15="","",IF(Contracts!N15="","–",Contracts!N15)) -> – | I15: =IF(Contracts!$A$15="","",IF(Contracts!J15="","–",Contracts!J15)) -> – | J15: =IF(Contracts!$A$15="","",IF(Contracts!K15="","–",Contracts!K15)) -> 0 | K15: =IF(Contracts!$A$15="","",IF(Contracts!L15="","–",Contracts!L15)) -> – | L15: =IF(Contracts!$A$15="","",IF(Contracts!O15="","–",Contracts!O15)) -> NO KIT LIST
B16: =IF(Contracts!$A$16="","",IF(Contracts!A16="","–",Contracts!A16)) -> DARAJA-R24P (TBC) | C16: =IF(Contracts!$A$16="","",IF(Contracts!B16="","–",Contracts!B16)) -> Daraja Ext to SA | D16: =IF(Contracts!$A$16="","",IF(Contracts!C16="","–",Contracts!C16)) -> Not yet released | E16: =IF(Contracts!$A$16="","",IF(Contracts!D16="","–",Contracts!D16)) -> 24 | F16: =IF(Contracts!$A$16="","",IF(Contracts!F16="","–",Contracts!F16)) -> 46 | G16: =IF(Contracts!$A$16="","",IF(Contracts!I16="","–",Contracts!I16)) -> – | H16: =IF(Contracts!$A$16="","",IF(Contracts!N16="","–",Contracts!N16)) -> – | I16: =IF(Contracts!$A$16="","",IF(Contracts!J16="","–",Contracts!J16)) -> – | J16: =IF(Contracts!$A$16="","",IF(Contracts!K16="","–",Contracts!K16)) -> 0 | K16: =IF(Contracts!$A$16="","",IF(Contracts!L16="","–",Contracts!L16)) -> – | L16: =IF(Contracts!$A$16="","",IF(Contracts!O16="","–",Contracts!O16)) -> NO KIT LIST
B17: =IF(Contracts!$A$17="","",IF(Contracts!A17="","–",Contracts!A17)) -> REUNION-SOUTH-R16P (TBC) | C17: =IF(Contracts!$A$17="","",IF(Contracts!B17="","–",Contracts!B17)) -> Reunion-South Africa (wet plant only) | D17: =IF(Contracts!$A$17="","",IF(Contracts!C17="","–",Contracts!C17)) -> Not yet released | E17: =IF(Contracts!$A$17="","",IF(Contracts!D17="","–",Contracts!D17)) -> 16 | F17: =IF(Contracts!$A$17="","",IF(Contracts!F17="","–",Contracts!F17)) -> 31 | G17: =IF(Contracts!$A$17="","",IF(Contracts!I17="","–",Contracts!I17)) -> – | H17: =IF(Contracts!$A$17="","",IF(Contracts!N17="","–",Contracts!N17)) -> – | I17: =IF(Contracts!$A$17="","",IF(Contracts!J17="","–",Contracts!J17)) -> – | J17: =IF(Contracts!$A$17="","",IF(Contracts!K17="","–",Contracts!K17)) -> 0 | K17: =IF(Contracts!$A$17="","",IF(Contracts!L17="","–",Contracts!L17)) -> – | L17: =IF(Contracts!$A$17="","",IF(Contracts!O17="","–",Contracts!O17)) -> NO KIT LIST
B18: =IF(Contracts!$A$18="","",IF(Contracts!A18="","–",Contracts!A18)) | C18: =IF(Contracts!$A$18="","",IF(Contracts!B18="","–",Contracts!B18)) | D18: =IF(Contracts!$A$18="","",IF(Contracts!C18="","–",Contracts!C18)) | E18: =IF(Contracts!$A$18="","",IF(Contracts!D18="","–",Contracts!D18)) | F18: =IF(Contracts!$A$18="","",IF(Contracts!F18="","–",Contracts!F18)) | G18: =IF(Contracts!$A$18="","",IF(Contracts!I18="","–",Contracts!I18)) | H18: =IF(Contracts!$A$18="","",IF(Contracts!N18="","–",Contracts!N18)) | I18: =IF(Contracts!$A$18="","",IF(Contracts!J18="","–",Contracts!J18)) | J18: =IF(Contracts!$A$18="","",IF(Contracts!K18="","–",Contracts!K18)) | K18: =IF(Contracts!$A$18="","",IF(Contracts!L18="","–",Contracts!L18)) | L18: =IF(Contracts!$A$18="","",IF(Contracts!O18="","–",Contracts!O18))
B19: =IF(Contracts!$A$19="","",IF(Contracts!A19="","–",Contracts!A19)) | C19: =IF(Contracts!$A$19="","",IF(Contracts!B19="","–",Contracts!B19)) | D19: =IF(Contracts!$A$19="","",IF(Contracts!C19="","–",Contracts!C19)) | E19: =IF(Contracts!$A$19="","",IF(Contracts!D19="","–",Contracts!D19)) | F19: =IF(Contracts!$A$19="","",IF(Contracts!F19="","–",Contracts!F19)) | G19: =IF(Contracts!$A$19="","",IF(Contracts!I19="","–",Contracts!I19)) | H19: =IF(Contracts!$A$19="","",IF(Contracts!N19="","–",Contracts!N19)) | I19: =IF(Contracts!$A$19="","",IF(Contracts!J19="","–",Contracts!J19)) | J19: =IF(Contracts!$A$19="","",IF(Contracts!K19="","–",Contracts!K19)) | K19: =IF(Contracts!$A$19="","",IF(Contracts!L19="","–",Contracts!L19)) | L19: =IF(Contracts!$A$19="","",IF(Contracts!O19="","–",Contracts!O19))
B20: =IF(Contracts!$A$20="","",IF(Contracts!A20="","–",Contracts!A20)) | C20: =IF(Contracts!$A$20="","",IF(Contracts!B20="","–",Contracts!B20)) | D20: =IF(Contracts!$A$20="","",IF(Contracts!C20="","–",Contracts!C20)) | E20: =IF(Contracts!$A$20="","",IF(Contracts!D20="","–",Contracts!D20)) | F20: =IF(Contracts!$A$20="","",IF(Contracts!F20="","–",Contracts!F20)) | G20: =IF(Contracts!$A$20="","",IF(Contracts!I20="","–",Contracts!I20)) | H20: =IF(Contracts!$A$20="","",IF(Contracts!N20="","–",Contracts!N20)) | I20: =IF(Contracts!$A$20="","",IF(Contracts!J20="","–",Contracts!J20)) | J20: =IF(Contracts!$A$20="","",IF(Contracts!K20="","–",Contracts!K20)) | K20: =IF(Contracts!$A$20="","",IF(Contracts!L20="","–",Contracts!L20)) | L20: =IF(Contracts!$A$20="","",IF(Contracts!O20="","–",Contracts!O20))
B21: =IF(Contracts!$A$21="","",IF(Contracts!A21="","–",Contracts!A21)) | C21: =IF(Contracts!$A$21="","",IF(Contracts!B21="","–",Contracts!B21)) | D21: =IF(Contracts!$A$21="","",IF(Contracts!C21="","–",Contracts!C21)) | E21: =IF(Contracts!$A$21="","",IF(Contracts!D21="","–",Contracts!D21)) | F21: =IF(Contracts!$A$21="","",IF(Contracts!F21="","–",Contracts!F21)) | G21: =IF(Contracts!$A$21="","",IF(Contracts!I21="","–",Contracts!I21)) | H21: =IF(Contracts!$A$21="","",IF(Contracts!N21="","–",Contracts!N21)) | I21: =IF(Contracts!$A$21="","",IF(Contracts!J21="","–",Contracts!J21)) | J21: =IF(Contracts!$A$21="","",IF(Contracts!K21="","–",Contracts!K21)) | K21: =IF(Contracts!$A$21="","",IF(Contracts!L21="","–",Contracts!L21)) | L21: =IF(Contracts!$A$21="","",IF(Contracts!O21="","–",Contracts!O21))
B22: =IF(Contracts!$A$22="","",IF(Contracts!A22="","–",Contracts!A22)) | C22: =IF(Contracts!$A$22="","",IF(Contracts!B22="","–",Contracts!B22)) | D22: =IF(Contracts!$A$22="","",IF(Contracts!C22="","–",Contracts!C22)) | E22: =IF(Contracts!$A$22="","",IF(Contracts!D22="","–",Contracts!D22)) | F22: =IF(Contracts!$A$22="","",IF(Contracts!F22="","–",Contracts!F22)) | G22: =IF(Contracts!$A$22="","",IF(Contracts!I22="","–",Contracts!I22)) | H22: =IF(Contracts!$A$22="","",IF(Contracts!N22="","–",Contracts!N22)) | I22: =IF(Contracts!$A$22="","",IF(Contracts!J22="","–",Contracts!J22)) | J22: =IF(Contracts!$A$22="","",IF(Contracts!K22="","–",Contracts!K22)) | K22: =IF(Contracts!$A$22="","",IF(Contracts!L22="","–",Contracts!L22)) | L22: =IF(Contracts!$A$22="","",IF(Contracts!O22="","–",Contracts!O22))
B23: =IF(Contracts!$A$23="","",IF(Contracts!A23="","–",Contracts!A23)) | C23: =IF(Contracts!$A$23="","",IF(Contracts!B23="","–",Contracts!B23)) | D23: =IF(Contracts!$A$23="","",IF(Contracts!C23="","–",Contracts!C23)) | E23: =IF(Contracts!$A$23="","",IF(Contracts!D23="","–",Contracts!D23)) | F23: =IF(Contracts!$A$23="","",IF(Contracts!F23="","–",Contracts!F23)) | G23: =IF(Contracts!$A$23="","",IF(Contracts!I23="","–",Contracts!I23)) | H23: =IF(Contracts!$A$23="","",IF(Contracts!N23="","–",Contracts!N23)) | I23: =IF(Contracts!$A$23="","",IF(Contracts!J23="","–",Contracts!J23)) | J23: =IF(Contracts!$A$23="","",IF(Contracts!K23="","–",Contracts!K23)) | K23: =IF(Contracts!$A$23="","",IF(Contracts!L23="","–",Contracts!L23)) | L23: =IF(Contracts!$A$23="","",IF(Contracts!O23="","–",Contracts!O23))
B24: =IF(Contracts!$A$24="","",IF(Contracts!A24="","–",Contracts!A24)) | C24: =IF(Contracts!$A$24="","",IF(Contracts!B24="","–",Contracts!B24)) | D24: =IF(Contracts!$A$24="","",IF(Contracts!C24="","–",Contracts!C24)) | E24: =IF(Contracts!$A$24="","",IF(Contracts!D24="","–",Contracts!D24)) | F24: =IF(Contracts!$A$24="","",IF(Contracts!F24="","–",Contracts!F24)) | G24: =IF(Contracts!$A$24="","",IF(Contracts!I24="","–",Contracts!I24)) | H24: =IF(Contracts!$A$24="","",IF(Contracts!N24="","–",Contracts!N24)) | I24: =IF(Contracts!$A$24="","",IF(Contracts!J24="","–",Contracts!J24)) | J24: =IF(Contracts!$A$24="","",IF(Contracts!K24="","–",Contracts!K24)) | K24: =IF(Contracts!$A$24="","",IF(Contracts!L24="","–",Contracts!L24)) | L24: =IF(Contracts!$A$24="","",IF(Contracts!O24="","–",Contracts!O24))
B25: =IF(Contracts!$A$25="","",IF(Contracts!A25="","–",Contracts!A25)) | C25: =IF(Contracts!$A$25="","",IF(Contracts!B25="","–",Contracts!B25)) | D25: =IF(Contracts!$A$25="","",IF(Contracts!C25="","–",Contracts!C25)) | E25: =IF(Contracts!$A$25="","",IF(Contracts!D25="","–",Contracts!D25)) | F25: =IF(Contracts!$A$25="","",IF(Contracts!F25="","–",Contracts!F25)) | G25: =IF(Contracts!$A$25="","",IF(Contracts!I25="","–",Contracts!I25)) | H25: =IF(Contracts!$A$25="","",IF(Contracts!N25="","–",Contracts!N25)) | I25: =IF(Contracts!$A$25="","",IF(Contracts!J25="","–",Contracts!J25)) | J25: =IF(Contracts!$A$25="","",IF(Contracts!K25="","–",Contracts!K25)) | K25: =IF(Contracts!$A$25="","",IF(Contracts!L25="","–",Contracts!L25)) | L25: =IF(Contracts!$A$25="","",IF(Contracts!O25="","–",Contracts!O25))
B26: =IF(Contracts!$A$26="","",IF(Contracts!A26="","–",Contracts!A26)) | C26: =IF(Contracts!$A$26="","",IF(Contracts!B26="","–",Contracts!B26)) | D26: =IF(Contracts!$A$26="","",IF(Contracts!C26="","–",Contracts!C26)) | E26: =IF(Contracts!$A$26="","",IF(Contracts!D26="","–",Contracts!D26)) | F26: =IF(Contracts!$A$26="","",IF(Contracts!F26="","–",Contracts!F26)) | G26: =IF(Contracts!$A$26="","",IF(Contracts!I26="","–",Contracts!I26)) | H26: =IF(Contracts!$A$26="","",IF(Contracts!N26="","–",Contracts!N26)) | I26: =IF(Contracts!$A$26="","",IF(Contracts!J26="","–",Contracts!J26)) | J26: =IF(Contracts!$A$26="","",IF(Contracts!K26="","–",Contracts!K26)) | K26: =IF(Contracts!$A$26="","",IF(Contracts!L26="","–",Contracts!L26)) | L26: =IF(Contracts!$A$26="","",IF(Contracts!O26="","–",Contracts!O26))
B27: =IF(Contracts!$A$27="","",IF(Contracts!A27="","–",Contracts!A27)) | C27: =IF(Contracts!$A$27="","",IF(Contracts!B27="","–",Contracts!B27)) | D27: =IF(Contracts!$A$27="","",IF(Contracts!C27="","–",Contracts!C27)) | E27: =IF(Contracts!$A$27="","",IF(Contracts!D27="","–",Contracts!D27)) | F27: =IF(Contracts!$A$27="","",IF(Contracts!F27="","–",Contracts!F27)) | G27: =IF(Contracts!$A$27="","",IF(Contracts!I27="","–",Contracts!I27)) | H27: =IF(Contracts!$A$27="","",IF(Contracts!N27="","–",Contracts!N27)) | I27: =IF(Contracts!$A$27="","",IF(Contracts!J27="","–",Contracts!J27)) | J27: =IF(Contracts!$A$27="","",IF(Contracts!K27="","–",Contracts!K27)) | K27: =IF(Contracts!$A$27="","",IF(Contracts!L27="","–",Contracts!L27)) | L27: =IF(Contracts!$A$27="","",IF(Contracts!O27="","–",Contracts!O27))
B28: =IF(Contracts!$A$28="","",IF(Contracts!A28="","–",Contracts!A28)) | C28: =IF(Contracts!$A$28="","",IF(Contracts!B28="","–",Contracts!B28)) | D28: =IF(Contracts!$A$28="","",IF(Contracts!C28="","–",Contracts!C28)) | E28: =IF(Contracts!$A$28="","",IF(Contracts!D28="","–",Contracts!D28)) | F28: =IF(Contracts!$A$28="","",IF(Contracts!F28="","–",Contracts!F28)) | G28: =IF(Contracts!$A$28="","",IF(Contracts!I28="","–",Contracts!I28)) | H28: =IF(Contracts!$A$28="","",IF(Contracts!N28="","–",Contracts!N28)) | I28: =IF(Contracts!$A$28="","",IF(Contracts!J28="","–",Contracts!J28)) | J28: =IF(Contracts!$A$28="","",IF(Contracts!K28="","–",Contracts!K28)) | K28: =IF(Contracts!$A$28="","",IF(Contracts!L28="","–",Contracts!L28)) | L28: =IF(Contracts!$A$28="","",IF(Contracts!O28="","–",Contracts!O28))
B29: =IF(Contracts!$A$29="","",IF(Contracts!A29="","–",Contracts!A29)) | C29: =IF(Contracts!$A$29="","",IF(Contracts!B29="","–",Contracts!B29)) | D29: =IF(Contracts!$A$29="","",IF(Contracts!C29="","–",Contracts!C29)) | E29: =IF(Contracts!$A$29="","",IF(Contracts!D29="","–",Contracts!D29)) | F29: =IF(Contracts!$A$29="","",IF(Contracts!F29="","–",Contracts!F29)) | G29: =IF(Contracts!$A$29="","",IF(Contracts!I29="","–",Contracts!I29)) | H29: =IF(Contracts!$A$29="","",IF(Contracts!N29="","–",Contracts!N29)) | I29: =IF(Contracts!$A$29="","",IF(Contracts!J29="","–",Contracts!J29)) | J29: =IF(Contracts!$A$29="","",IF(Contracts!K29="","–",Contracts!K29)) | K29: =IF(Contracts!$A$29="","",IF(Contracts!L29="","–",Contracts!L29)) | L29: =IF(Contracts!$A$29="","",IF(Contracts!O29="","–",Contracts!O29))
B30: =IF(Contracts!$A$30="","",IF(Contracts!A30="","–",Contracts!A30)) | C30: =IF(Contracts!$A$30="","",IF(Contracts!B30="","–",Contracts!B30)) | D30: =IF(Contracts!$A$30="","",IF(Contracts!C30="","–",Contracts!C30)) | E30: =IF(Contracts!$A$30="","",IF(Contracts!D30="","–",Contracts!D30)) | F30: =IF(Contracts!$A$30="","",IF(Contracts!F30="","–",Contracts!F30)) | G30: =IF(Contracts!$A$30="","",IF(Contracts!I30="","–",Contracts!I30)) | H30: =IF(Contracts!$A$30="","",IF(Contracts!N30="","–",Contracts!N30)) | I30: =IF(Contracts!$A$30="","",IF(Contracts!J30="","–",Contracts!J30)) | J30: =IF(Contracts!$A$30="","",IF(Contracts!K30="","–",Contracts!K30)) | K30: =IF(Contracts!$A$30="","",IF(Contracts!L30="","–",Contracts!L30)) | L30: =IF(Contracts!$A$30="","",IF(Contracts!O30="","–",Contracts!O30))
B31: =IF(Contracts!$A$31="","",IF(Contracts!A31="","–",Contracts!A31)) | C31: =IF(Contracts!$A$31="","",IF(Contracts!B31="","–",Contracts!B31)) | D31: =IF(Contracts!$A$31="","",IF(Contracts!C31="","–",Contracts!C31)) | E31: =IF(Contracts!$A$31="","",IF(Contracts!D31="","–",Contracts!D31)) | F31: =IF(Contracts!$A$31="","",IF(Contracts!F31="","–",Contracts!F31)) | G31: =IF(Contracts!$A$31="","",IF(Contracts!I31="","–",Contracts!I31)) | H31: =IF(Contracts!$A$31="","",IF(Contracts!N31="","–",Contracts!N31)) | I31: =IF(Contracts!$A$31="","",IF(Contracts!J31="","–",Contracts!J31)) | J31: =IF(Contracts!$A$31="","",IF(Contracts!K31="","–",Contracts!K31)) | K31: =IF(Contracts!$A$31="","",IF(Contracts!L31="","–",Contracts!L31)) | L31: =IF(Contracts!$A$31="","",IF(Contracts!O31="","–",Contracts!O31))
B32: =IF(Contracts!$A$32="","",IF(Contracts!A32="","–",Contracts!A32)) | C32: =IF(Contracts!$A$32="","",IF(Contracts!B32="","–",Contracts!B32)) | D32: =IF(Contracts!$A$32="","",IF(Contracts!C32="","–",Contracts!C32)) | E32: =IF(Contracts!$A$32="","",IF(Contracts!D32="","–",Contracts!D32)) | F32: =IF(Contracts!$A$32="","",IF(Contracts!F32="","–",Contracts!F32)) | G32: =IF(Contracts!$A$32="","",IF(Contracts!I32="","–",Contracts!I32)) | H32: =IF(Contracts!$A$32="","",IF(Contracts!N32="","–",Contracts!N32)) | I32: =IF(Contracts!$A$32="","",IF(Contracts!J32="","–",Contracts!J32)) | J32: =IF(Contracts!$A$32="","",IF(Contracts!K32="","–",Contracts!K32)) | K32: =IF(Contracts!$A$32="","",IF(Contracts!L32="","–",Contracts!L32)) | L32: =IF(Contracts!$A$32="","",IF(Contracts!O32="","–",Contracts!O32))
B33: =IF(Contracts!$A$33="","",IF(Contracts!A33="","–",Contracts!A33)) | C33: =IF(Contracts!$A$33="","",IF(Contracts!B33="","–",Contracts!B33)) | D33: =IF(Contracts!$A$33="","",IF(Contracts!C33="","–",Contracts!C33)) | E33: =IF(Contracts!$A$33="","",IF(Contracts!D33="","–",Contracts!D33)) | F33: =IF(Contracts!$A$33="","",IF(Contracts!F33="","–",Contracts!F33)) | G33: =IF(Contracts!$A$33="","",IF(Contracts!I33="","–",Contracts!I33)) | H33: =IF(Contracts!$A$33="","",IF(Contracts!N33="","–",Contracts!N33)) | I33: =IF(Contracts!$A$33="","",IF(Contracts!J33="","–",Contracts!J33)) | J33: =IF(Contracts!$A$33="","",IF(Contracts!K33="","–",Contracts!K33)) | K33: =IF(Contracts!$A$33="","",IF(Contracts!L33="","–",Contracts!L33)) | L33: =IF(Contracts!$A$33="","",IF(Contracts!O33="","–",Contracts!O33))
B34: =IF(Contracts!$A$34="","",IF(Contracts!A34="","–",Contracts!A34)) | C34: =IF(Contracts!$A$34="","",IF(Contracts!B34="","–",Contracts!B34)) | D34: =IF(Contracts!$A$34="","",IF(Contracts!C34="","–",Contracts!C34)) | E34: =IF(Contracts!$A$34="","",IF(Contracts!D34="","–",Contracts!D34)) | F34: =IF(Contracts!$A$34="","",IF(Contracts!F34="","–",Contracts!F34)) | G34: =IF(Contracts!$A$34="","",IF(Contracts!I34="","–",Contracts!I34)) | H34: =IF(Contracts!$A$34="","",IF(Contracts!N34="","–",Contracts!N34)) | I34: =IF(Contracts!$A$34="","",IF(Contracts!J34="","–",Contracts!J34)) | J34: =IF(Contracts!$A$34="","",IF(Contracts!K34="","–",Contracts!K34)) | K34: =IF(Contracts!$A$34="","",IF(Contracts!L34="","–",Contracts!L34)) | L34: =IF(Contracts!$A$34="","",IF(Contracts!O34="","–",Contracts!O34))
B35: =IF(Contracts!$A$35="","",IF(Contracts!A35="","–",Contracts!A35)) | C35: =IF(Contracts!$A$35="","",IF(Contracts!B35="","–",Contracts!B35)) | D35: =IF(Contracts!$A$35="","",IF(Contracts!C35="","–",Contracts!C35)) | E35: =IF(Contracts!$A$35="","",IF(Contracts!D35="","–",Contracts!D35)) | F35: =IF(Contracts!$A$35="","",IF(Contracts!F35="","–",Contracts!F35)) | G35: =IF(Contracts!$A$35="","",IF(Contracts!I35="","–",Contracts!I35)) | H35: =IF(Contracts!$A$35="","",IF(Contracts!N35="","–",Contracts!N35)) | I35: =IF(Contracts!$A$35="","",IF(Contracts!J35="","–",Contracts!J35)) | J35: =IF(Contracts!$A$35="","",IF(Contracts!K35="","–",Contracts!K35)) | K35: =IF(Contracts!$A$35="","",IF(Contracts!L35="","–",Contracts!L35)) | L35: =IF(Contracts!$A$35="","",IF(Contracts!O35="","–",Contracts!O35))
B36: =IF(Contracts!$A$36="","",IF(Contracts!A36="","–",Contracts!A36)) | C36: =IF(Contracts!$A$36="","",IF(Contracts!B36="","–",Contracts!B36)) | D36: =IF(Contracts!$A$36="","",IF(Contracts!C36="","–",Contracts!C36)) | E36: =IF(Contracts!$A$36="","",IF(Contracts!D36="","–",Contracts!D36)) | F36: =IF(Contracts!$A$36="","",IF(Contracts!F36="","–",Contracts!F36)) | G36: =IF(Contracts!$A$36="","",IF(Contracts!I36="","–",Contracts!I36)) | H36: =IF(Contracts!$A$36="","",IF(Contracts!N36="","–",Contracts!N36)) | I36: =IF(Contracts!$A$36="","",IF(Contracts!J36="","–",Contracts!J36)) | J36: =IF(Contracts!$A$36="","",IF(Contracts!K36="","–",Contracts!K36)) | K36: =IF(Contracts!$A$36="","",IF(Contracts!L36="","–",Contracts!L36)) | L36: =IF(Contracts!$A$36="","",IF(Contracts!O36="","–",Contracts!O36))
B37: =IF(Contracts!$A$37="","",IF(Contracts!A37="","–",Contracts!A37)) | C37: =IF(Contracts!$A$37="","",IF(Contracts!B37="","–",Contracts!B37)) | D37: =IF(Contracts!$A$37="","",IF(Contracts!C37="","–",Contracts!C37)) | E37: =IF(Contracts!$A$37="","",IF(Contracts!D37="","–",Contracts!D37)) | F37: =IF(Contracts!$A$37="","",IF(Contracts!F37="","–",Contracts!F37)) | G37: =IF(Contracts!$A$37="","",IF(Contracts!I37="","–",Contracts!I37)) | H37: =IF(Contracts!$A$37="","",IF(Contracts!N37="","–",Contracts!N37)) | I37: =IF(Contracts!$A$37="","",IF(Contracts!J37="","–",Contracts!J37)) | J37: =IF(Contracts!$A$37="","",IF(Contracts!K37="","–",Contracts!K37)) | K37: =IF(Contracts!$A$37="","",IF(Contracts!L37="","–",Contracts!L37)) | L37: =IF(Contracts!$A$37="","",IF(Contracts!O37="","–",Contracts!O37))
B38: =IF(Contracts!$A$38="","",IF(Contracts!A38="","–",Contracts!A38)) | C38: =IF(Contracts!$A$38="","",IF(Contracts!B38="","–",Contracts!B38)) | D38: =IF(Contracts!$A$38="","",IF(Contracts!C38="","–",Contracts!C38)) | E38: =IF(Contracts!$A$38="","",IF(Contracts!D38="","–",Contracts!D38)) | F38: =IF(Contracts!$A$38="","",IF(Contracts!F38="","–",Contracts!F38)) | G38: =IF(Contracts!$A$38="","",IF(Contracts!I38="","–",Contracts!I38)) | H38: =IF(Contracts!$A$38="","",IF(Contracts!N38="","–",Contracts!N38)) | I38: =IF(Contracts!$A$38="","",IF(Contracts!J38="","–",Contracts!J38)) | J38: =IF(Contracts!$A$38="","",IF(Contracts!K38="","–",Contracts!K38)) | K38: =IF(Contracts!$A$38="","",IF(Contracts!L38="","–",Contracts!L38)) | L38: =IF(Contracts!$A$38="","",IF(Contracts!O38="","–",Contracts!O38))
B39: =IF(Contracts!$A$39="","",IF(Contracts!A39="","–",Contracts!A39)) | C39: =IF(Contracts!$A$39="","",IF(Contracts!B39="","–",Contracts!B39)) | D39: =IF(Contracts!$A$39="","",IF(Contracts!C39="","–",Contracts!C39)) | E39: =IF(Contracts!$A$39="","",IF(Contracts!D39="","–",Contracts!D39)) | F39: =IF(Contracts!$A$39="","",IF(Contracts!F39="","–",Contracts!F39)) | G39: =IF(Contracts!$A$39="","",IF(Contracts!I39="","–",Contracts!I39)) | H39: =IF(Contracts!$A$39="","",IF(Contracts!N39="","–",Contracts!N39)) | I39: =IF(Contracts!$A$39="","",IF(Contracts!J39="","–",Contracts!J39)) | J39: =IF(Contracts!$A$39="","",IF(Contracts!K39="","–",Contracts!K39)) | K39: =IF(Contracts!$A$39="","",IF(Contracts!L39="","–",Contracts!L39)) | L39: =IF(Contracts!$A$39="","",IF(Contracts!O39="","–",Contracts!O39))
B40: =IF(Contracts!$A$40="","",IF(Contracts!A40="","–",Contracts!A40)) | C40: =IF(Contracts!$A$40="","",IF(Contracts!B40="","–",Contracts!B40)) | D40: =IF(Contracts!$A$40="","",IF(Contracts!C40="","–",Contracts!C40)) | E40: =IF(Contracts!$A$40="","",IF(Contracts!D40="","–",Contracts!D40)) | F40: =IF(Contracts!$A$40="","",IF(Contracts!F40="","–",Contracts!F40)) | G40: =IF(Contracts!$A$40="","",IF(Contracts!I40="","–",Contracts!I40)) | H40: =IF(Contracts!$A$40="","",IF(Contracts!N40="","–",Contracts!N40)) | I40: =IF(Contracts!$A$40="","",IF(Contracts!J40="","–",Contracts!J40)) | J40: =IF(Contracts!$A$40="","",IF(Contracts!K40="","–",Contracts!K40)) | K40: =IF(Contracts!$A$40="","",IF(Contracts!L40="","–",Contracts!L40)) | L40: =IF(Contracts!$A$40="","",IF(Contracts!O40="","–",Contracts!O40))
