Workbook

Sheet Dashboard
B2: R5B E2A 12FP COLD T5 · REPEATER KITTING
B3: ="Contract R5B · E2A 12FP Cold T5 · 92ERP12548A++ · 12FP · Repeaters 1–"&'Kitting Plan'!$C$3&" · "&COUNT('COOIS Data'!$A$6:$A$1505)&" WOs in COOIS · latest release "&TEXT(MAX('COOIS Data'!$F$6:$F$1505),"dd-mmm-yy") -> Contract R5B · E2A 12FP Cold T5 · 92ERP12548A++ · 12FP · Repeaters 1–13 · 691 WOs in COOIS · latest release 03-Oct-26
B5: REPEATERS KITTED | D5: WORK ORDERS KITTED | E5: ISSUED (GMPS) | I5: DELIVERED (DLV) | M5: OPEN WOs
B6: =MIN(H11:H24)&" / "&'Kitting Plan'!$C$3 -> 13 / 13 | D6: =SUM(G11:G24) -> 691 | E6: =MIN(K11:K24)&" reps" -> 7 reps | I6: =MIN(M11:M24)&" reps" -> 5 reps | M6: =SUM(N11:N24) -> 277
B7: ="Every code has ≥ "&MIN(H11:H24)&" full repeater kits (WO printed in SAP)" -> Every code has ≥ 13 full repeater kits (WO printed in SAP) | D7: =SUM(F11:F24)&" needed for "&'Kitting Plan'!$C$3&" reps · "&SUM(I11:I24)&" surplus to review" -> 663 needed for 13 reps · 28 surplus to review | E7: ="components issued for all codes" -> components issued for all codes | I7: ="all 14 codes goods-receipted" -> all 14 codes goods-receipted | M7: ="kitted, not yet delivered" -> kitted, not yet delivered
B9: KITTED BY ASSY CODE | D9: Kitted = WO released and printed (PRT) in COOIS. Kits = kitted WOs ÷ qty per repeater.
B10: Sequence | C10: Assy Code | D10: Description | E10: Qty / Rep | F10: Contract Qty | G10: WOs Kitted | H10: Rep Kits | I10: Surplus WOs | J10: Issued | K10: Issued Reps | L10: Delivered | M10: Delivered Reps | N10: Open WOs | O10: Open WOs
B11: ='Kitting Plan'!A6 -> LASER ASSY | C11: ='Kitting Plan'!B6 -> 92YLS00548BAA | D11: ='Kitting Plan'!C6 -> R5B LASER ASSEMBLY 4P BOAT 1 - E2A | E11: ='Kitting Plan'!D6 -> 1 | F11: ='Kitting Plan'!E6 -> 13 | G11: =SUMIFS('COOIS Data'!$I$6:$I$1505,'COOIS Data'!$B$6:$B$1505,C11) -> 14 | H11: =IF(E11=0,0,INT(G11/E11)) -> 14 | I11: =MAX(0,G11-F11) -> 1 | J11: =SUMIFS('COOIS Data'!$J$6:$J$1505,'COOIS Data'!$B$6:$B$1505,C11) -> 10 | K11: =IF(E11=0,0,INT(J11/E11)) -> 10 | L11: =SUMIFS('COOIS Data'!$K$6:$K$1505,'COOIS Data'!$B$6:$B$1505,C11) -> 9 | M11: =IF(E11=0,0,INT(L11/E11)) -> 9 | N11: =G11-L11 -> 5
B12: ='Kitting Plan'!A7 -> LASER ASSY | C12: ='Kitting Plan'!B7 -> 92YLS00548BBA | D12: ='Kitting Plan'!C7 -> R5B LASER ASSEMBLY 4P BOAT 2/3 - E2A | E12: ='Kitting Plan'!D7 -> 2 | F12: ='Kitting Plan'!E7 -> 26 | G12: =SUMIFS('COOIS Data'!$I$6:$I$1505,'COOIS Data'!$B$6:$B$1505,C12) -> 26 | H12: =IF(E12=0,0,INT(G12/E12)) -> 13 | I12: =MAX(0,G12-F12) -> 0 | J12: =SUMIFS('COOIS Data'!$J$6:$J$1505,'COOIS Data'!$B$6:$B$1505,C12) -> 18 | K12: =IF(E12=0,0,INT(J12/E12)) -> 9 | L12: =SUMIFS('COOIS Data'!$K$6:$K$1505,'COOIS Data'!$B$6:$B$1505,C12) -> 17 | M12: =IF(E12=0,0,INT(L12/E12)) -> 8 | N12: =G12-L12 -> 9
B13: ='Kitting Plan'!A8 -> PSB ASSY | C13: ='Kitting Plan'!B8 -> 91YAF03404AAA | D13: ='Kitting Plan'!C8 -> R5B PSB SUB ASSEMBLY 4P-4FP | E13: ='Kitting Plan'!D8 -> 3 | F13: ='Kitting Plan'!E8 -> 39 | G13: =SUMIFS('COOIS Data'!$I$6:$I$1505,'COOIS Data'!$B$6:$B$1505,C13) -> 51 | H13: =IF(E13=0,0,INT(G13/E13)) -> 17 | I13: =MAX(0,G13-F13) -> 12 | J13: =SUMIFS('COOIS Data'!$J$6:$J$1505,'COOIS Data'!$B$6:$B$1505,C13) -> 38 | K13: =IF(E13=0,0,INT(J13/E13)) -> 12 | L13: =SUMIFS('COOIS Data'!$K$6:$K$1505,'COOIS Data'!$B$6:$B$1505,C13) -> 38 | M13: =IF(E13=0,0,INT(L13/E13)) -> 12 | N13: =G13-L13 -> 13
B14: ='Kitting Plan'!A9 -> OPF ASSY | C14: ='Kitting Plan'!B9 -> 92YFD04548BAA | D14: ='Kitting Plan'!C9 -> R5B OPF ASSEMBLY (4P-4FP) BOAT 1 - E2A | E14: ='Kitting Plan'!D9 -> 1 | F14: ='Kitting Plan'!E9 -> 13 | G14: =SUMIFS('COOIS Data'!$I$6:$I$1505,'COOIS Data'!$B$6:$B$1505,C14) -> 14 | H14: =IF(E14=0,0,INT(G14/E14)) -> 14 | I14: =MAX(0,G14-F14) -> 1 | J14: =SUMIFS('COOIS Data'!$J$6:$J$1505,'COOIS Data'!$B$6:$B$1505,C14) -> 9 | K14: =IF(E14=0,0,INT(J14/E14)) -> 9 | L14: =SUMIFS('COOIS Data'!$K$6:$K$1505,'COOIS Data'!$B$6:$B$1505,C14) -> 8 | M14: =IF(E14=0,0,INT(L14/E14)) -> 8 | N14: =G14-L14 -> 6
B15: ='Kitting Plan'!A10 -> OPF ASSY | C15: ='Kitting Plan'!B10 -> 92YFD04548BBA | D15: ='Kitting Plan'!C10 -> R5B OPF ASSEMBLY (4P-4FP) BOAT 2/3 - E2A | E15: ='Kitting Plan'!D10 -> 2 | F15: ='Kitting Plan'!E10 -> 26 | G15: =SUMIFS('COOIS Data'!$I$6:$I$1505,'COOIS Data'!$B$6:$B$1505,C15) -> 26 | H15: =IF(E15=0,0,INT(G15/E15)) -> 13 | I15: =MAX(0,G15-F15) -> 0 | J15: =SUMIFS('COOIS Data'!$J$6:$J$1505,'COOIS Data'!$B$6:$B$1505,C15) -> 16 | K15: =IF(E15=0,0,INT(J15/E15)) -> 8 | L15: =SUMIFS('COOIS Data'!$K$6:$K$1505,'COOIS Data'!$B$6:$B$1505,C15) -> 15 | M15: =IF(E15=0,0,INT(L15/E15)) -> 7 | N15: =G15-L15 -> 11
B16: ='Kitting Plan'!A11 -> POB ASSY | C16: ='Kitting Plan'!B11 -> 92YWS04548AAA | D16: ='Kitting Plan'!C11 -> R5B 4FP POB LUMENTUM SUB ASSEMBLY - E2A | E16: ='Kitting Plan'!D11 -> 3 | F16: ='Kitting Plan'!E11 -> 39 | G16: =SUMIFS('COOIS Data'!$I$6:$I$1505,'COOIS Data'!$B$6:$B$1505,C16) -> 39 | H16: =IF(E16=0,0,INT(G16/E16)) -> 13 | I16: =MAX(0,G16-F16) -> 0 | J16: =SUMIFS('COOIS Data'!$J$6:$J$1505,'COOIS Data'!$B$6:$B$1505,C16) -> 27 | K16: =IF(E16=0,0,INT(J16/E16)) -> 9 | L16: =SUMIFS('COOIS Data'!$K$6:$K$1505,'COOIS Data'!$B$6:$B$1505,C16) -> 27 | M16: =IF(E16=0,0,INT(L16/E16)) -> 9 | N16: =G16-L16 -> 12
B17: ='Kitting Plan'!A12 -> ERBIUM ASSY | C17: ='Kitting Plan'!B12 -> 92RRA00548AAA | D17: ='Kitting Plan'!C12 -> R5B ERBIUM SPOOL ASSEMBLY - E2A | E17: ='Kitting Plan'!D12 -> 24 | F17: ='Kitting Plan'!E12 -> 312 | G17: =SUMIFS('COOIS Data'!$I$6:$I$1505,'COOIS Data'!$B$6:$B$1505,C17) -> 322 | H17: =IF(E17=0,0,INT(G17/E17)) -> 13 | I17: =MAX(0,G17-F17) -> 10 | J17: =SUMIFS('COOIS Data'!$J$6:$J$1505,'COOIS Data'!$B$6:$B$1505,C17) -> 202 | K17: =IF(E17=0,0,INT(J17/E17)) -> 8 | L17: =SUMIFS('COOIS Data'!$K$6:$K$1505,'COOIS Data'!$B$6:$B$1505,C17) -> 202 | M17: =IF(E17=0,0,INT(L17/E17)) -> 8 | N17: =G17-L17 -> 120
B18: ='Kitting Plan'!A13 -> ERBIUM ASSY | C18: ='Kitting Plan'!B13 -> 92YRA01548AAA | D18: ='Kitting Plan'!C13 -> R5B ERBIUM ASSEMBLY POSITION 1 | E18: ='Kitting Plan'!D13 -> 3 | F18: ='Kitting Plan'!E13 -> 39 | G18: =SUMIFS('COOIS Data'!$I$6:$I$1505,'COOIS Data'!$B$6:$B$1505,C18) -> 40 | H18: =IF(E18=0,0,INT(G18/E18)) -> 13 | I18: =MAX(0,G18-F18) -> 1 | J18: =SUMIFS('COOIS Data'!$J$6:$J$1505,'COOIS Data'!$B$6:$B$1505,C18) -> 25 | K18: =IF(E18=0,0,INT(J18/E18)) -> 8 | L18: =SUMIFS('COOIS Data'!$K$6:$K$1505,'COOIS Data'!$B$6:$B$1505,C18) -> 22 | M18: =IF(E18=0,0,INT(L18/E18)) -> 7 | N18: =G18-L18 -> 18
B19: ='Kitting Plan'!A14 -> ERBIUM ASSY | C19: ='Kitting Plan'!B14 -> 92YRA02548AAA | D19: ='Kitting Plan'!C14 -> R5B ERBIUM ASSEMBLY POSITION 2 | E19: ='Kitting Plan'!D14 -> 3 | F19: ='Kitting Plan'!E14 -> 39 | G19: =SUMIFS('COOIS Data'!$I$6:$I$1505,'COOIS Data'!$B$6:$B$1505,C19) -> 39 | H19: =IF(E19=0,0,INT(G19/E19)) -> 13 | I19: =MAX(0,G19-F19) -> 0 | J19: =SUMIFS('COOIS Data'!$J$6:$J$1505,'COOIS Data'!$B$6:$B$1505,C19) -> 24 | K19: =IF(E19=0,0,INT(J19/E19)) -> 8 | L19: =SUMIFS('COOIS Data'!$K$6:$K$1505,'COOIS Data'!$B$6:$B$1505,C19) -> 20 | M19: =IF(E19=0,0,INT(L19/E19)) -> 6 | N19: =G19-L19 -> 19
B20: ='Kitting Plan'!A15 -> ERBIUM ASSY | C20: ='Kitting Plan'!B15 -> 92YRA03548AAA | D20: ='Kitting Plan'!C15 -> R5B ERBIUM ASSEMBLY POSITION 3 | E20: ='Kitting Plan'!D15 -> 3 | F20: ='Kitting Plan'!E15 -> 39 | G20: =SUMIFS('COOIS Data'!$I$6:$I$1505,'COOIS Data'!$B$6:$B$1505,C20) -> 42 | H20: =IF(E20=0,0,INT(G20/E20)) -> 14 | I20: =MAX(0,G20-F20) -> 3 | J20: =SUMIFS('COOIS Data'!$J$6:$J$1505,'COOIS Data'!$B$6:$B$1505,C20) -> 24 | K20: =IF(E20=0,0,INT(J20/E20)) -> 8 | L20: =SUMIFS('COOIS Data'!$K$6:$K$1505,'COOIS Data'!$B$6:$B$1505,C20) -> 20 | M20: =IF(E20=0,0,INT(L20/E20)) -> 6 | N20: =G20-L20 -> 22
B21: ='Kitting Plan'!A16 -> ERBIUM ASSY | C21: ='Kitting Plan'!B16 -> 92YRA04548AAA | D21: ='Kitting Plan'!C16 -> R5B ERBIUM ASSEMBLY POSITION 4 | E21: ='Kitting Plan'!D16 -> 3 | F21: ='Kitting Plan'!E16 -> 39 | G21: =SUMIFS('COOIS Data'!$I$6:$I$1505,'COOIS Data'!$B$6:$B$1505,C21) -> 39 | H21: =IF(E21=0,0,INT(G21/E21)) -> 13 | I21: =MAX(0,G21-F21) -> 0 | J21: =SUMIFS('COOIS Data'!$J$6:$J$1505,'COOIS Data'!$B$6:$B$1505,C21) -> 24 | K21: =IF(E21=0,0,INT(J21/E21)) -> 8 | L21: =SUMIFS('COOIS Data'!$K$6:$K$1505,'COOIS Data'!$B$6:$B$1505,C21) -> 20 | M21: =IF(E21=0,0,INT(L21/E21)) -> 6 | N21: =G21-L21 -> 19
B22: ='Kitting Plan'!A17 -> BOAT ASSY | C22: ='Kitting Plan'!B17 -> 92UAP04548BAA | D22: ='Kitting Plan'!C17 -> R5B BOAT 1 ASSY (4P-4FP) | E22: ='Kitting Plan'!D17 -> 1 | F22: ='Kitting Plan'!E17 -> 13 | G22: =SUMIFS('COOIS Data'!$I$6:$I$1505,'COOIS Data'!$B$6:$B$1505,C22) -> 13 | H22: =IF(E22=0,0,INT(G22/E22)) -> 13 | I22: =MAX(0,G22-F22) -> 0 | J22: =SUMIFS('COOIS Data'!$J$6:$J$1505,'COOIS Data'!$B$6:$B$1505,C22) -> 8 | K22: =IF(E22=0,0,INT(J22/E22)) -> 8 | L22: =SUMIFS('COOIS Data'!$K$6:$K$1505,'COOIS Data'!$B$6:$B$1505,C22) -> 5 | M22: =IF(E22=0,0,INT(L22/E22)) -> 5 | N22: =G22-L22 -> 8
... B24: ='Kitting Plan'!A19 -> BOAT ASSY | C24: ='Kitting Plan'!B19 -> 92UAP04548BCA | D24: ='Kitting Plan'!C19 -> R5B BOAT 3 ASSY (4P-4FP) | E24: ='Kitting Plan'!D19 -> 1 | F24: ='Kitting Plan'!E19 -> 13 | G24: =SUMIFS('COOIS Data'!$I$6:$I$1505,'COOIS Data'!$B$6:$B$1505,C24) -> 13 | H24: =IF(E24=0,0,INT(G24/E24)) -> 13 | I24: =MAX(0,G24-F24) -> 0 | J24: =SUMIFS('COOIS Data'!$J$6:$J$1505,'COOIS Data'!$B$6:$B$1505,C24) -> 7 | K24: =IF(E24=0,0,INT(J24/E24)) -> 7 | L24: =SUMIFS('COOIS Data'!$K$6:$K$1505,'COOIS Data'!$B$6:$B$1505,C24) -> 6 | M24: =IF(E24=0,0,INT(L24/E24)) -> 6 | N24: =G24-L24 -> 7
C25: TOTAL / MIN | D25: Rep kits / reps columns show the MIN — the limiting code | F25: =SUM(F11:F24) -> 663 | G25: =SUM(G11:G24) -> 691 | H25: =MIN(H11:H24) -> 13 | I25: =SUM(I11:I24) -> 28 | J25: =SUM(J11:J24) -> 440 | K25: =MIN(K11:K24) -> 7 | L25: =SUM(L11:L24) -> 414 | M25: =MIN(M11:M24) -> 5 | N25: =SUM(N11:N24) -> 277
B27: REPEATER KIT TRACKER | D27: WOs are assigned to repeaters in release order (oldest first). K = kitted · I = components issued · D = delivered · – = not kitted
B28: Sequence | C28: Assy Code | D28: Description | E28: Rep 1 | F28: Rep 2 | G28: Rep 3 | H28: Rep 4 | I28: Rep 5 | J28: Rep 6 | K28: Rep 7 | L28: Rep 8 | M28: Rep 9 | N28: Rep 10 | O28: Rep 11 | P28: Rep 12 | Q28: Rep 13
B29: =B11 -> LASER ASSY | C29: =C11 -> 92YLS00548BAA | D29: =D11 -> R5B LASER ASSEMBLY 4P BOAT 1 - E2A | E29: =IF(COUNTIFS('COOIS Data'!$B$6:$B$1505,$C29,'COOIS Data'!$N$6:$N$1505,1,'COOIS Data'!$I$6:$I$1505,">0")<$E11,"–",IF(COUNTIFS('COOIS Data'!$B$6:$B$1505,$C29,'COOIS Data'!$N$6:$N$1505,1,'COOIS Data'!$K$6:$K$1505,">0")>=$E11,"D",IF(COUNTIFS('COOIS Data'!$B$6:$B$1505,$C29,'COOIS Data'!$N$6:$N$1505,1,'COOIS Data'!$J$6:$J$1505,">0")>=$E11,"I","K"))) -> D | F29: =IF(COUNTIFS('COOIS Data'!$B$6:$B$1505,$C29,'COOIS Data'!$N$6:$N$1505,2,'COOIS Data'!$I$6:$I$1505,">0")<$E11,"–",IF(COUNTIFS('COOIS Data'!$B$6:$B$1505,$C29,'COOIS Data'!$N$6:$N$1505,2,'COOIS Data'!$K$6:$K$1505,">0")>=$E11,"D",IF(COUNTIFS('COOIS Data'!$B$6:$B$1505,$C29,'COOIS Data'!$N$6:$N$1505,2,'COOIS Data'!$J$6:$J$1505,">0")>=$E11,"I","K"))) -> D | G29: =IF(COUNTIFS('COOIS Data'!$B$6:$B$1505,$C29,'COOIS Data'!$N$6:$N$1505,3,'COOIS Data'!$I$6:$I$1505,">0")<$E11,"–",IF(COUNTIFS('COOIS Data'!$B$6:$B$1505,$C29,'COOIS Data'!$N$6:$N$1505,3,'COOIS Data'!$K$6:$K$1505,">0")>=$E11,"D",IF(COUNTIFS('COOIS Data'!$B$6:$B$1505,$C29,'COOIS Data'!$N$6:$N$1505,3,'COOIS Data'!$J$6:$J$1505,">0")>=$E11,"I","K"))) -> D | H29: =IF(COUNTIFS('COOIS Data'!$B$6:$B$1505,$C29,'COOIS Data'!$N$6:$N$1505,4,'COOIS Data'!$I$6:$I$1505,">0")<$E11,"–",IF(COUNTIFS('COOIS Data'!$B$6:$B$1505,$C29,'COOIS Data'!$N$6:$N$1505,4,'COOIS Data'!$K$6:$K$1505,">0")>=$E11,"D",IF(COUNTIFS('COOIS Data'!$B$6:$B$1505,$C29,'COOIS Data'!$N$6:$N$1505,4,'COOIS Data'!$J$6:$J$1505,">0")>=$E11,"I","K"))) -> D | I29: =IF(COUNTIFS('COOIS Data'!$B$6:$B$1505,$C29,'COOIS Data'!$N$6:$N$1505,5,'COOIS Data'!$I$6:$I$1505,">0")<$E11,"–",IF(COUNTIFS('COOIS Data'!$B$6:$B$1505,$C29,'COOIS Data'!$N$6:$N$1505,5,'COOIS Data'!$K$6:$K$1505,">0")>=$E11,"D",IF(COUNTIFS('COOIS Data'!$B$6:$B$1505,$C29,'COOIS Data'!$N$6:$N$1505,5,'COOIS Data'!$J$6:$J$1505,">0")>=$E11,"I","K"))) -> D | J29: =IF(COUNTIFS('COOIS Data'!$B$6:$B$1505,$C29,'COOIS Data'!$N$6:$N$1505,6,'COOIS Data'!$I$6:$I$1505,">0")<$E11,"–",IF(COUNTIFS('COOIS Data'!$B$6:$B$1505,$C29,'COOIS Data'!$N$6:$N$1505,6,'COOIS Data'!$K$6:$K$1505,">0")>=$E11,"D",IF(COUNTIFS('COOIS Data'!$B$6:$B$1505,$C29,'COOIS Data'!$N$6:$N$1505,6,'COOIS Data'!$J$6:$J$1505,">0")>=$E11,"I","K"))) -> D | K29: =IF(COUNTIFS('COOIS Data'!$B$6:$B$1505,$C29,'COOIS Data'!$N$6:$N$1505,7,'COOIS Data'!$I$6:$I$1505,">0")<$E11,"–",IF(COUNTIFS('COOIS Data'!$B$6:$B$1505,$C29,'COOIS Data'!$N$6:$N$1505,7,'COOIS Data'!$K$6:$K$1505,">0")>=$E11,"D",IF(COUNTIFS('COOIS Data'!$B$6:$B$1505,$C29,'COOIS Data'!$N$6:$N$1505,7,'COOIS Data'!$J$6:$J$1505,">0")>=$E11,"I","K"))) -> D | L29: =IF(COUNTIFS('COOIS Data'!$B$6:$B$1505,$C29,'COOIS Data'!$N$6:$N$1505,8,'COOIS Data'!$I$6:$I$1505,">0")<$E11,"–",IF(COUNTIFS('COOIS Data'!$B$6:$B$1505,$C29,'COOIS Data'!$N$6:$N$1505,8,'COOIS Data'!$K$6:$K$1505,">0")>=$E11,"D",IF(COUNTIFS('COOIS Data'!$B$6:$B$1505,$C29,'COOIS Data'!$N$6:$N$1505,8,'COOIS Data'!$J$6:$J$1505,">0")>=$E11,"I","K"))) -> D | M29: =IF(COUNTIFS('COOIS Data'!$B$6:$B$1505,$C29,'COOIS Data'!$N$6:$N$1505,9,'COOIS Data'!$I$6:$I$1505,">0")<$E11,"–",IF(COUNTIFS('COOIS Data'!$B$6:$B$1505,$C29,'COOIS Data'!$N$6:$N$1505,9,'COOIS Data'!$K$6:$K$1505,">0")>=$E11,"D",IF(COUNTIFS('COOIS Data'!$B$6:$B$1505,$C29,'COOIS Data'!$N$6:$N$1505,9,'COOIS Data'!$J$6:$J$1505,">0")>=$E11,"I","K"))) -> D | N29: =IF(COUNTIFS('COOIS Data'!$B$6:$B$1505,$C29,'COOIS Data'!$N$6:$N$1505,10,'COOIS Data'!$I$6:$I$1505,">0")<$E11,"–",IF(COUNTIFS('COOIS Data'!$B$6:$B$1505,$C29,'COOIS Data'!$N$6:$N$1505,10,'COOIS Data'!$K$6:$K$1505,">0")>=$E11,"D",IF(COUNTIFS('COOIS Data'!$B$6:$B$1505,$C29,'COOIS Data'!$N$6:$N$1505,10,'COOIS Data'!$J$6:$J$1505,">0")>=$E11,"I","K"))) -> I | O29: =IF(COUNTIFS('COOIS Data'!$B$6:$B$1505,$C29,'COOIS Data'!$N$6:$N$1505,11,'COOIS Data'!$I$6:$I$1505,">0")<$E11,"–",IF(COUNTIFS('COOIS Data'!$B$6:$B$1505,$C29,'COOIS Data'!$N$6:$N$1505,11,'COOIS Data'!$K$6:$K$1505,">0")>=$E11,"D",IF(COUNTIFS('COOIS Data'!$B$6:$B$1505,$C29,'COOIS Data'!$N$6:$N$1505,11,'COOIS Data'!$J$6:$J$1505,">0")>=$E11,"I","K"))) -> K | P29: =IF(COUNTIFS('COOIS Data'!$B$6:$B$1505,$C29,'COOIS Data'!$N$6:$N$1505,12,'COOIS Data'!$I$6:$I$1505,">0")<$E11,"–",IF(COUNTIFS('COOIS Data'!$B$6:$B$1505,$C29,'COOIS Data'!$N$6:$N$1505,12,'COOIS Data'!$K$6:$K$1505,">0")>=$E11,"D",IF(COUNTIFS('COOIS Data'!$B$6:$B$1505,$C29,'COOIS Data'!$N$6:$N$1505,12,'COOIS Data'!$J$6:$J$1505,">0")>=$E11,"I","K"))) -> K | Q29: =IF(COUNTIFS('COOIS Data'!$B$6:$B$1505,$C29,'COOIS Data'!$N$6:$N$1505,13,'COOIS Data'!$I$6:$I$1505,">0")<$E11,"–",IF(COUNTIFS('COOIS Data'!$B$6:$B$1505,$C29,'COOIS Data'!$N$6:$N$1505,13,'COOIS Data'!$K$6:$K$1505,">0")>=$E11,"D",IF(COUNTIFS('COOIS Data'!$B$6:$B$1505,$C29,'COOIS Data'!$N$6:$N$1505,13,'COOIS Data'!$J$6:$J$1505,">0")>=$E11,"I","K"))) -> K
B30: =B12 -> LASER ASSY | C30: =C12 -> 92YLS00548BBA | D30: =D12 -> R5B LASER ASSEMBLY 4P BOAT 2/3 - E2A | E30: =IF(COUNTIFS('COOIS Data'!$B$6:$B$1505,$C30,'COOIS Data'!$N$6:$N$1505,1,'COOIS Data'!$I$6:$I$1505,">0")<$E12,"–",IF(COUNTIFS('COOIS Data'!$B$6:$B$1505,$C30,'COOIS Data'!$N$6:$N$1505,1,'COOIS Data'!$K$6:$K$1505,">0")>=$E12,"D",IF(COUNTIFS('COOIS Data'!$B$6:$B$1505,$C30,'COOIS Data'!$N$6:$N$1505,1,'COOIS Data'!$J$6:$J$1505,">0")>=$E12,"I","K"))) -> D | F30: =IF(COUNTIFS('COOIS Data'!$B$6:$B$1505,$C30,'COOIS Data'!$N$6:$N$1505,2,'COOIS Data'!$I$6:$I$1505,">0")<$E12,"–",IF(COUNTIFS('COOIS Data'!$B$6:$B$1505,$C30,'COOIS Data'!$N$6:$N$1505,2,'COOIS Data'!$K$6:$K$1505,">0")>=$E12,"D",IF(COUNTIFS('COOIS Data'!$B$6:$B$1505,$C30,'COOIS Data'!$N$6:$N$1505,2,'COOIS Data'!$J$6:$J$1505,">0")>=$E12,"I","K"))) -> D | G30: =IF(COUNTIFS('COOIS Data'!$B$6:$B$1505,$C30,'COOIS Data'!$N$6:$N$1505,3,'COOIS Data'!$I$6:$I$1505,">0")<$E12,"–",IF(COUNTIFS('COOIS Data'!$B$6:$B$1505,$C30,'COOIS Data'!$N$6:$N$1505,3,'COOIS Data'!$K$6:$K$1505,">0")>=$E12,"D",IF(COUNTIFS('COOIS Data'!$B$6:$B$1505,$C30,'COOIS Data'!$N$6:$N$1505,3,'COOIS Data'!$J$6:$J$1505,">0")>=$E12,"I","K"))) -> D | H30: =IF(COUNTIFS('COOIS Data'!$B$6:$B$1505,$C30,'COOIS Data'!$N$6:$N$1505,4,'COOIS Data'!$I$6:$I$1505,">0")<$E12,"–",IF(COUNTIFS('COOIS Data'!$B$6:$B$1505,$C30,'COOIS Data'!$N$6:$N$1505,4,'COOIS Data'!$K$6:$K$1505,">0")>=$E12,"D",IF(COUNTIFS('COOIS Data'!$B$6:$B$1505,$C30,'COOIS Data'!$N$6:$N$1505,4,'COOIS Data'!$J$6:$J$1505,">0")>=$E12,"I","K"))) -> D | I30: =IF(COUNTIFS('COOIS Data'!$B$6:$B$1505,$C30,'COOIS Data'!$N$6:$N$1505,5,'COOIS Data'!$I$6:$I$1505,">0")<$E12,"–",IF(COUNTIFS('COOIS Data'!$B$6:$B$1505,$C30,'COOIS Data'!$N$6:$N$1505,5,'COOIS Data'!$K$6:$K$1505,">0")>=$E12,"D",IF(COUNTIFS('COOIS Data'!$B$6:$B$1505,$C30,'COOIS Data'!$N$6:$N$1505,5,'COOIS Data'!$J$6:$J$1505,">0")>=$E12,"I","K"))) -> D | J30: =IF(COUNTIFS('COOIS Data'!$B$6:$B$1505,$C30,'COOIS Data'!$N$6:$N$1505,6,'COOIS Data'!$I$6:$I$1505,">0")<$E12,"–",IF(COUNTIFS('COOIS Data'!$B$6:$B$1505,$C30,'COOIS Data'!$N$6:$N$1505,6,'COOIS Data'!$K$6:$K$1505,">0")>=$E12,"D",IF(COUNTIFS('COOIS Data'!$B$6:$B$1505,$C30,'COOIS Data'!$N$6:$N$1505,6,'COOIS Data'!$J$6:$J$1505,">0")>=$E12,"I","K"))) -> D | K30: =IF(COUNTIFS('COOIS Data'!$B$6:$B$1505,$C30,'COOIS Data'!$N$6:$N$1505,7,'COOIS Data'!$I$6:$I$1505,">0")<$E12,"–",IF(COUNTIFS('COOIS Data'!$B$6:$B$1505,$C30,'COOIS Data'!$N$6:$N$1505,7,'COOIS Data'!$K$6:$K$1505,">0")>=$E12,"D",IF(COUNTIFS('COOIS Data'!$B$6:$B$1505,$C30,'COOIS Data'!$N$6:$N$1505,7,'COOIS Data'!$J$6:$J$1505,">0")>=$E12,"I","K"))) -> D | L30: =IF(COUNTIFS('COOIS Data'!$B$6:$B$1505,$C30,'COOIS Data'!$N$6:$N$1505,8,'COOIS Data'!$I$6:$I$1505,">0")<$E12,"–",IF(COUNTIFS('COOIS Data'!$B$6:$B$1505,$C30,'COOIS Data'!$N$6:$N$1505,8,'COOIS Data'!$K$6:$K$1505,">0")>=$E12,"D",IF(COUNTIFS('COOIS Data'!$B$6:$B$1505,$C30,'COOIS Data'!$N$6:$N$1505,8,'COOIS Data'!$J$6:$J$1505,">0")>=$E12,"I","K"))) -> D | M30: =IF(COUNTIFS('COOIS Data'!$B$6:$B$1505,$C30,'COOIS Data'!$N$6:$N$1505,9,'COOIS Data'!$I$6:$I$1505,">0")<$E12,"–",IF(COUNTIFS('COOIS Data'!$B$6:$B$1505,$C30,'COOIS Data'!$N$6:$N$1505,9,'COOIS Data'!$K$6:$K$1505,">0")>=$E12,"D",IF(COUNTIFS('COOIS Data'!$B$6:$B$1505,$C30,'COOIS Data'!$N$6:$N$1505,9,'COOIS Data'!$J$6:$J$1505,">0")>=$E12,"I","K"))) -> I | N30: =IF(COUNTIFS('COOIS Data'!$B$6:$B$1505,$C30,'COOIS Data'!$N$6:$N$1505,10,'COOIS Data'!$I$6:$I$1505,">0")<$E12,"–",IF(COUNTIFS('COOIS Data'!$B$6:$B$1505,$C30,'COOIS Data'!$N$6:$N$1505,10,'COOIS Data'!$K$6:$K$1505,">0")>=$E12,"D",IF(COUNTIFS('COOIS Data'!$B$6:$B$1505,$C30,'COOIS Data'!$N$6:$N$1505,10,'COOIS Data'!$J$6:$J$1505,">0")>=$E12,"I","K"))) -> K | O30: =IF(COUNTIFS('COOIS Data'!$B$6:$B$1505,$C30,'COOIS Data'!$N$6:$N$1505,11,'COOIS Data'!$I$6:$I$1505,">0")<$E12,"–",IF(COUNTIFS('COOIS Data'!$B$6:$B$1505,$C30,'COOIS Data'!$N$6:$N$1505,11,'COOIS Data'!$K$6:$K$1505,">0")>=$E12,"D",IF(COUNTIFS('COOIS Data'!$B$6:$B$1505,$C30,'COOIS Data'!$N$6:$N$1505,11,'COOIS Data'!$J$6:$J$1505,">0")>=$E12,"I","K"))) -> K | P30: =IF(COUNTIFS('COOIS Data'!$B$6:$B$1505,$C30,'COOIS Data'!$N$6:$N$1505,12,'COOIS Data'!$I$6:$I$1505,">0")<$E12,"–",IF(COUNTIFS('COOIS Data'!$B$6:$B$1505,$C30,'COOIS Data'!$N$6:$N$1505,12,'COOIS Data'!$K$6:$K$1505,">0")>=$E12,"D",IF(COUNTIFS('COOIS Data'!$B$6:$B$1505,$C30,'COOIS Data'!$N$6:$N$1505,12,'COOIS Data'!$J$6:$J$1505,">0")>=$E12,"I","K"))) -> K | Q30: =IF(COUNTIFS('COOIS Data'!$B$6:$B$1505,$C30,'COOIS Data'!$N$6:$N$1505,13,'COOIS Data'!$I$6:$I$1505,">0")<$E12,"–",IF(COUNTIFS('COOIS Data'!$B$6:$B$1505,$C30,'COOIS Data'!$N$6:$N$1505,13,'COOIS Data'!$K$6:$K$1505,">0")>=$E12,"D",IF(COUNTIFS('COOIS Data'!$B$6:$B$1505,$C30,'COOIS Data'!$N$6:$N$1505,13,'COOIS Data'!$J$6:$J$1505,">0")>=$E12,"I","K"))) -> K
B31: =B13 -> PSB ASSY | C31: =C13 -> 91YAF03404AAA | D31: =D13 -> R5B PSB SUB ASSEMBLY 4P-4FP | E31: =IF(COUNTIFS('COOIS Data'!$B$6:$B$1505,$C31,'COOIS Data'!$N$6:$N$1505,1,'COOIS Data'!$I$6:$I$1505,">0")<$E13,"–",IF(COUNTIFS('COOIS Data'!$B$6:$B$1505,$C31,'COOIS Data'!$N$6:$N$1505,1,'COOIS Data'!$K$6:$K$1505,">0")>=$E13,"D",IF(COUNTIFS('COOIS Data'!$B$6:$B$1505,$C31,'COOIS Data'!$N$6:$N$1505,1,'COOIS Data'!$J$6:$J$1505,">0")>=$E13,"I","K"))) -> D | F31: =IF(COUNTIFS('COOIS Data'!$B$6:$B$1505,$C31,'COOIS Data'!$N$6:$N$1505,2,'COOIS Data'!$I$6:$I$1505,">0")<$E13,"–",IF(COUNTIFS('COOIS Data'!$B$6:$B$1505,$C31,'COOIS Data'!$N$6:$N$1505,2,'COOIS Data'!$K$6:$K$1505,">0")>=$E13,"D",IF(COUNTIFS('COOIS Data'!$B$6:$B$1505,$C31,'COOIS Data'!$N$6:$N$1505,2,'COOIS Data'!$J$6:$J$1505,">0")>=$E13,"I","K"))) -> D | G31: =IF(COUNTIFS('COOIS Data'!$B$6:$B$1505,$C31,'COOIS Data'!$N$6:$N$1505,3,'COOIS Data'!$I$6:$I$1505,">0")<$E13,"–",IF(COUNTIFS('COOIS Data'!$B$6:$B$1505,$C31,'COOIS Data'!$N$6:$N$1505,3,'COOIS Data'!$K$6:$K$1505,">0")>=$E13,"D",IF(COUNTIFS('COOIS Data'!$B$6:$B$1505,$C31,'COOIS Data'!$N$6:$N$1505,3,'COOIS Data'!$J$6:$J$1505,">0")>=$E13,"I","K"))) -> D | H31: =IF(COUNTIFS('COOIS Data'!$B$6:$B$1505,$C31,'COOIS Data'!$N$6:$N$1505,4,'COOIS Data'!$I$6:$I$1505,">0")<$E13,"–",IF(COUNTIFS('COOIS Data'!$B$6:$B$1505,$C31,'COOIS Data'!$N$6:$N$1505,4,'COOIS Data'!$K$6:$K$1505,">0")>=$E13,"D",IF(COUNTIFS('COOIS Data'!$B$6:$B$1505,$C31,'COOIS Data'!$N$6:$N$1505,4,'COOIS Data'!$J$6:$J$1505,">0")>=$E13,"I","K"))) -> D | I31: =IF(COUNTIFS('COOIS Data'!$B$6:$B$1505,$C31,'COOIS Data'!$N$6:$N$1505,5,'COOIS Data'!$I$6:$I$1505,">0")<$E13,"–",IF(COUNTIFS('COOIS Data'!$B$6:$B$1505,$C31,'COOIS Data'!$N$6:$N$1505,5,'COOIS Data'!$K$6:$K$1505,">0")>=$E13,"D",IF(COUNTIFS('COOIS Data'!$B$6:$B$1505,$C31,'COOIS Data'!$N$6:$N$1505,5,'COOIS Data'!$J$6:$J$1505,">0")>=$E13,"I","K"))) -> D | J31: =IF(COUNTIFS('COOIS Data'!$B$6:$B$1505,$C31,'COOIS Data'!$N$6:$N$1505,6,'COOIS Data'!$I$6:$I$1505,">0")<$E13,"–",IF(COUNTIFS('COOIS Data'!$B$6:$B$1505,$C31,'COOIS Data'!$N$6:$N$1505,6,'COOIS Data'!$K$6:$K$1505,">0")>=$E13,"D",IF(COUNTIFS('COOIS Data'!$B$6:$B$1505,$C31,'COOIS Data'!$N$6:$N$1505,6,'COOIS Data'!$J$6:$J$1505,">0")>=$E13,"I","K"))) -> D | K31: =IF(COUNTIFS('COOIS Data'!$B$6:$B$1505,$C31,'COOIS Data'!$N$6:$N$1505,7,'COOIS Data'!$I$6:$I$1505,">0")<$E13,"–",IF(COUNTIFS('COOIS Data'!$B$6:$B$1505,$C31,'COOIS Data'!$N$6:$N$1505,7,'COOIS Data'!$K$6:$K$1505,">0")>=$E13,"D",IF(COUNTIFS('COOIS Data'!$B$6:$B$1505,$C31,'COOIS Data'!$N$6:$N$1505,7,'COOIS Data'!$J$6:$J$1505,">0")>=$E13,"I","K"))) -> D | L31: =IF(COUNTIFS('COOIS Data'!$B$6:$B$1505,$C31,'COOIS Data'!$N$6:$N$1505,8,'COOIS Data'!$I$6:$I$1505,">0")<$E13,"–",IF(COUNTIFS('COOIS Data'!$B$6:$B$1505,$C31,'COOIS Data'!$N$6:$N$1505,8,'COOIS Data'!$K$6:$K$1505,">0")>=$E13,"D",IF(COUNTIFS('COOIS Data'!$B$6:$B$1505,$C31,'COOIS Data'!$N$6:$N$1505,8,'COOIS Data'!$J$6:$J$1505,">0")>=$E13,"I","K"))) -> D | M31: =IF(COUNTIFS('COOIS Data'!$B$6:$B$1505,$C31,'COOIS Data'!$N$6:$N$1505,9,'COOIS Data'!$I$6:$I$1505,">0")<$E13,"–",IF(COUNTIFS('COOIS Data'!$B$6:$B$1505,$C31,'COOIS Data'!$N$6:$N$1505,9,'COOIS Data'!$K$6:$K$1505,">0")>=$E13,"D",IF(COUNTIFS('COOIS Data'!$B$6:$B$1505,$C31,'COOIS Data'!$N$6:$N$1505,9,'COOIS Data'!$J$6:$J$1505,">0")>=$E13,"I","K"))) -> D | N31: =IF(COUNTIFS('COOIS Data'!$B$6:$B$1505,$C31,'COOIS Data'!$N$6:$N$1505,10,'COOIS Data'!$I$6:$I$1505,">0")<$E13,"–",IF(COUNTIFS('COOIS Data'!$B$6:$B$1505,$C31,'COOIS Data'!$N$6:$N$1505,10,'COOIS Data'!$K$6:$K$1505,">0")>=$E13,"D",IF(COUNTIFS('COOIS Data'!$B$6:$B$1505,$C31,'COOIS Data'!$N$6:$N$1505,10,'COOIS Data'!$J$6:$J$1505,">0")>=$E13,"I","K"))) -> D | O31: =IF(COUNTIFS('COOIS Data'!$B$6:$B$1505,$C31,'COOIS Data'!$N$6:$N$1505,11,'COOIS Data'!$I$6:$I$1505,">0")<$E13,"–",IF(COUNTIFS('COOIS Data'!$B$6:$B$1505,$C31,'COOIS Data'!$N$6:$N$1505,11,'COOIS Data'!$K$6:$K$1505,">0")>=$E13,"D",IF(COUNTIFS('COOIS Data'!$B$6:$B$1505,$C31,'COOIS Data'!$N$6:$N$1505,11,'COOIS Data'!$J$6:$J$1505,">0")>=$E13,"I","K"))) -> K | P31: =IF(COUNTIFS('COOIS Data'!$B$6:$B$1505,$C31,'COOIS Data'!$N$6:$N$1505,12,'COOIS Data'!$I$6:$I$1505,">0")<$E13,"–",IF(COUNTIFS('COOIS Data'!$B$6:$B$1505,$C31,'COOIS Data'!$N$6:$N$1505,12,'COOIS Data'!$K$6:$K$1505,">0")>=$E13,"D",IF(COUNTIFS('COOIS Data'!$B$6:$B$1505,$C31,'COOIS Data'!$N$6:$N$1505,12,'COOIS Data'!$J$6:$J$1505,">0")>=$E13,"I","K"))) -> K | Q31: =IF(COUNTIFS('COOIS Data'!$B$6:$B$1505,$C31,'COOIS Data'!$N$6:$N$1505,13,'COOIS Data'!$I$6:$I$1505,">0")<$E13,"–",IF(COUNTIFS('COOIS Data'!$B$6:$B$1505,$C31,'COOIS Data'!$N$6:$N$1505,13,'COOIS Data'!$K$6:$K$1505,">0")>=$E13,"D",IF(COUNTIFS('COOIS Data'!$B$6:$B$1505,$C31,'COOIS Data'!$N$6:$N$1505,13,'COOIS Data'!$J$6:$J$1505,">0")>=$E13,"I","K"))) -> D
B32: =B14 -> OPF ASSY | C32: =C14 -> 92YFD04548BAA | D32: =D14 -> R5B OPF ASSEMBLY (4P-4FP) BOAT 1 - E2A | E32: =IF(COUNTIFS('COOIS Data'!$B$6:$B$1505,$C32,'COOIS Data'!$N$6:$N$1505,1,'COOIS Data'!$I$6:$I$1505,">0")<$E14,"–",IF(COUNTIFS('COOIS Data'!$B$6:$B$1505,$C32,'COOIS Data'!$N$6:$N$1505,1,'COOIS Data'!$K$6:$K$1505,">0")>=$E14,"D",IF(COUNTIFS('COOIS Data'!$B$6:$B$1505,$C32,'COOIS Data'!$N$6:$N$1505,1,'COOIS Data'!$J$6:$J$1505,">0")>=$E14,"I","K"))) -> D | F32: =IF(COUNTIFS('COOIS Data'!$B$6:$B$1505,$C32,'COOIS Data'!$N$6:$N$1505,2,'COOIS Data'!$I$6:$I$1505,">0")<$E14,"–",IF(COUNTIFS('COOIS Data'!$B$6:$B$1505,$C32,'COOIS Data'!$N$6:$N$1505,2,'COOIS Data'!$K$6:$K$1505,">0")>=$E14,"D",IF(COUNTIFS('COOIS Data'!$B$6:$B$1505,$C32,'COOIS Data'!$N$6:$N$1505,2,'COOIS Data'!$J$6:$J$1505,">0")>=$E14,"I","K"))) -> D | G32: =IF(COUNTIFS('COOIS Data'!$B$6:$B$1505,$C32,'COOIS Data'!$N$6:$N$1505,3,'COOIS Data'!$I$6:$I$1505,">0")<$E14,"–",IF(COUNTIFS('COOIS Data'!$B$6:$B$1505,$C32,'COOIS Data'!$N$6:$N$1505,3,'COOIS Data'!$K$6:$K$1505,">0")>=$E14,"D",IF(COUNTIFS('COOIS Data'!$B$6:$B$1505,$C32,'COOIS Data'!$N$6:$N$1505,3,'COOIS Data'!$J$6:$J$1505,">0")>=$E14,"I","K"))) -> D | H32: =IF(COUNTIFS('COOIS Data'!$B$6:$B$1505,$C32,'COOIS Data'!$N$6:$N$1505,4,'COOIS Data'!$I$6:$I$1505,">0")<$E14,"–",IF(COUNTIFS('COOIS Data'!$B$6:$B$1505,$C32,'COOIS Data'!$N$6:$N$1505,4,'COOIS Data'!$K$6:$K$1505,">0")>=$E14,"D",IF(COUNTIFS('COOIS Data'!$B$6:$B$1505,$C32,'COOIS Data'!$N$6:$N$1505,4,'COOIS Data'!$J$6:$J$1505,">0")>=$E14,"I","K"))) -> D | I32: =IF(COUNTIFS('COOIS Data'!$B$6:$B$1505,$C32,'COOIS Data'!$N$6:$N$1505,5,'COOIS Data'!$I$6:$I$1505,">0")<$E14,"–",IF(COUNTIFS('COOIS Data'!$B$6:$B$1505,$C32,'COOIS Data'!$N$6:$N$1505,5,'COOIS Data'!$K$6:$K$1505,">0")>=$E14,"D",IF(COUNTIFS('COOIS Data'!$B$6:$B$1505,$C32,'COOIS Data'!$N$6:$N$1505,5,'COOIS Data'!$J$6:$J$1505,">0")>=$E14,"I","K"))) -> D | J32: =IF(COUNTIFS('COOIS Data'!$B$6:$B$1505,$C32,'COOIS Data'!$N$6:$N$1505,6,'COOIS Data'!$I$6:$I$1505,">0")<$E14,"–",IF(COUNTIFS('COOIS Data'!$B$6:$B$1505,$C32,'COOIS Data'!$N$6:$N$1505,6,'COOIS Data'!$K$6:$K$1505,">0")>=$E14,"D",IF(COUNTIFS('COOIS Data'!$B$6:$B$1505,$C32,'COOIS Data'!$N$6:$N$1505,6,'COOIS Data'!$J$6:$J$1505,">0")>=$E14,"I","K"))) -> D | K32: =IF(COUNTIFS('COOIS Data'!$B$6:$B$1505,$C32,'COOIS Data'!$N$6:$N$1505,7,'COOIS Data'!$I$6:$I$1505,">0")<$E14,"–",IF(COUNTIFS('COOIS Data'!$B$6:$B$1505,$C32,'COOIS Data'!$N$6:$N$1505,7,'COOIS Data'!$K$6:$K$1505,">0")>=$E14,"D",IF(COUNTIFS('COOIS Data'!$B$6:$B$1505,$C32,'COOIS Data'!$N$6:$N$1505,7,'COOIS Data'!$J$6:$J$1505,">0")>=$E14,"I","K"))) -> D | L32: =IF(COUNTIFS('COOIS Data'!$B$6:$B$1505,$C32,'COOIS Data'!$N$6:$N$1505,8,'COOIS Data'!$I$6:$I$1505,">0")<$E14,"–",IF(COUNTIFS('COOIS Data'!$B$6:$B$1505,$C32,'COOIS Data'!$N$6:$N$1505,8,'COOIS Data'!$K$6:$K$1505,">0")>=$E14,"D",IF(COUNTIFS('COOIS Data'!$B$6:$B$1505,$C32,'COOIS Data'!$N$6:$N$1505,8,'COOIS Data'!$J$6:$J$1505,">0")>=$E14,"I","K"))) -> D | M32: =IF(COUNTIFS('COOIS Data'!$B$6:$B$1505,$C32,'COOIS Data'!$N$6:$N$1505,9,'COOIS Data'!$I$6:$I$1505,">0")<$E14,"–",IF(COUNTIFS('COOIS Data'!$B$6:$B$1505,$C32,'COOIS Data'!$N$6:$N$1505,9,'COOIS Data'!$K$6:$K$1505,">0")>=$E14,"D",IF(COUNTIFS('COOIS Data'!$B$6:$B$1505,$C32,'COOIS Data'!$N$6:$N$1505,9,'COOIS Data'!$J$6:$J$1505,">0")>=$E14,"I","K"))) -> I | N32: =IF(COUNTIFS('COOIS Data'!$B$6:$B$1505,$C32,'COOIS Data'!$N$6:$N$1505,10,'COOIS Data'!$I$6:$I$1505,">0")<$E14,"–",IF(COUNTIFS('COOIS Data'!$B$6:$B$1505,$C32,'COOIS Data'!$N$6:$N$1505,10,'COOIS Data'!$K$6:$K$1505,">0")>=$E14,"D",IF(COUNTIFS('COOIS Data'!$B$6:$B$1505,$C32,'COOIS Data'!$N$6:$N$1505,10,'COOIS Data'!$J$6:$J$1505,">0")>=$E14,"I","K"))) -> K | O32: =IF(COUNTIFS('COOIS Data'!$B$6:$B$1505,$C32,'COOIS Data'!$N$6:$N$1505,11,'COOIS Data'!$I$6:$I$1505,">0")<$E14,"–",IF(COUNTIFS('COOIS Data'!$B$6:$B$1505,$C32,'COOIS Data'!$N$6:$N$1505,11,'COOIS Data'!$K$6:$K$1505,">0")>=$E14,"D",IF(COUNTIFS('COOIS Data'!$B$6:$B$1505,$C32,'COOIS Data'!$N$6:$N$1505,11,'COOIS Data'!$J$6:$J$1505,">0")>=$E14,"I","K"))) -> K | P32: =IF(COUNTIFS('COOIS Data'!$B$6:$B$1505,$C32,'COOIS Data'!$N$6:$N$1505,12,'COOIS Data'!$I$6:$I$1505,">0")<$E14,"–",IF(COUNTIFS('COOIS Data'!$B$6:$B$1505,$C32,'COOIS Data'!$N$6:$N$1505,12,'COOIS Data'!$K$6:$K$1505,">0")>=$E14,"D",IF(COUNTIFS('COOIS Data'!$B$6:$B$1505,$C32,'COOIS Data'!$N$6:$N$1505,12,'COOIS Data'!$J$6:$J$1505,">0")>=$E14,"I","K"))) -> K | Q32: =IF(COUNTIFS('COOIS Data'!$B$6:$B$1505,$C32,'COOIS Data'!$N$6:$N$1505,13,'COOIS Data'!$I$6:$I$1505,">0")<$E14,"–",IF(COUNTIFS('COOIS Data'!$B$6:$B$1505,$C32,'COOIS Data'!$N$6:$N$1505,13,'COOIS Data'!$K$6:$K$1505,">0")>=$E14,"D",IF(COUNTIFS('COOIS Data'!$B$6:$B$1505,$C32,'COOIS Data'!$N$6:$N$1505,13,'COOIS Data'!$J$6:$J$1505,">0")>=$E14,"I","K"))) -> K
B33: =B15 -> OPF ASSY | C33: =C15 -> 92YFD04548BBA | D33: =D15 -> R5B OPF ASSEMBLY (4P-4FP) BOAT 2/3 - E2A | E33: =IF(COUNTIFS('COOIS Data'!$B$6:$B$1505,$C33,'COOIS Data'!$N$6:$N$1505,1,'COOIS Data'!$I$6:$I$1505,">0")<$E15,"–",IF(COUNTIFS('COOIS Data'!$B$6:$B$1505,$C33,'COOIS Data'!$N$6:$N$1505,1,'COOIS Data'!$K$6:$K$1505,">0")>=$E15,"D",IF(COUNTIFS('COOIS Data'!$B$6:$B$1505,$C33,'COOIS Data'!$N$6:$N$1505,1,'COOIS Data'!$J$6:$J$1505,">0")>=$E15,"I","K"))) -> D | F33: =IF(COUNTIFS('COOIS Data'!$B$6:$B$1505,$C33,'COOIS Data'!$N$6:$N$1505,2,'COOIS Data'!$I$6:$I$1505,">0")<$E15,"–",IF(COUNTIFS('COOIS Data'!$B$6:$B$1505,$C33,'COOIS Data'!$N$6:$N$1505,2,'COOIS Data'!$K$6:$K$1505,">0")>=$E15,"D",IF(COUNTIFS('COOIS Data'!$B$6:$B$1505,$C33,'COOIS Data'!$N$6:$N$1505,2,'COOIS Data'!$J$6:$J$1505,">0")>=$E15,"I","K"))) -> D | G33: =IF(COUNTIFS('COOIS Data'!$B$6:$B$1505,$C33,'COOIS Data'!$N$6:$N$1505,3,'COOIS Data'!$I$6:$I$1505,">0")<$E15,"–",IF(COUNTIFS('COOIS Data'!$B$6:$B$1505,$C33,'COOIS Data'!$N$6:$N$1505,3,'COOIS Data'!$K$6:$K$1505,">0")>=$E15,"D",IF(COUNTIFS('COOIS Data'!$B$6:$B$1505,$C33,'COOIS Data'!$N$6:$N$1505,3,'COOIS Data'!$J$6:$J$1505,">0")>=$E15,"I","K"))) -> D | H33: =IF(COUNTIFS('COOIS Data'!$B$6:$B$1505,$C33,'COOIS Data'!$N$6:$N$1505,4,'COOIS Data'!$I$6:$I$1505,">0")<$E15,"–",IF(COUNTIFS('COOIS Data'!$B$6:$B$1505,$C33,'COOIS Data'!$N$6:$N$1505,4,'COOIS Data'!$K$6:$K$1505,">0")>=$E15,"D",IF(COUNTIFS('COOIS Data'!$B$6:$B$1505,$C33,'COOIS Data'!$N$6:$N$1505,4,'COOIS Data'!$J$6:$J$1505,">0")>=$E15,"I","K"))) -> D | I33: =IF(COUNTIFS('COOIS Data'!$B$6:$B$1505,$C33,'COOIS Data'!$N$6:$N$1505,5,'COOIS Data'!$I$6:$I$1505,">0")<$E15,"–",IF(COUNTIFS('COOIS Data'!$B$6:$B$1505,$C33,'COOIS Data'!$N$6:$N$1505,5,'COOIS Data'!$K$6:$K$1505,">0")>=$E15,"D",IF(COUNTIFS('COOIS Data'!$B$6:$B$1505,$C33,'COOIS Data'!$N$6:$N$1505,5,'COOIS Data'!$J$6:$J$1505,">0")>=$E15,"I","K"))) -> D | J33: =IF(COUNTIFS('COOIS Data'!$B$6:$B$1505,$C33,'COOIS Data'!$N$6:$N$1505,6,'COOIS Data'!$I$6:$I$1505,">0")<$E15,"–",IF(COUNTIFS('COOIS Data'!$B$6:$B$1505,$C33,'COOIS Data'!$N$6:$N$1505,6,'COOIS Data'!$K$6:$K$1505,">0")>=$E15,"D",IF(COUNTIFS('COOIS Data'!$B$6:$B$1505,$C33,'COOIS Data'!$N$6:$N$1505,6,'COOIS Data'!$J$6:$J$1505,">0")>=$E15,"I","K"))) -> D | K33: =IF(COUNTIFS('COOIS Data'!$B$6:$B$1505,$C33,'COOIS Data'!$N$6:$N$1505,7,'COOIS Data'!$I$6:$I$1505,">0")<$E15,"–",IF(COUNTIFS('COOIS Data'!$B$6:$B$1505,$C33,'COOIS Data'!$N$6:$N$1505,7,'COOIS Data'!$K$6:$K$1505,">0")>=$E15,"D",IF(COUNTIFS('COOIS Data'!$B$6:$B$1505,$C33,'COOIS Data'!$N$6:$N$1505,7,'COOIS Data'!$J$6:$J$1505,">0")>=$E15,"I","K"))) -> D | L33: =IF(COUNTIFS('COOIS Data'!$B$6:$B$1505,$C33,'COOIS Data'!$N$6:$N$1505,8,'COOIS Data'!$I$6:$I$1505,">0")<$E15,"–",IF(COUNTIFS('COOIS Data'!$B$6:$B$1505,$C33,'COOIS Data'!$N$6:$N$1505,8,'COOIS Data'!$K$6:$K$1505,">0")>=$E15,"D",IF(COUNTIFS('COOIS Data'!$B$6:$B$1505,$C33,'COOIS Data'!$N$6:$N$1505,8,'COOIS Data'!$J$6:$J$1505,">0")>=$E15,"I","K"))) -> I | M33: =IF(COUNTIFS('COOIS Data'!$B$6:$B$1505,$C33,'COOIS Data'!$N$6:$N$1505,9,'COOIS Data'!$I$6:$I$1505,">0")<$E15,"–",IF(COUNTIFS('COOIS Data'!$B$6:$B$1505,$C33,'COOIS Data'!$N$6:$N$1505,9,'COOIS Data'!$K$6:$K$1505,">0")>=$E15,"D",IF(COUNTIFS('COOIS Data'!$B$6:$B$1505,$C33,'COOIS Data'!$N$6:$N$1505,9,'COOIS Data'!$J$6:$J$1505,">0")>=$E15,"I","K"))) -> K | N33: =IF(COUNTIFS('COOIS Data'!$B$6:$B$1505,$C33,'COOIS Data'!$N$6:$N$1505,10,'COOIS Data'!$I$6:$I$1505,">0")<$E15,"–",IF(COUNTIFS('COOIS Data'!$B$6:$B$1505,$C33,'COOIS Data'!$N$6:$N$1505,10,'COOIS Data'!$K$6:$K$1505,">0")>=$E15,"D",IF(COUNTIFS('COOIS Data'!$B$6:$B$1505,$C33,'COOIS Data'!$N$6:$N$1505,10,'COOIS Data'!$J$6:$J$1505,">0")>=$E15,"I","K"))) -> K | O33: =IF(COUNTIFS('COOIS Data'!$B$6:$B$1505,$C33,'COOIS Data'!$N$6:$N$1505,11,'COOIS Data'!$I$6:$I$1505,">0")<$E15,"–",IF(COUNTIFS('COOIS Data'!$B$6:$B$1505,$C33,'COOIS Data'!$N$6:$N$1505,11,'COOIS Data'!$K$6:$K$1505,">0")>=$E15,"D",IF(COUNTIFS('COOIS Data'!$B$6:$B$1505,$C33,'COOIS Data'!$N$6:$N$1505,11,'COOIS Data'!$J$6:$J$1505,">0")>=$E15,"I","K"))) -> K | P33: =IF(COUNTIFS('COOIS Data'!$B$6:$B$1505,$C33,'COOIS Data'!$N$6:$N$1505,12,'COOIS Data'!$I$6:$I$1505,">0")<$E15,"–",IF(COUNTIFS('COOIS Data'!$B$6:$B$1505,$C33,'COOIS Data'!$N$6:$N$1505,12,'COOIS Data'!$K$6:$K$1505,">0")>=$E15,"D",IF(COUNTIFS('COOIS Data'!$B$6:$B$1505,$C33,'COOIS Data'!$N$6:$N$1505,12,'COOIS Data'!$J$6:$J$1505,">0")>=$E15,"I","K"))) -> K | Q33: =IF(COUNTIFS('COOIS Data'!$B$6:$B$1505,$C33,'COOIS Data'!$N$6:$N$1505,13,'COOIS Data'!$I$6:$I$1505,">0")<$E15,"–",IF(COUNTIFS('COOIS Data'!$B$6:$B$1505,$C33,'COOIS Data'!$N$6:$N$1505,13,'COOIS Data'!$K$6:$K$1505,">0")>=$E15,"D",IF(COUNTIFS('COOIS Data'!$B$6:$B$1505,$C33,'COOIS Data'!$N$6:$N$1505,13,'COOIS Data'!$J$6:$J$1505,">0")>=$E15,"I","K"))) -> K
B34: =B16 -> POB ASSY | C34: =C16 -> 92YWS04548AAA | D34: =D16 -> R5B 4FP POB LUMENTUM SUB ASSEMBLY - E2A | E34: =IF(COUNTIFS('COOIS Data'!$B$6:$B$1505,$C34,'COOIS Data'!$N$6:$N$1505,1,'COOIS Data'!$I$6:$I$1505,">0")<$E16,"–",IF(COUNTIFS('COOIS Data'!$B$6:$B$1505,$C34,'COOIS Data'!$N$6:$N$1505,1,'COOIS Data'!$K$6:$K$1505,">0")>=$E16,"D",IF(COUNTIFS('COOIS Data'!$B$6:$B$1505,$C34,'COOIS Data'!$N$6:$N$1505,1,'COOIS Data'!$J$6:$J$1505,">0")>=$E16,"I","K"))) -> D | F34: =IF(COUNTIFS('COOIS Data'!$B$6:$B$1505,$C34,'COOIS Data'!$N$6:$N$1505,2,'COOIS Data'!$I$6:$I$1505,">0")<$E16,"–",IF(COUNTIFS('COOIS Data'!$B$6:$B$1505,$C34,'COOIS Data'!$N$6:$N$1505,2,'COOIS Data'!$K$6:$K$1505,">0")>=$E16,"D",IF(COUNTIFS('COOIS Data'!$B$6:$B$1505,$C34,'COOIS Data'!$N$6:$N$1505,2,'COOIS Data'!$J$6:$J$1505,">0")>=$E16,"I","K"))) -> D | G34: =IF(COUNTIFS('COOIS Data'!$B$6:$B$1505,$C34,'COOIS Data'!$N$6:$N$1505,3,'COOIS Data'!$I$6:$I$1505,">0")<$E16,"–",IF(COUNTIFS('COOIS Data'!$B$6:$B$1505,$C34,'COOIS Data'!$N$6:$N$1505,3,'COOIS Data'!$K$6:$K$1505,">0")>=$E16,"D",IF(COUNTIFS('COOIS Data'!$B$6:$B$1505,$C34,'COOIS Data'!$N$6:$N$1505,3,'COOIS Data'!$J$6:$J$1505,">0")>=$E16,"I","K"))) -> D | H34: =IF(COUNTIFS('COOIS Data'!$B$6:$B$1505,$C34,'COOIS Data'!$N$6:$N$1505,4,'COOIS Data'!$I$6:$I$1505,">0")<$E16,"–",IF(COUNTIFS('COOIS Data'!$B$6:$B$1505,$C34,'COOIS Data'!$N$6:$N$1505,4,'COOIS Data'!$K$6:$K$1505,">0")>=$E16,"D",IF(COUNTIFS('COOIS Data'!$B$6:$B$1505,$C34,'COOIS Data'!$N$6:$N$1505,4,'COOIS Data'!$J$6:$J$1505,">0")>=$E16,"I","K"))) -> D | I34: =IF(COUNTIFS('COOIS Data'!$B$6:$B$1505,$C34,'COOIS Data'!$N$6:$N$1505,5,'COOIS Data'!$I$6:$I$1505,">0")<$E16,"–",IF(COUNTIFS('COOIS Data'!$B$6:$B$1505,$C34,'COOIS Data'!$N$6:$N$1505,5,'COOIS Data'!$K$6:$K$1505,">0")>=$E16,"D",IF(COUNTIFS('COOIS Data'!$B$6:$B$1505,$C34,'COOIS Data'!$N$6:$N$1505,5,'COOIS Data'!$J$6:$J$1505,">0")>=$E16,"I","K"))) -> D | J34: =IF(COUNTIFS('COOIS Data'!$B$6:$B$1505,$C34,'COOIS Data'!$N$6:$N$1505,6,'COOIS Data'!$I$6:$I$1505,">0")<$E16,"–",IF(COUNTIFS('COOIS Data'!$B$6:$B$1505,$C34,'COOIS Data'!$N$6:$N$1505,6,'COOIS Data'!$K$6:$K$1505,">0")>=$E16,"D",IF(COUNTIFS('COOIS Data'!$B$6:$B$1505,$C34,'COOIS Data'!$N$6:$N$1505,6,'COOIS Data'!$J$6:$J$1505,">0")>=$E16,"I","K"))) -> D | K34: =IF(COUNTIFS('COOIS Data'!$B$6:$B$1505,$C34,'COOIS Data'!$N$6:$N$1505,7,'COOIS Data'!$I$6:$I$1505,">0")<$E16,"–",IF(COUNTIFS('COOIS Data'!$B$6:$B$1505,$C34,'COOIS Data'!$N$6:$N$1505,7,'COOIS Data'!$K$6:$K$1505,">0")>=$E16,"D",IF(COUNTIFS('COOIS Data'!$B$6:$B$1505,$C34,'COOIS Data'!$N$6:$N$1505,7,'COOIS Data'!$J$6:$J$1505,">0")>=$E16,"I","K"))) -> D | L34: =IF(COUNTIFS('COOIS Data'!$B$6:$B$1505,$C34,'COOIS Data'!$N$6:$N$1505,8,'COOIS Data'!$I$6:$I$1505,">0")<$E16,"–",IF(COUNTIFS('COOIS Data'!$B$6:$B$1505,$C34,'COOIS Data'!$N$6:$N$1505,8,'COOIS Data'!$K$6:$K$1505,">0")>=$E16,"D",IF(COUNTIFS('COOIS Data'!$B$6:$B$1505,$C34,'COOIS Data'!$N$6:$N$1505,8,'COOIS Data'!$J$6:$J$1505,">0")>=$E16,"I","K"))) -> D | M34: =IF(COUNTIFS('COOIS Data'!$B$6:$B$1505,$C34,'COOIS Data'!$N$6:$N$1505,9,'COOIS Data'!$I$6:$I$1505,">0")<$E16,"–",IF(COUNTIFS('COOIS Data'!$B$6:$B$1505,$C34,'COOIS Data'!$N$6:$N$1505,9,'COOIS Data'!$K$6:$K$1505,">0")>=$E16,"D",IF(COUNTIFS('COOIS Data'!$B$6:$B$1505,$C34,'COOIS Data'!$N$6:$N$1505,9,'COOIS Data'!$J$6:$J$1505,">0")>=$E16,"I","K"))) -> D | N34: =IF(COUNTIFS('COOIS Data'!$B$6:$B$1505,$C34,'COOIS Data'!$N$6:$N$1505,10,'COOIS Data'!$I$6:$I$1505,">0")<$E16,"–",IF(COUNTIFS('COOIS Data'!$B$6:$B$1505,$C34,'COOIS Data'!$N$6:$N$1505,10,'COOIS Data'!$K$6:$K$1505,">0")>=$E16,"D",IF(COUNTIFS('COOIS Data'!$B$6:$B$1505,$C34,'COOIS Data'!$N$6:$N$1505,10,'COOIS Data'!$J$6:$J$1505,">0")>=$E16,"I","K"))) -> K | O34: =IF(COUNTIFS('COOIS Data'!$B$6:$B$1505,$C34,'COOIS Data'!$N$6:$N$1505,11,'COOIS Data'!$I$6:$I$1505,">0")<$E16,"–",IF(COUNTIFS('COOIS Data'!$B$6:$B$1505,$C34,'COOIS Data'!$N$6:$N$1505,11,'COOIS Data'!$K$6:$K$1505,">0")>=$E16,"D",IF(COUNTIFS('COOIS Data'!$B$6:$B$1505,$C34,'COOIS Data'!$N$6:$N$1505,11,'COOIS Data'!$J$6:$J$1505,">0")>=$E16,"I","K"))) -> K | P34: =IF(COUNTIFS('COOIS Data'!$B$6:$B$1505,$C34,'COOIS Data'!$N$6:$N$1505,12,'COOIS Data'!$I$6:$I$1505,">0")<$E16,"–",IF(COUNTIFS('COOIS Data'!$B$6:$B$1505,$C34,'COOIS Data'!$N$6:$N$1505,12,'COOIS Data'!$K$6:$K$1505,">0")>=$E16,"D",IF(COUNTIFS('COOIS Data'!$B$6:$B$1505,$C34,'COOIS Data'!$N$6:$N$1505,12,'COOIS Data'!$J$6:$J$1505,">0")>=$E16,"I","K"))) -> K | Q34: =IF(COUNTIFS('COOIS Data'!$B$6:$B$1505,$C34,'COOIS Data'!$N$6:$N$1505,13,'COOIS Data'!$I$6:$I$1505,">0")<$E16,"–",IF(COUNTIFS('COOIS Data'!$B$6:$B$1505,$C34,'COOIS Data'!$N$6:$N$1505,13,'COOIS Data'!$K$6:$K$1505,">0")>=$E16,"D",IF(COUNTIFS('COOIS Data'!$B$6:$B$1505,$C34,'COOIS Data'!$N$6:$N$1505,13,'COOIS Data'!$J$6:$J$1505,">0")>=$E16,"I","K"))) -> K
B35: =B17 -> ERBIUM ASSY | C35: =C17 -> 92RRA00548AAA | D35: =D17 -> R5B ERBIUM SPOOL ASSEMBLY - E2A | E35: =IF(COUNTIFS('COOIS Data'!$B$6:$B$1505,$C35,'COOIS Data'!$N$6:$N$1505,1,'COOIS Data'!$I$6:$I$1505,">0")<$E17,"–",IF(COUNTIFS('COOIS Data'!$B$6:$B$1505,$C35,'COOIS Data'!$N$6:$N$1505,1,'COOIS Data'!$K$6:$K$1505,">0")>=$E17,"D",IF(COUNTIFS('COOIS Data'!$B$6:$B$1505,$C35,'COOIS Data'!$N$6:$N$1505,1,'COOIS Data'!$J$6:$J$1505,">0")>=$E17,"I","K"))) -> D | F35: =IF(COUNTIFS('COOIS Data'!$B$6:$B$1505,$C35,'COOIS Data'!$N$6:$N$1505,2,'COOIS Data'!$I$6:$I$1505,">0")<$E17,"–",IF(COUNTIFS('COOIS Data'!$B$6:$B$1505,$C35,'COOIS Data'!$N$6:$N$1505,2,'COOIS Data'!$K$6:$K$1505,">0")>=$E17,"D",IF(COUNTIFS('COOIS Data'!$B$6:$B$1505,$C35,'COOIS Data'!$N$6:$N$1505,2,'COOIS Data'!$J$6:$J$1505,">0")>=$E17,"I","K"))) -> D | G35: =IF(COUNTIFS('COOIS Data'!$B$6:$B$1505,$C35,'COOIS Data'!$N$6:$N$1505,3,'COOIS Data'!$I$6:$I$1505,">0")<$E17,"–",IF(COUNTIFS('COOIS Data'!$B$6:$B$1505,$C35,'COOIS Data'!$N$6:$N$1505,3,'COOIS Data'!$K$6:$K$1505,">0")>=$E17,"D",IF(COUNTIFS('COOIS Data'!$B$6:$B$1505,$C35,'COOIS Data'!$N$6:$N$1505,3,'COOIS Data'!$J$6:$J$1505,">0")>=$E17,"I","K"))) -> D | H35: =IF(COUNTIFS('COOIS Data'!$B$6:$B$1505,$C35,'COOIS Data'!$N$6:$N$1505,4,'COOIS Data'!$I$6:$I$1505,">0")<$E17,"–",IF(COUNTIFS('COOIS Data'!$B$6:$B$1505,$C35,'COOIS Data'!$N$6:$N$1505,4,'COOIS Data'!$K$6:$K$1505,">0")>=$E17,"D",IF(COUNTIFS('COOIS Data'!$B$6:$B$1505,$C35,'COOIS Data'!$N$6:$N$1505,4,'COOIS Data'!$J$6:$J$1505,">0")>=$E17,"I","K"))) -> D | I35: =IF(COUNTIFS('COOIS Data'!$B$6:$B$1505,$C35,'COOIS Data'!$N$6:$N$1505,5,'COOIS Data'!$I$6:$I$1505,">0")<$E17,"–",IF(COUNTIFS('COOIS Data'!$B$6:$B$1505,$C35,'COOIS Data'!$N$6:$N$1505,5,'COOIS Data'!$K$6:$K$1505,">0")>=$E17,"D",IF(COUNTIFS('COOIS Data'!$B$6:$B$1505,$C35,'COOIS Data'!$N$6:$N$1505,5,'COOIS Data'!$J$6:$J$1505,">0")>=$E17,"I","K"))) -> D | J35: =IF(COUNTIFS('COOIS Data'!$B$6:$B$1505,$C35,'COOIS Data'!$N$6:$N$1505,6,'COOIS Data'!$I$6:$I$1505,">0")<$E17,"–",IF(COUNTIFS('COOIS Data'!$B$6:$B$1505,$C35,'COOIS Data'!$N$6:$N$1505,6,'COOIS Data'!$K$6:$K$1505,">0")>=$E17,"D",IF(COUNTIFS('COOIS Data'!$B$6:$B$1505,$C35,'COOIS Data'!$N$6:$N$1505,6,'COOIS Data'!$J$6:$J$1505,">0")>=$E17,"I","K"))) -> D | K35: =IF(COUNTIFS('COOIS Data'!$B$6:$B$1505,$C35,'COOIS Data'!$N$6:$N$1505,7,'COOIS Data'!$I$6:$I$1505,">0")<$E17,"–",IF(COUNTIFS('COOIS Data'!$B$6:$B$1505,$C35,'COOIS Data'!$N$6:$N$1505,7,'COOIS Data'!$K$6:$K$1505,">0")>=$E17,"D",IF(COUNTIFS('COOIS Data'!$B$6:$B$1505,$C35,'COOIS Data'!$N$6:$N$1505,7,'COOIS Data'!$J$6:$J$1505,">0")>=$E17,"I","K"))) -> D | L35: =IF(COUNTIFS('COOIS Data'!$B$6:$B$1505,$C35,'COOIS Data'!$N$6:$N$1505,8,'COOIS Data'!$I$6:$I$1505,">0")<$E17,"–",IF(COUNTIFS('COOIS Data'!$B$6:$B$1505,$C35,'COOIS Data'!$N$6:$N$1505,8,'COOIS Data'!$K$6:$K$1505,">0")>=$E17,"D",IF(COUNTIFS('COOIS Data'!$B$6:$B$1505,$C35,'COOIS Data'!$N$6:$N$1505,8,'COOIS Data'!$J$6:$J$1505,">0")>=$E17,"I","K"))) -> D | M35: =IF(COUNTIFS('COOIS Data'!$B$6:$B$1505,$C35,'COOIS Data'!$N$6:$N$1505,9,'COOIS Data'!$I$6:$I$1505,">0")<$E17,"–",IF(COUNTIFS('COOIS Data'!$B$6:$B$1505,$C35,'COOIS Data'!$N$6:$N$1505,9,'COOIS Data'!$K$6:$K$1505,">0")>=$E17,"D",IF(COUNTIFS('COOIS Data'!$B$6:$B$1505,$C35,'COOIS Data'!$N$6:$N$1505,9,'COOIS Data'!$J$6:$J$1505,">0")>=$E17,"I","K"))) -> K | N35: =IF(COUNTIFS('COOIS Data'!$B$6:$B$1505,$C35,'COOIS Data'!$N$6:$N$1505,10,'COOIS Data'!$I$6:$I$1505,">0")<$E17,"–",IF(COUNTIFS('COOIS Data'!$B$6:$B$1505,$C35,'COOIS Data'!$N$6:$N$1505,10,'COOIS Data'!$K$6:$K$1505,">0")>=$E17,"D",IF(COUNTIFS('COOIS Data'!$B$6:$B$1505,$C35,'COOIS Data'!$N$6:$N$1505,10,'COOIS Data'!$J$6:$J$1505,">0")>=$E17,"I","K"))) -> K | O35: =IF(COUNTIFS('COOIS Data'!$B$6:$B$1505,$C35,'COOIS Data'!$N$6:$N$1505,11,'COOIS Data'!$I$6:$I$1505,">0")<$E17,"–",IF(COUNTIFS('COOIS Data'!$B$6:$B$1505,$C35,'COOIS Data'!$N$6:$N$1505,11,'COOIS Data'!$K$6:$K$1505,">0")>=$E17,"D",IF(COUNTIFS('COOIS Data'!$B$6:$B$1505,$C35,'COOIS Data'!$N$6:$N$1505,11,'COOIS Data'!$J$6:$J$1505,">0")>=$E17,"I","K"))) -> K | P35: =IF(COUNTIFS('COOIS Data'!$B$6:$B$1505,$C35,'COOIS Data'!$N$6:$N$1505,12,'COOIS Data'!$I$6:$I$1505,">0")<$E17,"–",IF(COUNTIFS('COOIS Data'!$B$6:$B$1505,$C35,'COOIS Data'!$N$6:$N$1505,12,'COOIS Data'!$K$6:$K$1505,">0")>=$E17,"D",IF(COUNTIFS('COOIS Data'!$B$6:$B$1505,$C35,'COOIS Data'!$N$6:$N$1505,12,'COOIS Data'!$J$6:$J$1505,">0")>=$E17,"I","K"))) -> K | Q35: =IF(COUNTIFS('COOIS Data'!$B$6:$B$1505,$C35,'COOIS Data'!$N$6:$N$1505,13,'COOIS Data'!$I$6:$I$1505,">0")<$E17,"–",IF(COUNTIFS('COOIS Data'!$B$6:$B$1505,$C35,'COOIS Data'!$N$6:$N$1505,13,'COOIS Data'!$K$6:$K$1505,">0")>=$E17,"D",IF(COUNTIFS('COOIS Data'!$B$6:$B$1505,$C35,'COOIS Data'!$N$6:$N$1505,13,'COOIS Data'!$J$6:$J$1505,">0")>=$E17,"I","K"))) -> K
B36: =B18 -> ERBIUM ASSY | C36: =C18 -> 92YRA01548AAA | D36: =D18 -> R5B ERBIUM ASSEMBLY POSITION 1 | E36: =IF(COUNTIFS('COOIS Data'!$B$6:$B$1505,$C36,'COOIS Data'!$N$6:$N$1505,1,'COOIS Data'!$I$6:$I$1505,">0")<$E18,"–",IF(COUNTIFS('COOIS Data'!$B$6:$B$1505,$C36,'COOIS Data'!$N$6:$N$1505,1,'COOIS Data'!$K$6:$K$1505,">0")>=$E18,"D",IF(COUNTIFS('COOIS Data'!$B$6:$B$1505,$C36,'COOIS Data'!$N$6:$N$1505,1,'COOIS Data'!$J$6:$J$1505,">0")>=$E18,"I","K"))) -> D | F36: =IF(COUNTIFS('COOIS Data'!$B$6:$B$1505,$C36,'COOIS Data'!$N$6:$N$1505,2,'COOIS Data'!$I$6:$I$1505,">0")<$E18,"–",IF(COUNTIFS('COOIS Data'!$B$6:$B$1505,$C36,'COOIS Data'!$N$6:$N$1505,2,'COOIS Data'!$K$6:$K$1505,">0")>=$E18,"D",IF(COUNTIFS('COOIS Data'!$B$6:$B$1505,$C36,'COOIS Data'!$N$6:$N$1505,2,'COOIS Data'!$J$6:$J$1505,">0")>=$E18,"I","K"))) -> D | G36: =IF(COUNTIFS('COOIS Data'!$B$6:$B$1505,$C36,'COOIS Data'!$N$6:$N$1505,3,'COOIS Data'!$I$6:$I$1505,">0")<$E18,"–",IF(COUNTIFS('COOIS Data'!$B$6:$B$1505,$C36,'COOIS Data'!$N$6:$N$1505,3,'COOIS Data'!$K$6:$K$1505,">0")>=$E18,"D",IF(COUNTIFS('COOIS Data'!$B$6:$B$1505,$C36,'COOIS Data'!$N$6:$N$1505,3,'COOIS Data'!$J$6:$J$1505,">0")>=$E18,"I","K"))) -> D | H36: =IF(COUNTIFS('COOIS Data'!$B$6:$B$1505,$C36,'COOIS Data'!$N$6:$N$1505,4,'COOIS Data'!$I$6:$I$1505,">0")<$E18,"–",IF(COUNTIFS('COOIS Data'!$B$6:$B$1505,$C36,'COOIS Data'!$N$6:$N$1505,4,'COOIS Data'!$K$6:$K$1505,">0")>=$E18,"D",IF(COUNTIFS('COOIS Data'!$B$6:$B$1505,$C36,'COOIS Data'!$N$6:$N$1505,4,'COOIS Data'!$J$6:$J$1505,">0")>=$E18,"I","K"))) -> D | I36: =IF(COUNTIFS('COOIS Data'!$B$6:$B$1505,$C36,'COOIS Data'!$N$6:$N$1505,5,'COOIS Data'!$I$6:$I$1505,">0")<$E18,"–",IF(COUNTIFS('COOIS Data'!$B$6:$B$1505,$C36,'COOIS Data'!$N$6:$N$1505,5,'COOIS Data'!$K$6:$K$1505,">0")>=$E18,"D",IF(COUNTIFS('COOIS Data'!$B$6:$B$1505,$C36,'COOIS Data'!$N$6:$N$1505,5,'COOIS Data'!$J$6:$J$1505,">0")>=$E18,"I","K"))) -> D | J36: =IF(COUNTIFS('COOIS Data'!$B$6:$B$1505,$C36,'COOIS Data'!$N$6:$N$1505,6,'COOIS Data'!$I$6:$I$1505,">0")<$E18,"–",IF(COUNTIFS('COOIS Data'!$B$6:$B$1505,$C36,'COOIS Data'!$N$6:$N$1505,6,'COOIS Data'!$K$6:$K$1505,">0")>=$E18,"D",IF(COUNTIFS('COOIS Data'!$B$6:$B$1505,$C36,'COOIS Data'!$N$6:$N$1505,6,'COOIS Data'!$J$6:$J$1505,">0")>=$E18,"I","K"))) -> D | K36: =IF(COUNTIFS('COOIS Data'!$B$6:$B$1505,$C36,'COOIS Data'!$N$6:$N$1505,7,'COOIS Data'!$I$6:$I$1505,">0")<$E18,"–",IF(COUNTIFS('COOIS Data'!$B$6:$B$1505,$C36,'COOIS Data'!$N$6:$N$1505,7,'COOIS Data'!$K$6:$K$1505,">0")>=$E18,"D",IF(COUNTIFS('COOIS Data'!$B$6:$B$1505,$C36,'COOIS Data'!$N$6:$N$1505,7,'COOIS Data'!$J$6:$J$1505,">0")>=$E18,"I","K"))) -> I | L36: =IF(COUNTIFS('COOIS Data'!$B$6:$B$1505,$C36,'COOIS Data'!$N$6:$N$1505,8,'COOIS Data'!$I$6:$I$1505,">0")<$E18,"–",IF(COUNTIFS('COOIS Data'!$B$6:$B$1505,$C36,'COOIS Data'!$N$6:$N$1505,8,'COOIS Data'!$K$6:$K$1505,">0")>=$E18,"D",IF(COUNTIFS('COOIS Data'!$B$6:$B$1505,$C36,'COOIS Data'!$N$6:$N$1505,8,'COOIS Data'!$J$6:$J$1505,">0")>=$E18,"I","K"))) -> I | M36: =IF(COUNTIFS('COOIS Data'!$B$6:$B$1505,$C36,'COOIS Data'!$N$6:$N$1505,9,'COOIS Data'!$I$6:$I$1505,">0")<$E18,"–",IF(COUNTIFS('COOIS Data'!$B$6:$B$1505,$C36,'COOIS Data'!$N$6:$N$1505,9,'COOIS Data'!$K$6:$K$1505,">0")>=$E18,"D",IF(COUNTIFS('COOIS Data'!$B$6:$B$1505,$C36,'COOIS Data'!$N$6:$N$1505,9,'COOIS Data'!$J$6:$J$1505,">0")>=$E18,"I","K"))) -> K | N36: =IF(COUNTIFS('COOIS Data'!$B$6:$B$1505,$C36,'COOIS Data'!$N$6:$N$1505,10,'COOIS Data'!$I$6:$I$1505,">0")<$E18,"–",IF(COUNTIFS('COOIS Data'!$B$6:$B$1505,$C36,'COOIS Data'!$N$6:$N$1505,10,'COOIS Data'!$K$6:$K$1505,">0")>=$E18,"D",IF(COUNTIFS('COOIS Data'!$B$6:$B$1505,$C36,'COOIS Data'!$N$6:$N$1505,10,'COOIS Data'!$J$6:$J$1505,">0")>=$E18,"I","K"))) -> K | O36: =IF(COUNTIFS('COOIS Data'!$B$6:$B$1505,$C36,'COOIS Data'!$N$6:$N$1505,11,'COOIS Data'!$I$6:$I$1505,">0")<$E18,"–",IF(COUNTIFS('COOIS Data'!$B$6:$B$1505,$C36,'COOIS Data'!$N$6:$N$1505,11,'COOIS Data'!$K$6:$K$1505,">0")>=$E18,"D",IF(COUNTIFS('COOIS Data'!$B$6:$B$1505,$C36,'COOIS Data'!$N$6:$N$1505,11,'COOIS Data'!$J$6:$J$1505,">0")>=$E18,"I","K"))) -> K | P36: =IF(COUNTIFS('COOIS Data'!$B$6:$B$1505,$C36,'COOIS Data'!$N$6:$N$1505,12,'COOIS Data'!$I$6:$I$1505,">0")<$E18,"–",IF(COUNTIFS('COOIS Data'!$B$6:$B$1505,$C36,'COOIS Data'!$N$6:$N$1505,12,'COOIS Data'!$K$6:$K$1505,">0")>=$E18,"D",IF(COUNTIFS('COOIS Data'!$B$6:$B$1505,$C36,'COOIS Data'!$N$6:$N$1505,12,'COOIS Data'!$J$6:$J$1505,">0")>=$E18,"I","K"))) -> K | Q36: =IF(COUNTIFS('COOIS Data'!$B$6:$B$1505,$C36,'COOIS Data'!$N$6:$N$1505,13,'COOIS Data'!$I$6:$I$1505,">0")<$E18,"–",IF(COUNTIFS('COOIS Data'!$B$6:$B$1505,$C36,'COOIS Data'!$N$6:$N$1505,13,'COOIS Data'!$K$6:$K$1505,">0")>=$E18,"D",IF(COUNTIFS('COOIS Data'!$B$6:$B$1505,$C36,'COOIS Data'!$N$6:$N$1505,13,'COOIS Data'!$J$6:$J$1505,">0")>=$E18,"I","K"))) -> K
B37: =B19 -> ERBIUM ASSY | C37: =C19 -> 92YRA02548AAA | D37: =D19 -> R5B ERBIUM ASSEMBLY POSITION 2 | E37: =IF(COUNTIFS('COOIS Data'!$B$6:$B$1505,$C37,'COOIS Data'!$N$6:$N$1505,1,'COOIS Data'!$I$6:$I$1505,">0")<$E19,"–",IF(COUNTIFS('COOIS Data'!$B$6:$B$1505,$C37,'COOIS Data'!$N$6:$N$1505,1,'COOIS Data'!$K$6:$K$1505,">0")>=$E19,"D",IF(COUNTIFS('COOIS Data'!$B$6:$B$1505,$C37,'COOIS Data'!$N$6:$N$1505,1,'COOIS Data'!$J$6:$J$1505,">0")>=$E19,"I","K"))) -> D | F37: =IF(COUNTIFS('COOIS Data'!$B$6:$B$1505,$C37,'COOIS Data'!$N$6:$N$1505,2,'COOIS Data'!$I$6:$I$1505,">0")<$E19,"–",IF(COUNTIFS('COOIS Data'!$B$6:$B$1505,$C37,'COOIS Data'!$N$6:$N$1505,2,'COOIS Data'!$K$6:$K$1505,">0")>=$E19,"D",IF(COUNTIFS('COOIS Data'!$B$6:$B$1505,$C37,'COOIS Data'!$N$6:$N$1505,2,'COOIS Data'!$J$6:$J$1505,">0")>=$E19,"I","K"))) -> D | G37: =IF(COUNTIFS('COOIS Data'!$B$6:$B$1505,$C37,'COOIS Data'!$N$6:$N$1505,3,'COOIS Data'!$I$6:$I$1505,">0")<$E19,"–",IF(COUNTIFS('COOIS Data'!$B$6:$B$1505,$C37,'COOIS Data'!$N$6:$N$1505,3,'COOIS Data'!$K$6:$K$1505,">0")>=$E19,"D",IF(COUNTIFS('COOIS Data'!$B$6:$B$1505,$C37,'COOIS Data'!$N$6:$N$1505,3,'COOIS Data'!$J$6:$J$1505,">0")>=$E19,"I","K"))) -> D | H37: =IF(COUNTIFS('COOIS Data'!$B$6:$B$1505,$C37,'COOIS Data'!$N$6:$N$1505,4,'COOIS Data'!$I$6:$I$1505,">0")<$E19,"–",IF(COUNTIFS('COOIS Data'!$B$6:$B$1505,$C37,'COOIS Data'!$N$6:$N$1505,4,'COOIS Data'!$K$6:$K$1505,">0")>=$E19,"D",IF(COUNTIFS('COOIS Data'!$B$6:$B$1505,$C37,'COOIS Data'!$N$6:$N$1505,4,'COOIS Data'!$J$6:$J$1505,">0")>=$E19,"I","K"))) -> D | I37: =IF(COUNTIFS('COOIS Data'!$B$6:$B$1505,$C37,'COOIS Data'!$N$6:$N$1505,5,'COOIS Data'!$I$6:$I$1505,">0")<$E19,"–",IF(COUNTIFS('COOIS Data'!$B$6:$B$1505,$C37,'COOIS Data'!$N$6:$N$1505,5,'COOIS Data'!$K$6:$K$1505,">0")>=$E19,"D",IF(COUNTIFS('COOIS Data'!$B$6:$B$1505,$C37,'COOIS Data'!$N$6:$N$1505,5,'COOIS Data'!$J$6:$J$1505,">0")>=$E19,"I","K"))) -> D | J37: =IF(COUNTIFS('COOIS Data'!$B$6:$B$1505,$C37,'COOIS Data'!$N$6:$N$1505,6,'COOIS Data'!$I$6:$I$1505,">0")<$E19,"–",IF(COUNTIFS('COOIS Data'!$B$6:$B$1505,$C37,'COOIS Data'!$N$6:$N$1505,6,'COOIS Data'!$K$6:$K$1505,">0")>=$E19,"D",IF(COUNTIFS('COOIS Data'!$B$6:$B$1505,$C37,'COOIS Data'!$N$6:$N$1505,6,'COOIS Data'!$J$6:$J$1505,">0")>=$E19,"I","K"))) -> D | K37: =IF(COUNTIFS('COOIS Data'!$B$6:$B$1505,$C37,'COOIS Data'!$N$6:$N$1505,7,'COOIS Data'!$I$6:$I$1505,">0")<$E19,"–",IF(COUNTIFS('COOIS Data'!$B$6:$B$1505,$C37,'COOIS Data'!$N$6:$N$1505,7,'COOIS Data'!$K$6:$K$1505,">0")>=$E19,"D",IF(COUNTIFS('COOIS Data'!$B$6:$B$1505,$C37,'COOIS Data'!$N$6:$N$1505,7,'COOIS Data'!$J$6:$J$1505,">0")>=$E19,"I","K"))) -> I | L37: =IF(COUNTIFS('COOIS Data'!$B$6:$B$1505,$C37,'COOIS Data'!$N$6:$N$1505,8,'COOIS Data'!$I$6:$I$1505,">0")<$E19,"–",IF(COUNTIFS('COOIS Data'!$B$6:$B$1505,$C37,'COOIS Data'!$N$6:$N$1505,8,'COOIS Data'!$K$6:$K$1505,">0")>=$E19,"D",IF(COUNTIFS('COOIS Data'!$B$6:$B$1505,$C37,'COOIS Data'!$N$6:$N$1505,8,'COOIS Data'!$J$6:$J$1505,">0")>=$E19,"I","K"))) -> I | M37: =IF(COUNTIFS('COOIS Data'!$B$6:$B$1505,$C37,'COOIS Data'!$N$6:$N$1505,9,'COOIS Data'!$I$6:$I$1505,">0")<$E19,"–",IF(COUNTIFS('COOIS Data'!$B$6:$B$1505,$C37,'COOIS Data'!$N$6:$N$1505,9,'COOIS Data'!$K$6:$K$1505,">0")>=$E19,"D",IF(COUNTIFS('COOIS Data'!$B$6:$B$1505,$C37,'COOIS Data'!$N$6:$N$1505,9,'COOIS Data'!$J$6:$J$1505,">0")>=$E19,"I","K"))) -> K | N37: =IF(COUNTIFS('COOIS Data'!$B$6:$B$1505,$C37,'COOIS Data'!$N$6:$N$1505,10,'COOIS Data'!$I$6:$I$1505,">0")<$E19,"–",IF(COUNTIFS('COOIS Data'!$B$6:$B$1505,$C37,'COOIS Data'!$N$6:$N$1505,10,'COOIS Data'!$K$6:$K$1505,">0")>=$E19,"D",IF(COUNTIFS('COOIS Data'!$B$6:$B$1505,$C37,'COOIS Data'!$N$6:$N$1505,10,'COOIS Data'!$J$6:$J$1505,">0")>=$E19,"I","K"))) -> K | O37: =IF(COUNTIFS('COOIS Data'!$B$6:$B$1505,$C37,'COOIS Data'!$N$6:$N$1505,11,'COOIS Data'!$I$6:$I$1505,">0")<$E19,"–",IF(COUNTIFS('COOIS Data'!$B$6:$B$1505,$C37,'COOIS Data'!$N$6:$N$1505,11,'COOIS Data'!$K$6:$K$1505,">0")>=$E19,"D",IF(COUNTIFS('COOIS Data'!$B$6:$B$1505,$C37,'COOIS Data'!$N$6:$N$1505,11,'COOIS Data'!$J$6:$J$1505,">0")>=$E19,"I","K"))) -> K | P37: =IF(COUNTIFS('COOIS Data'!$B$6:$B$1505,$C37,'COOIS Data'!$N$6:$N$1505,12,'COOIS Data'!$I$6:$I$1505,">0")<$E19,"–",IF(COUNTIFS('COOIS Data'!$B$6:$B$1505,$C37,'COOIS Data'!$N$6:$N$1505,12,'COOIS Data'!$K$6:$K$1505,">0")>=$E19,"D",IF(COUNTIFS('COOIS Data'!$B$6:$B$1505,$C37,'COOIS Data'!$N$6:$N$1505,12,'COOIS Data'!$J$6:$J$1505,">0")>=$E19,"I","K"))) -> K | Q37: =IF(COUNTIFS('COOIS Data'!$B$6:$B$1505,$C37,'COOIS Data'!$N$6:$N$1505,13,'COOIS Data'!$I$6:$I$1505,">0")<$E19,"–",IF(COUNTIFS('COOIS Data'!$B$6:$B$1505,$C37,'COOIS Data'!$N$6:$N$1505,13,'COOIS Data'!$K$6:$K$1505,">0")>=$E19,"D",IF(COUNTIFS('COOIS Data'!$B$6:$B$1505,$C37,'COOIS Data'!$N$6:$N$1505,13,'COOIS Data'!$J$6:$J$1505,">0")>=$E19,"I","K"))) -> K
B38: =B20 -> ERBIUM ASSY | C38: =C20 -> 92YRA03548AAA | D38: =D20 -> R5B ERBIUM ASSEMBLY POSITION 3 | E38: =IF(COUNTIFS('COOIS Data'!$B$6:$B$1505,$C38,'COOIS Data'!$N$6:$N$1505,1,'COOIS Data'!$I$6:$I$1505,">0")<$E20,"–",IF(COUNTIFS('COOIS Data'!$B$6:$B$1505,$C38,'COOIS Data'!$N$6:$N$1505,1,'COOIS Data'!$K$6:$K$1505,">0")>=$E20,"D",IF(COUNTIFS('COOIS Data'!$B$6:$B$1505,$C38,'COOIS Data'!$N$6:$N$1505,1,'COOIS Data'!$J$6:$J$1505,">0")>=$E20,"I","K"))) -> D | F38: =IF(COUNTIFS('COOIS Data'!$B$6:$B$1505,$C38,'COOIS Data'!$N$6:$N$1505,2,'COOIS Data'!$I$6:$I$1505,">0")<$E20,"–",IF(COUNTIFS('COOIS Data'!$B$6:$B$1505,$C38,'COOIS Data'!$N$6:$N$1505,2,'COOIS Data'!$K$6:$K$1505,">0")>=$E20,"D",IF(COUNTIFS('COOIS Data'!$B$6:$B$1505,$C38,'COOIS Data'!$N$6:$N$1505,2,'COOIS Data'!$J$6:$J$1505,">0")>=$E20,"I","K"))) -> D | G38: =IF(COUNTIFS('COOIS Data'!$B$6:$B$1505,$C38,'COOIS Data'!$N$6:$N$1505,3,'COOIS Data'!$I$6:$I$1505,">0")<$E20,"–",IF(COUNTIFS('COOIS Data'!$B$6:$B$1505,$C38,'COOIS Data'!$N$6:$N$1505,3,'COOIS Data'!$K$6:$K$1505,">0")>=$E20,"D",IF(COUNTIFS('COOIS Data'!$B$6:$B$1505,$C38,'COOIS Data'!$N$6:$N$1505,3,'COOIS Data'!$J$6:$J$1505,">0")>=$E20,"I","K"))) -> K | H38: =IF(COUNTIFS('COOIS Data'!$B$6:$B$1505,$C38,'COOIS Data'!$N$6:$N$1505,4,'COOIS Data'!$I$6:$I$1505,">0")<$E20,"–",IF(COUNTIFS('COOIS Data'!$B$6:$B$1505,$C38,'COOIS Data'!$N$6:$N$1505,4,'COOIS Data'!$K$6:$K$1505,">0")>=$E20,"D",IF(COUNTIFS('COOIS Data'!$B$6:$B$1505,$C38,'COOIS Data'!$N$6:$N$1505,4,'COOIS Data'!$J$6:$J$1505,">0")>=$E20,"I","K"))) -> D | I38: =IF(COUNTIFS('COOIS Data'!$B$6:$B$1505,$C38,'COOIS Data'!$N$6:$N$1505,5,'COOIS Data'!$I$6:$I$1505,">0")<$E20,"–",IF(COUNTIFS('COOIS Data'!$B$6:$B$1505,$C38,'COOIS Data'!$N$6:$N$1505,5,'COOIS Data'!$K$6:$K$1505,">0")>=$E20,"D",IF(COUNTIFS('COOIS Data'!$B$6:$B$1505,$C38,'COOIS Data'!$N$6:$N$1505,5,'COOIS Data'!$J$6:$J$1505,">0")>=$E20,"I","K"))) -> D | J38: =IF(COUNTIFS('COOIS Data'!$B$6:$B$1505,$C38,'COOIS Data'!$N$6:$N$1505,6,'COOIS Data'!$I$6:$I$1505,">0")<$E20,"–",IF(COUNTIFS('COOIS Data'!$B$6:$B$1505,$C38,'COOIS Data'!$N$6:$N$1505,6,'COOIS Data'!$K$6:$K$1505,">0")>=$E20,"D",IF(COUNTIFS('COOIS Data'!$B$6:$B$1505,$C38,'COOIS Data'!$N$6:$N$1505,6,'COOIS Data'!$J$6:$J$1505,">0")>=$E20,"I","K"))) -> D | K38: =IF(COUNTIFS('COOIS Data'!$B$6:$B$1505,$C38,'COOIS Data'!$N$6:$N$1505,7,'COOIS Data'!$I$6:$I$1505,">0")<$E20,"–",IF(COUNTIFS('COOIS Data'!$B$6:$B$1505,$C38,'COOIS Data'!$N$6:$N$1505,7,'COOIS Data'!$K$6:$K$1505,">0")>=$E20,"D",IF(COUNTIFS('COOIS Data'!$B$6:$B$1505,$C38,'COOIS Data'!$N$6:$N$1505,7,'COOIS Data'!$J$6:$J$1505,">0")>=$E20,"I","K"))) -> D | L38: =IF(COUNTIFS('COOIS Data'!$B$6:$B$1505,$C38,'COOIS Data'!$N$6:$N$1505,8,'COOIS Data'!$I$6:$I$1505,">0")<$E20,"–",IF(COUNTIFS('COOIS Data'!$B$6:$B$1505,$C38,'COOIS Data'!$N$6:$N$1505,8,'COOIS Data'!$K$6:$K$1505,">0")>=$E20,"D",IF(COUNTIFS('COOIS Data'!$B$6:$B$1505,$C38,'COOIS Data'!$N$6:$N$1505,8,'COOIS Data'!$J$6:$J$1505,">0")>=$E20,"I","K"))) -> I | M38: =IF(COUNTIFS('COOIS Data'!$B$6:$B$1505,$C38,'COOIS Data'!$N$6:$N$1505,9,'COOIS Data'!$I$6:$I$1505,">0")<$E20,"–",IF(COUNTIFS('COOIS Data'!$B$6:$B$1505,$C38,'COOIS Data'!$N$6:$N$1505,9,'COOIS Data'!$K$6:$K$1505,">0")>=$E20,"D",IF(COUNTIFS('COOIS Data'!$B$6:$B$1505,$C38,'COOIS Data'!$N$6:$N$1505,9,'COOIS Data'!$J$6:$J$1505,">0")>=$E20,"I","K"))) -> I | N38: =IF(COUNTIFS('COOIS Data'!$B$6:$B$1505,$C38,'COOIS Data'!$N$6:$N$1505,10,'COOIS Data'!$I$6:$I$1505,">0")<$E20,"–",IF(COUNTIFS('COOIS Data'!$B$6:$B$1505,$C38,'COOIS Data'!$N$6:$N$1505,10,'COOIS Data'!$K$6:$K$1505,">0")>=$E20,"D",IF(COUNTIFS('COOIS Data'!$B$6:$B$1505,$C38,'COOIS Data'!$N$6:$N$1505,10,'COOIS Data'!$J$6:$J$1505,">0")>=$E20,"I","K"))) -> K | O38: =IF(COUNTIFS('COOIS Data'!$B$6:$B$1505,$C38,'COOIS Data'!$N$6:$N$1505,11,'COOIS Data'!$I$6:$I$1505,">0")<$E20,"–",IF(COUNTIFS('COOIS Data'!$B$6:$B$1505,$C38,'COOIS Data'!$N$6:$N$1505,11,'COOIS Data'!$K$6:$K$1505,">0")>=$E20,"D",IF(COUNTIFS('COOIS Data'!$B$6:$B$1505,$C38,'COOIS Data'!$N$6:$N$1505,11,'COOIS Data'!$J$6:$J$1505,">0")>=$E20,"I","K"))) -> K | P38: =IF(COUNTIFS('COOIS Data'!$B$6:$B$1505,$C38,'COOIS Data'!$N$6:$N$1505,12,'COOIS Data'!$I$6:$I$1505,">0")<$E20,"–",IF(COUNTIFS('COOIS Data'!$B$6:$B$1505,$C38,'COOIS Data'!$N$6:$N$1505,12,'COOIS Data'!$K$6:$K$1505,">0")>=$E20,"D",IF(COUNTIFS('COOIS Data'!$B$6:$B$1505,$C38,'COOIS Data'!$N$6:$N$1505,12,'COOIS Data'!$J$6:$J$1505,">0")>=$E20,"I","K"))) -> K | Q38: =IF(COUNTIFS('COOIS Data'!$B$6:$B$1505,$C38,'COOIS Data'!$N$6:$N$1505,13,'COOIS Data'!$I$6:$I$1505,">0")<$E20,"–",IF(COUNTIFS('COOIS Data'!$B$6:$B$1505,$C38,'COOIS Data'!$N$6:$N$1505,13,'COOIS Data'!$K$6:$K$1505,">0")>=$E20,"D",IF(COUNTIFS('COOIS Data'!$B$6:$B$1505,$C38,'COOIS Data'!$N$6:$N$1505,13,'COOIS Data'!$J$6:$J$1505,">0")>=$E20,"I","K"))) -> K
