Workbook
Name RptDate: IF(Settings!$C$6="",TODAY(),Settings!$C$6)
Name ThisMon: RptDate-WEEKDAY(RptDate,2)+1
Name KitLead: Settings!$C$7
Name Rv_Key: 'COOIS Review'!$A$6:$A$20005
Name Rv_Mat: 'COOIS Review'!$B$6:$B$20005
Name Rv_Qty: 'COOIS Review'!$D$6:$D$20005
Name Rv_Rel: 'COOIS Review'!$E$6:$E$20005
Name Rv_CLSD: 'COOIS Review'!$K$6:$K$20005
Name Rv_Entry: 'COOIS Review'!$N$6:$N$20005
Name Rv_Review: 'COOIS Review'!$P$6:$P$20005
Name WkHdr: Calc!$Q$1:$ALL$1
Name WkASPMon: Calc!$Q$2:$ALL$2
Name WkKitMon: Calc!$Q$3:$ALL$3
Name WkKitLbl: Calc!$Q$4:$ALL$4
Name AspWeeks: ASP!$Q$2:$ALL$1000
Name P_ProjId: Calc!$B$8:$B$1006
Name P_ProjName: Calc!$C$8:$C$1006
Name P_Product: Calc!$D$8:$D$1006
Name P_ProdId: Calc!$F$8:$F$1006
Name P_Var: Calc!$G$8:$G$1006
Name P_System: Calc!$K$8:$K$1006
Name P_Planned: Calc!$L$8:$L$1006
Name P_WSum: Calc!$P$8:$P$1006
Name P_DueEnd: Calc!$Q$8:$Q$1006
Name P_DueBefore: Calc!$R$8:$R$1006
Name P_Next4: Calc!$S$8:$S$1006
Name P_RowOK: Calc!$T$8:$T$1006
Name P_Valid: Calc!$U$8:$U$1006
Name P_Lines: Calc!$V$8:$V$1006
Name P_Built: Calc!$W$8:$W$1006
Name P_Complete: Calc!$X$8:$X$1006
Name P_Partial: Calc!$Y$8:$Y$1006
Name P_Remaining: Calc!$Z$8:$Z$1006
Name P_Pct: Calc!$AA$8:$AA$1006
Name P_DueThis: Calc!$AB$8:$AB$1006
Name P_Behind: Calc!$AC$8:$AC$1006
Name P_Short: Calc!$AD$8:$AD$1006
Name P_TopDiff: Calc!$AE$8:$AE$1006
Name P_Status: Calc!$AF$8:$AF$1006
Name L_Var: Calc!$AH$8:$AH$2007
Name L_Stage: Calc!$AI$8:$AI$2007
Name L_Code: Calc!$AK$8:$AK$2007
Name L_Rec: Calc!$AN$8:$AN$2007
Name L_Alloc: Calc!$AO$8:$AO$2007
Name L_Cov: Calc!$AP$8:$AP$2007
Name L_Short: Calc!$AQ$8:$AQ$2007
Name L_CovReps: Calc!$AS$8:$AS$2007
Name L_StartReps: Calc!$AT$8:$AT$2007
Name L_Avail: Calc!$AW$8:$AW$2007
Name ProductList: Calc!$BA$8:$BA$200
Name ProjectList: Calc!$BB$8:$BB$400
Name VariantAllList: Calc!$BC$8:$BC$600
Name VariantList: Calc!$BD$8:$BD$400
Name StageList: Calc!$BE$8:$BE$100
Name CodeList: Calc!$BF$8:$BF$200

Sheet Read Me
B2: ASN Kitting Progress Tracker - Read Me
B3: For Production Controllers. No macros. Yellow cells and the two Settings tables are inputs; ASP and COOIS are paste areas; everything else calculates.
B5: 1. Load a new ASP
B6: - | C6: Open the ASP export, select all (Ctrl+A), copy, then click cell A1 on the ASP sheet and paste. Do not insert, delete or move columns.
B7: - | C7: Type the file name and today's date in Settings (ASP file loaded / ASP loaded on). The export's own version and export time show at the top of the Dashboard.
B8: - | C8: New contracts and variants appear in the Dashboard filters automatically. Recorded progress is kept by Variant ID (ASP Friendly_name), so it is never erased by a new ASP.
B9: - | C9: If a variant you have set up or recorded is no longer in the ASP, the Dashboard Data checks list it for review. Its history stays in the Kitting Log.
B11: 2. Load COOIS (keep the column order)
B12: - | C12: Run COOIS for the assembly codes you need, export to Excel, copy everything and paste at cell A1 of the COOIS sheet. Columns Order to System Status must stay in SAP's order; extra columns to the right are fine.
B13: - | C13: Order numbers and material codes are treated as text identifiers. An order already in an earlier export keeps its allocation; nothing is counted twice.
B14: - | C14: An allocated order that is missing from a new export is flagged 'Not in current COOIS - review'. That does not prove it was cancelled - the new export may cover a different selection.
B15: - | C15: The COOIS Review sheet shows each order's SAP status tokens (PCNF, CNF, DLV, CLSD, TECO are matched as whole words, so PCNF is never read as CNF) beside the tracker's allocation.
B17: 3. Record what was kitted (daily routine)
B18: - | C18: Record Kitting sheet. Step 1: choose the Variant ID you actually worked on (even if management changed the order), the Stage, and how many repeaters' worth you kitted. Leave Assembly code blank for a whole stage, or choose one code for a partial (line-only) entry.
B19: - | C19: REP from / REP to are optional. Fill them only when you know which repeater numbers the kit is for. Without them the quantity is held at contract level.
B20: - | C20: Step 2 shows, for each assembly line: units for this entry, what is already recorded and allocated, units still needing COOIS orders, orders available and any shortage.
B21: - | C21: Step 3 is the green block. Select it from N19 to the last green row, copy, go to the Kitting Log, click column A on the first empty row of the table and use Paste Special > Values. That is the confirmation. Then clear the Step 1 inputs.
B22: - | C22: Excel without macros cannot press a Confirm button for you or stop you pasting twice. The Check column catches a second paste (Duplicate allocation - fix): void the second entry.
B24: 4. Shortages and shared assemblies
B25: - | C25: If fewer suitable COOIS orders exist than the quantity needed, the shortfall shows in Step 2 and in 'Units without COOIS order'. The stage is not counted as complete until it is covered.
B26: - | C26: When a later COOIS export contains the missing orders, enter the same variant and stage with REPs kitted = 0. Only the outstanding orders are proposed.
B27: - | C27: Codes used by more than one variant (for example the PSB 91YAF03404AAA) are never assigned to a contract automatically. Unallocated orders show 'Shared code - no contract allocation'.
B29: 5. Add or change a contract's assembly requirements
B30: - | C30: Settings > requirements table: one row per assembly line with Project, Variant ID (exactly as the ASP Friendly_name), Top code, Fibre pairs, Stage, Assembly code, description and Qty per REP (for ONE repeater).
B31: - | C31: Type the new rows in the first empty row below the table; it grows by itself. The same code can appear in several variants with different quantities.
B32: - | C32: Fill 'Verified by / date' once a line is checked against the official kitting sheet. A variant without rows shows 'Assembly setup required'.
B33: - | C33: New stages (Internal Unit, Housing...) are added in the Kitting stages table with an order number, then their lines in the requirements table.
B35: 6. Correct an entry
B36: - | C36: Never delete or overwrite log rows. In the Kitting Log type Y in Void on any row of the wrong entry and write a Void reason. The whole entry (progress and its orders) stops counting, stays visible and is struck through.
B37: - | C37: Then record the correct entry through Record Kitting as normal. The released orders become available again.
B38: - | C38: To assign contract-level kitting to known repeater numbers later: void the original entry and re-enter it with REP from / REP to.
B40: 7. Save, back up and hand over
B41: - | C41: Save as .xlsx (no macros). Keep a dated copy each week, e.g. 'ASN Kitting Tracker 2026-W44.xlsx', in the shared drive.
B42: - | C42: The Kitting Log and Settings are the only records that cannot be re-created from SAP. Everything else is recalculated from the pasted ASP and COOIS.
B43: - | C43: Handover: give the new controller this file and this Read Me. Nothing is hidden: the Calc sheet shows every intermediate number.
B44: - | C44: If the file opens in Protected View, click Enable Editing - formulas do not calculate until then.
B46: 8. What the terms mean
B47: - | C47: Kitting Progress: what the controller records as physically kitted (repeaters' worth of a stage or line).
B48: - | C48: Status: the result shown in the report - All kitted, On track, Kit due this week, Kit behind, Assembly setup required, review flags.
B49: - | C49: Complete assembly kits: repeaters' worth where every set-up assembly line is recorded AND covered by allocated COOIS orders. It is not a finished repeater.
...

Sheet Dashboard
B2: Kitting Progress Dashboard | AD2: {=SUMPRODUCT((UPPER(P_Product)=UPPER($C$5))*(P_RowOK=1)*((($F$5="All")+($F$5=""))+(UPPER(P_ProjName)=UPPER($F$5))>0)*((($I$5="All")+($I$5=""))+(UPPER(P_Var)=UPPER($I$5))>0),IFERROR(--P_Planned,0))}
B3: ="Week "&RIGHT(YEAR(ThisMon+3),2)&" W"&_xlfn.ISOWEEKNUM(ThisMon)&" | report date "&TEXT(RptDate,"dd mmm yyyy")&" | kit target = ASP week - "&KitLead&" weeks | ASP: "&ASP!$B$2&" (export "&IFERROR(TEXT(ASP!$A$2,"dd mmm yyyy"),"?")&") | COOIS: "&Settings!$C$10&IF(Settings!$C$11="",""," loaded "&TEXT(Settings!$C$11,"dd mmm yyyy")) | AD3: {=SUMPRODUCT((UPPER(P_Product)=UPPER($C$5))*(P_RowOK=1)*((($F$5="All")+($F$5=""))+(UPPER(P_ProjName)=UPPER($F$5))>0)*((($I$5="All")+($I$5=""))+(UPPER(P_Var)=UPPER($I$5))>0)*(P_Lines>0),IFERROR(--P_Planned,0))}
AD4: {=SUMPRODUCT((UPPER(P_Product)=UPPER($C$5))*(P_RowOK=1)*((($F$5="All")+($F$5=""))+(UPPER(P_ProjName)=UPPER($F$5))>0)*((($I$5="All")+($I$5=""))+(UPPER(P_Var)=UPPER($I$5))>0)*(P_Lines>0),IFERROR(--P_Complete,0))}
B5: Product | C5: REPEATERS | E5: Project | F5: All | H5: Variant | I5: All | T5: Definitions | AD5: {=SUMPRODUCT((UPPER(P_Product)=UPPER($C$5))*(P_RowOK=1)*((($F$5="All")+($F$5=""))+(UPPER(P_ProjName)=UPPER($F$5))>0)*((($I$5="All")+($I$5=""))+(UPPER(P_Var)=UPPER($I$5))>0)*(P_Lines>0),IFERROR(--P_Partial,0))}
T6: Planned: ASP Planned Qty for the selected product/project/variant. Repeaters and amplifiers are separate products in the ASP and are never added together. | AD6: {=SUMPRODUCT((UPPER(P_Product)=UPPER($C$5))*(P_RowOK=1)*((($F$5="All")+($F$5=""))+(UPPER(P_ProjName)=UPPER($F$5))>0)*((($I$5="All")+($I$5=""))+(UPPER(P_Var)=UPPER($I$5))>0)*(P_Lines>0),IFERROR(--P_DueThis,0))}
B7: PLANNED | D7: COMPLETE ASSEMBLY KITS | F7: PARTLY KITTED | H7: REMAINING TO KIT | J7: KITTING PROGRESS | L7: KITS DUE THIS WEEK | N7: KITS BEHIND | P7: COOIS: UNALLOCATED / REVIEW | T7: Complete assembly kits: repeaters' worth for which every set-up assembly line is recorded as kitted AND covered by allocated COOIS orders (the lowest line decides). | AD7: {=SUMPRODUCT((UPPER(P_Product)=UPPER($C$5))*(P_RowOK=1)*((($F$5="All")+($F$5=""))+(UPPER(P_ProjName)=UPPER($F$5))>0)*((($I$5="All")+($I$5=""))+(UPPER(P_Var)=UPPER($I$5))>0)*(P_Lines>0),IFERROR(--P_Behind,0))}
B8: =IF(AD8=0,AD2,AD3) | D8: =AD4 | F8: =AD5 | H8: =IF(AD8=0,"n/a",MAX(0,AD3-AD4)) | J8: =IF(OR(AD8=0,AD3=0),"not available",AD4/AD3) | L8: =AD6 | N8: =AD7 | P8: =AD11&" / "&AD12 | T8: Partly kitted: repeaters with at least one line started but not all lines complete. Remaining: planned minus complete kits. | AD8: {=SUMPRODUCT((UPPER(P_Product)=UPPER($C$5))*(P_RowOK=1)*((($F$5="All")+($F$5=""))+(UPPER(P_ProjName)=UPPER($F$5))>0)*((($I$5="All")+($I$5=""))+(UPPER(P_Var)=UPPER($I$5))>0)*(P_Lines>0))}
B9: =IF(AD8=0,"ASP planned qty in scope (no variant set up)","ASP planned qty, set-up variants"&IF(AD2>AD3," ("&AD2&" incl. not set up)","")) | D9: ="REPs with every set-up line covered" | F9: ="REPs started, not complete" | H9: ="planned minus complete kits" | J9: ="complete kits / planned (set-up variants)" | L9: ="kit target this week, not yet complete" | N9: ="kit target before this week, not complete" | P9: ="orders, all contracts - see COOIS Review" | T9: Kit target week = ASP planned week minus the kit lead (Settings, 3 weeks). Due this week / behind compare complete kits with the cumulative plan, contract by contract. | AD9: {=SUMPRODUCT((UPPER(P_Product)=UPPER($C$5))*(P_RowOK=1)*((($F$5="All")+($F$5=""))+(UPPER(P_ProjName)=UPPER($F$5))>0)*((($I$5="All")+($I$5=""))+(UPPER(P_Var)=UPPER($I$5))>0)*(P_Lines=0)*(IFERROR(--P_Planned,0)>0))}
T10: A complete assembly kit is not a finished repeater. COOIS CNF is not treated as kitted. Contract allocation is the controller's entry, not a link proven by SAP. | AD10: {=SUMPRODUCT((UPPER(P_Product)=UPPER($C$5))*(P_RowOK=1)*((($F$5="All")+($F$5=""))+(UPPER(P_ProjName)=UPPER($F$5))>0)*((($I$5="All")+($I$5=""))+(UPPER(P_Var)=UPPER($I$5))>0)*(P_Lines>0),IFERROR(--P_Short,0))}
B11: Kits due by kit week (scope above, set-up variants) - this week highlighted | AD11: {='COOIS Review'!$H$2}
B12: Kit week | C12: {=_xlfn.LET(_xlpm.smk,(UPPER(P_Product)=UPPER($C$5))*(P_RowOK=1)*((($F$5="All")+($F$5=""))+(UPPER(P_ProjName)=UPPER($F$5))>0)*((($I$5="All")+($I$5=""))+(UPPER(P_Var)=UPPER($I$5))>0)*(P_Lines>0),_xlpm.sw,MMULT(TRANSPOSE(_xlpm.smk),IFERROR(--AspWeeks,0)),_xlpm.swk,TRANSPOSE(WkKitMon),_xlpm.sM,ThisMon+7*_xlfn.SEQUENCE(1,13,-4),_xlpm.sdue,MMULT(_xlpm.sw,--(_xlpm.swk=_xlpm.sM)),_xlpm.scum,MMULT(_xlpm.sw,--(_xlpm.swk<=_xlpm.sM)),_xlfn.VSTACK(RIGHT(YEAR(_xlpm.sM+3),2)&" W"&_xlfn.ISOWEEKNUM(_xlpm.sM),_xlpm.sdue,_xlpm.scum,_xlpm.sM*0+$AD$4,IF(_xlpm.scum-$AD$4>0,_xlpm.scum-$AD$4,0)))} | AD12: {='COOIS Review'!$H$3+COUNTIFS(tblLog[Check],"*review*")+COUNTIFS(tblLog[Check],"*fix*")+COUNTIFS(tblLog[Check],"Assembly*")+COUNTIFS(tblLog[Check],"Stage*")+COUNTIFS(tblLog[Check],"REP*")+COUNTIFS(tblLog[Check],"Order number missing")+COUNTIFS(tblLog[Check],"Record type*")}
B13: REPs due to kit that week
B14: Cumulative due
B15: Complete kits to date
B16: Short of cumulative due
B18: Data checks
B19: {=IF(AND(ASP!$C$1="Project Id",ASP!$D$1="Project Name",ASP!$E$1="Product",ASP!$G$1="Prod Id",ASP!$H$1="Friendly_name",ASP!$K$1="Nber FP",ASP!$L$1="System Qty",ASP!$M$1="Planned Qty"),"OK ASP columns as expected ("&COUNTIFS(P_RowOK,1)&" ASP lines, "&COUNTIFS(WkHdr,"?? W*")&" week columns)","CHECK ASP headers are not in the expected columns - paste the export at ASP!A1")}
B20: {=IF(SUMPRODUCT(--(COOIS!$A$1:$O$1=({"Order","Order Type","Material Number","Material description","Plant","Batch","Order quantity (GMEIN)","Unit of measure (=GMEIN)","Release date (actual)","Delivered quantity (GMEIN)","Created on","Entered by","Change date","Last changed by","System Status"})))=15,"OK COOIS columns Order..System Status in the expected order ("&COUNTA(Rv_Key)&" orders)","CHECK COOIS headings differ from the expected layout - paste the export at COOIS!A1")}
B21: {=_xlfn.LET(_xlpm.nl,IFERROR(Calc!$BD$8:$BD$400&"",""),_xlpm.nm,(_xlpm.nl<>"")*(_xlpm.nl<>"(none)")*(COUNTIFS(P_Var,_xlpm.nl,P_Valid,1)=0),IF(SUM(_xlpm.nm)=0,"OK every set-up variant is in the current ASP","REVIEW set up but not in current ASP (history kept): "&_xlfn.TEXTJOIN(", ",TRUE,IF(_xlpm.nm=1,_xlpm.nl,""))))}
B22: {=IF(SUMPRODUCT((P_Lines>0)*(COUNTIFS(P_Var,P_Var,P_Valid,1)>1))=0,"OK no set-up variant appears on more than one ASP line","REVIEW a set-up variant appears on more than one ASP line - quantities are added together")}
B23: {=IF(AD12=0,"OK no Kitting Log or COOIS rows need review",AD12&" rows need review - see Check column in Kitting Log and Review column in COOIS Review")}
B24: {=IF(AD10=0,"OK every recorded unit in scope is covered by a COOIS order",AD10&" recorded units in scope have no allocated COOIS order yet (not counted as complete)")}
B25: {=IF(AD9=0,"OK every planned line in scope has assembly requirements",AD9&" planned ASP lines in scope have no requirements - Assembly setup required")}
B27: Contract overview
B28: Project | C28: Variant ID | D28: Top code | E28: FP | F28: Body | G28: Temp | H28: System qty | I28: Built before plan | J28: Planned | K28: Kits due by this week | L28: Complete kits | M28: Partly kitted | N28: Remaining | O28: Progress | P28: Due this week | Q28: Behind | R28: Units without COOIS order | S28: Status
B29: {=_xlfn.LET(_xlpm.om,(UPPER(P_Product)=UPPER($C$5))*(P_RowOK=1)*((($F$5="All")+($F$5=""))+(UPPER(P_ProjName)=UPPER($F$5))>0)*((($I$5="All")+($I$5=""))+(UPPER(P_Var)=UPPER($I$5))>0),_xlpm.orows,_xlfn._xlws.FILTER(Calc!$A$8:$AF$1006,_xlpm.om,""),IF(SUM(_xlpm.om)=0,"No ASP lines for this selection",_xlfn.CHOOSECOLS(_xlpm.orows,3,7,6,10,9,8,11,23,12,17,24,25,26,27,28,29,30,32)))}

Sheet Repeater View
B2: Repeater View
B3: Repeater-by-repeater stage progress for one variant. Kitted = recorded against that REP number. Kitted* = covered by a contract-level quantity, shown against the earliest open REP positions; it is NOT a physical traceability link.
G4: Project | H4: Top code (ASP) | I4: System qty | J4: Built before plan | K4: Planned | L4: Weekly plan total | M4: Complete kits | N4: This week
B5: Variant | C5: E2A-R12P-T5-C | G5: {=IFERROR(INDEX(P_ProjName,_xlfn.XMATCH(1,(UPPER(P_Var)=UPPER($C$5))*(P_Valid=1))),"not in ASP")} | H5: {=IFERROR(INDEX(P_ProdId,_xlfn.XMATCH(1,(UPPER(P_Var)=UPPER($C$5))*(P_Valid=1))),"")} | I5: {=SUMIFS(P_System,P_Var,$C$5)} | J5: {=SUMIFS(P_System,P_Var,$C$5)-SUMIFS(P_Planned,P_Var,$C$5)} | K5: {=SUMIFS(P_Planned,P_Var,$C$5)} | L5: {=SUMIFS(P_WSum,P_Var,$C$5)} | M5: {=IF(COUNTIF(tblReq[Variant ID],$C$5)=0,"Assembly setup required",_xlfn.MINIFS(L_CovReps,L_Var,$C$5))} | N5: {=RIGHT(YEAR(ThisMon+3),2)&" W"&_xlfn.ISOWEEKNUM(ThisMon)}
G6: =IF(SUMIFS(P_WSum,P_Var,$C$5)<>SUMIFS(P_Planned,P_Var,$C$5),"Note: the weekly plan total differs from Planned Qty in the ASP - REPs beyond the weekly plan show 'Not in weekly plan'.","")
B8: Stage summary (contract level)
B9: Stage | E9: {=_xlfn.LET(_xlpm.rv,TRIM($C$5&""),_xlpm.rmk,(UPPER(TRIM(P_Var&""))=UPPER(_xlpm.rv))*(_xlpm.rv<>""),_xlpm.rsy,SUMPRODUCT(_xlpm.rmk,IFERROR(--P_System,0)),_xlpm.rpl,SUMPRODUCT(_xlpm.rmk,IFERROR(--P_Planned,0)),_xlpm.rb,_xlpm.rsy-_xlpm.rpl,_xlpm.res,_xlfn.SORTBY(tblStages[Stage],tblStages[Order]),_xlpm.rnst,COUNTIFS(tblReq[Variant ID],_xlpm.rv,tblReq[Stage],_xlpm.res),_xlpm.rstg,TRANSPOSE(_xlfn._xlws.FILTER(_xlpm.res,_xlpm.rnst>0,"")),_xlpm.rS,SUM(--(_xlpm.rnst>0)),_xlpm.rcm,_xlfn.MINIFS(L_CovReps,L_Var,_xlpm.rv,L_Stage,_xlpm.rstg),_xlpm.rsa,_xlfn.MAXIFS(L_StartReps,L_Var,_xlpm.rv,L_Stage,_xlpm.rstg),_xlpm.rsh,SUMIFS(L_Short,L_Var,_xlpm.rv,L_Stage,_xlpm.rstg),_xlpm.rn,_xlfn.SEQUENCE(MAX(_xlpm.rsy,1)),_xlpm.rem,(tblLog[Active]=1)*(UPPER(TRIM(tblLog[Record type]&""))="KITTING PROGRESS")*(UPPER(TRIM(tblLog[Variant ID]&""))=UPPER(_xlpm.rv))*(TRIM(tblLog[Assembly code]&"")="")*ISNUMBER(tblLog[REP from])*(IFERROR(--tblLog[REP from],0)>0),_xlpm.rhe,SUM(_xlpm.rem)>0,_xlpm.ref,_xlfn._xlws.FILTER(tblLog[REP from],_xlpm.rem,0),_xlpm.ret,_xlfn._xlws.FILTER(IF(ISNUMBER(tblLog[REP to]),tblLog[REP to],tblLog[REP from]),_xlpm.rem,0),_xlpm.rstx,_xlfn._xlws.FILTER(UPPER(TRIM(tblLog[Stage]&"")),_xlpm.rem,""),_xlpm.rA,IF(_xlpm.rhe,MMULT((_xlpm.rn>=TRANSPOSE(_xlpm.ref))*(_xlpm.rn<=TRANSPOSE(_xlpm.ret)),--(_xlpm.rstx=UPPER(_xlpm.rstg)))>0,(_xlpm.rn+_xlfn.SEQUENCE(1,_xlpm.rS))<0),_xlpm.rasg,MMULT(TRANSPOSE(_xlpm.rn^0),--_xlpm.rA),_xlpm.rpool,IF(_xlpm.rcm-_xlpm.rasg>0,_xlpm.rcm-_xlpm.rasg,0),IF(_xlpm.rS=0,"Assembly setup required",_xlfn.VSTACK(_xlpm.rstg,_xlpm.rcm,_xlpm.rasg,_xlpm.rpool,_xlpm.rsa-_xlpm.rcm,_xlpm.rsh)))}
B10: Complete kits (covered)
B11: Recorded against REP numbers
B12: Contract level, not assigned to a REP
B13: Partly kitted REPs
B14: Units without COOIS order
B16: Repeater by repeater
B17: {=_xlfn.LET(_xlpm.rv,TRIM($C$5&""),_xlpm.res,_xlfn.SORTBY(tblStages[Stage],tblStages[Order]),_xlpm.rnst,COUNTIFS(tblReq[Variant ID],_xlpm.rv,tblReq[Stage],_xlpm.res),IF(SUM(--(_xlpm.rnst>0))=0,"",_xlfn.HSTACK("REP","ASP week",TRANSPOSE(_xlfn._xlws.FILTER(_xlpm.res,_xlpm.rnst>0,"")),"Next kit to issue","Kit due week","Weeks left","Status")))}
B18: {=_xlfn.LET(_xlpm.rv,TRIM($C$5&""),_xlpm.rmk,(UPPER(TRIM(P_Var&""))=UPPER(_xlpm.rv))*(_xlpm.rv<>""),_xlpm.rsy,SUMPRODUCT(_xlpm.rmk,IFERROR(--P_System,0)),_xlpm.rpl,SUMPRODUCT(_xlpm.rmk,IFERROR(--P_Planned,0)),_xlpm.rb,_xlpm.rsy-_xlpm.rpl,_xlpm.res,_xlfn.SORTBY(tblStages[Stage],tblStages[Order]),_xlpm.rnst,COUNTIFS(tblReq[Variant ID],_xlpm.rv,tblReq[Stage],_xlpm.res),_xlpm.rstg,TRANSPOSE(_xlfn._xlws.FILTER(_xlpm.res,_xlpm.rnst>0,"")),_xlpm.rS,SUM(--(_xlpm.rnst>0)),_xlpm.rcm,_xlfn.MINIFS(L_CovReps,L_Var,_xlpm.rv,L_Stage,_xlpm.rstg),_xlpm.rsa,_xlfn.MAXIFS(L_StartReps,L_Var,_xlpm.rv,L_Stage,_xlpm.rstg),_xlpm.rsh,SUMIFS(L_Short,L_Var,_xlpm.rv,L_Stage,_xlpm.rstg),_xlpm.rn,_xlfn.SEQUENCE(MAX(_xlpm.rsy,1)),_xlpm.rem,(tblLog[Active]=1)*(UPPER(TRIM(tblLog[Record type]&""))="KITTING PROGRESS")*(UPPER(TRIM(tblLog[Variant ID]&""))=UPPER(_xlpm.rv))*(TRIM(tblLog[Assembly code]&"")="")*ISNUMBER(tblLog[REP from])*(IFERROR(--tblLog[REP from],0)>0),_xlpm.rhe,SUM(_xlpm.rem)>0,_xlpm.ref,_xlfn._xlws.FILTER(tblLog[REP from],_xlpm.rem,0),_xlpm.ret,_xlfn._xlws.FILTER(IF(ISNUMBER(tblLog[REP to]),tblLog[REP to],tblLog[REP from]),_xlpm.rem,0),_xlpm.rstx,_xlfn._xlws.FILTER(UPPER(TRIM(tblLog[Stage]&"")),_xlpm.rem,""),_xlpm.rA,IF(_xlpm.rhe,MMULT((_xlpm.rn>=TRANSPOSE(_xlpm.ref))*(_xlpm.rn<=TRANSPOSE(_xlpm.ret)),--(_xlpm.rstx=UPPER(_xlpm.rstg)))>0,(_xlpm.rn+_xlfn.SEQUENCE(1,_xlpm.rS))<0),_xlpm.rasg,MMULT(TRANSPOSE(_xlpm.rn^0),--_xlpm.rA),_xlpm.rpool,IF(_xlpm.rcm-_xlpm.rasg>0,_xlpm.rcm-_xlpm.rasg,0),_xlpm.relig,(_xlpm.rA=FALSE)*(_xlpm.rn>_xlpm.rb),_xlpm.rrk,MMULT(--(_xlpm.rn>=TRANSPOSE(_xlpm.rn)),_xlpm.relig),_xlpm.rcell,IF(_xlpm.rn<=_xlpm.rb,"Built",IF(_xlpm.rA,"Kitted",IF(_xlpm.rrk<=_xlpm.rpool,"Kitted*",IF(_xlpm.rrk<=_xlpm.rpool+_xlpm.rsa-_xlpm.rcm,"Part","")))),_xlpm.rnk,(_xlpm.rcell<>"Kitted")*(_xlpm.rcell<>"Kitted*"),_xlpm.rsc,MMULT(_xlpm.rnk*2^(_xlpm.rS-_xlfn.SEQUENCE(1,_xlpm.rS)),_xlfn.SEQUENCE(_xlpm.rS)^0),_xlpm.rfi,IF(_xlpm.rsc=0,0,_xlpm.rS-INT(LOG(IF(_xlpm.rsc=0,1,_xlpm.rsc),2)+0.000000001)),_xlpm.rnx,IF(_xlpm.rn<=_xlpm.rb,"",IF(_xlpm.rfi=0,"All kitted",INDEX(_xlpm.rstg,1,IF(_xlpm.rfi=0,1,_xlpm.rfi)))),_xlpm.rwk,MMULT(TRANSPOSE(_xlpm.rmk),IFERROR(--AspWeeks,0)),_xlpm.rnw,COLUMNS(_xlpm.rwk),_xlpm.rcum,MMULT(_xlpm.rwk,--(_xlfn.SEQUENCE(_xlpm.rnw)<=_xlfn.SEQUENCE(1,_xlpm.rnw))),_xlpm.ridx,IFERROR(_xlfn.XMATCH(_xlpm.rn-_xlpm.rb,_xlpm.rcum,1),0),_xlpm.rkm,IF(_xlpm.ridx=0,"",INDEX(WkKitMon,1,IF(_xlpm.ridx=0,1,_xlpm.ridx))),_xlpm.rwl,IF(_xlpm.rkm="","",ROUND((_xlpm.rkm-ThisMon)/7,0)),_xlpm.rstt,IF(_xlpm.rn<=_xlpm.rb,"Built before plan",IF(_xlpm.rfi=0,"All kitted",IF(_xlpm.rkm="","Not in weekly plan",IF(_xlpm.rwl<0,"Kit behind",IF(_xlpm.rwl=0,"Kit due this week","On track"))))),IF(_xlpm.rS=0,"Assembly setup required for this variant",IF(_xlpm.rsy<=0,"No repeaters for this variant in the current ASP",_xlfn.HSTACK(_xlpm.rn,IF((_xlpm.rn<=_xlpm.rb)+(_xlpm.ridx=0),"",INDEX(WkHdr,1,IF(_xlpm.ridx=0,1,_xlpm.ridx))),_xlpm.rcell,_xlpm.rnx,IF((_xlpm.rn<=_xlpm.rb)+(_xlpm.ridx=0),"",INDEX(WkKitLbl,1,IF(_xlpm.ridx=0,1,_xlpm.ridx))),IF(_xlpm.rn<=_xlpm.rb,"",_xlpm.rwl),_xlpm.rstt))))}

Sheet Record Kitting
B2: Record Kitting
B3: Step 1 describe what was physically kitted. Step 2 review the quantities. Step 3 copy the green block into the Kitting Log.
B4: No macros: confirming = copy the green block (Step 3) and Paste Special > Values on the first empty row of the Kitting Log table. Excel cannot append the rows for you or stop a second paste; the Kitting Log Check column flags duplicates.
B5: Step 1 - Kitting Progress entry | E5: Checks
B6: Entry date (blank = report date) | E6: {=_xlfn.LET(_xlpm.kv,TRIM($C$7&""),_xlpm.ks,TRIM($C$8&""),_xlpm.ka,TRIM($C$9&""),_xlpm.kr,N($C$10),_xlpm.kf,$C$11,_xlpm.kt,IF(ISNUMBER($C$12),$C$12,$C$11),_xlpm.km,(TRIM(tblReq[Variant ID]&"")=_xlpm.kv)*(TRIM(tblReq[Stage]&"")=_xlpm.ks)*(((_xlpm.ka="")+(TRIM(tblReq[Assembly code]&"")=_xlpm.ka))>0),_xlpm.knv,COUNTIF(tblReq[Variant ID],_xlpm.kv),_xlpm.kn,SUM(_xlpm.km),_xlpm.kcodes,_xlfn._xlws.FILTER(TRIM(tblReq[Assembly code]&""),_xlpm.km,""),_xlpm.kq,_xlfn._xlws.FILTER(IFERROR(--tblReq[Qty per REP],0),_xlpm.km,0),_xlpm.kst,_xlfn._xlws.FILTER(TRIM(tblReq[Stage]&""),_xlpm.km,""),_xlpm.krec,SUMIFS(L_Rec,L_Var,_xlpm.kv,L_Stage,_xlpm.kst,L_Code,_xlpm.kcodes),_xlpm.kal,SUMIFS(L_Alloc,L_Var,_xlpm.kv,L_Stage,_xlpm.kst,L_Code,_xlpm.kcodes),_xlpm.kneed,IF(_xlpm.krec+_xlpm.kr*_xlpm.kq-_xlpm.kal>0,_xlpm.krec+_xlpm.kr*_xlpm.kq-_xlpm.kal,0),_xlpm.kmsg,_xlfn.VSTACK(IF(_xlpm.kv="","Choose a variant.",""),IF(AND(_xlpm.kv<>"",_xlpm.knv=0),"Assembly setup required for this variant (Settings).",""),IF(AND(_xlpm.knv>0,_xlpm.kn=0),"This stage / assembly code is not set up for this variant.",""),IF(_xlpm.kr<0,"REPs kitted cannot be negative.",""),IF(AND(ISNUMBER(_xlpm.kf),_xlpm.kt<_xlpm.kf),"REP to is before REP from.",""),IF(AND(ISNUMBER(_xlpm.kf),_xlpm.kt>=_xlpm.kf,_xlpm.ka="",_xlpm.kr>0,ABS(_xlpm.kt-_xlpm.kf+1-_xlpm.kr)>0.000000001),"Warning: REP range covers "&(_xlpm.kt-_xlpm.kf+1)&" repeaters but REPs kitted is "&_xlpm.kr&".",""),IF(AND(_xlpm.kv<>"",COUNTIFS(P_Var,_xlpm.kv,P_Valid,1)=0),"Warning: variant not in the current ASP - entry allowed, flagged for review.",""),IF(AND(_xlpm.kn>0,_xlpm.kr=0),"No REPs kitted entered - only orders for earlier shortages will be proposed.",""),IF(COUNTIF($K$19:$K$200,">0")>0,"Warning: not enough unallocated COOIS orders - see Shortage after. The shortfall stays open.","")),_xlfn._xlws.FILTER(_xlpm.kmsg,_xlpm.kmsg<>"","No problems found"))}
B7: Variant ID (contract variant)
B8: Stage
B9: Assembly code (optional - blank = whole stage)
B10: REPs kitted (repeaters' worth)
B11: REP from (optional)
B12: REP to (optional)
B13: Note (e.g. management instruction)
B16: Step 2 - review quantities for this entry | N16: Step 3 - copy the green block (from N19, all rows) and Paste Values at the bottom of the Kitting Log
B17: Orders are proposed oldest release date first, then lowest order number, skipping allocated and CLSD orders. A shortfall stays open: when a later COOIS has more orders, enter the same variant and stage with REPs kitted = 0.
B18: Assembly code | C18: Description | D18: Qty per REP | E18: Units this entry | F18: Already recorded | G18: Already allocated | H18: Needs COOIS orders | I18: Orders available | J18: Orders proposed | K18: Shortage after | L18: Settings rows using code | N18: Entry ID | O18: Entry date | P18: Record type | Q18: Variant ID | R18: Stage | S18: Assembly code | T18: REPs kitted | U18: REP from | V18: REP to | W18: Order | X18: Order qty | Y18: Void | Z18: Void reason | AA18: Note
B19: {=_xlfn.LET(_xlpm.kv,TRIM($C$7&""),_xlpm.ks,TRIM($C$8&""),_xlpm.ka,TRIM($C$9&""),_xlpm.kr,N($C$10),_xlpm.kf,$C$11,_xlpm.kt,IF(ISNUMBER($C$12),$C$12,$C$11),_xlpm.km,(TRIM(tblReq[Variant ID]&"")=_xlpm.kv)*(TRIM(tblReq[Stage]&"")=_xlpm.ks)*(((_xlpm.ka="")+(TRIM(tblReq[Assembly code]&"")=_xlpm.ka))>0),_xlpm.knv,COUNTIF(tblReq[Variant ID],_xlpm.kv),_xlpm.kn,SUM(_xlpm.km),_xlpm.kcodes,_xlfn._xlws.FILTER(TRIM(tblReq[Assembly code]&""),_xlpm.km,""),_xlpm.kq,_xlfn._xlws.FILTER(IFERROR(--tblReq[Qty per REP],0),_xlpm.km,0),_xlpm.kst,_xlfn._xlws.FILTER(TRIM(tblReq[Stage]&""),_xlpm.km,""),_xlpm.krec,SUMIFS(L_Rec,L_Var,_xlpm.kv,L_Stage,_xlpm.kst,L_Code,_xlpm.kcodes),_xlpm.kal,SUMIFS(L_Alloc,L_Var,_xlpm.kv,L_Stage,_xlpm.kst,L_Code,_xlpm.kcodes),_xlpm.kneed,IF(_xlpm.krec+_xlpm.kr*_xlpm.kq-_xlpm.kal>0,_xlpm.krec+_xlpm.kr*_xlpm.kq-_xlpm.kal,0),_xlpm.kprop,SUMIFS($X$19:$X$5000,$P$19:$P$5000,"COOIS order",$S$19:$S$5000,_xlpm.kcodes),_xlpm.kav,SUMIFS(L_Avail,L_Var,_xlpm.kv,L_Stage,_xlpm.kst,L_Code,_xlpm.kcodes),IF(_xlpm.kn=0,"",_xlfn.HSTACK(_xlpm.kcodes,_xlfn._xlws.FILTER(tblReq[Assembly description]&"",_xlpm.km,""),_xlpm.kq,_xlpm.kr*_xlpm.kq,_xlpm.krec,_xlpm.kal,_xlpm.kneed,_xlpm.kav,_xlpm.kprop,IF(_xlpm.kneed-_xlpm.kprop>0,_xlpm.kneed-_xlpm.kprop,0),COUNTIF(tblReq[Assembly code],_xlpm.kcodes))))} | N19: {=_xlfn.LET(_xlpm.kv,TRIM($C$7&""),_xlpm.ks,TRIM($C$8&""),_xlpm.ka,TRIM($C$9&""),_xlpm.kr,N($C$10),_xlpm.kf,$C$11,_xlpm.kt,IF(ISNUMBER($C$12),$C$12,$C$11),_xlpm.km,(TRIM(tblReq[Variant ID]&"")=_xlpm.kv)*(TRIM(tblReq[Stage]&"")=_xlpm.ks)*(((_xlpm.ka="")+(TRIM(tblReq[Assembly code]&"")=_xlpm.ka))>0),_xlpm.knv,COUNTIF(tblReq[Variant ID],_xlpm.kv),_xlpm.kn,SUM(_xlpm.km),_xlpm.kcodes,_xlfn._xlws.FILTER(TRIM(tblReq[Assembly code]&""),_xlpm.km,""),_xlpm.kq,_xlfn._xlws.FILTER(IFERROR(--tblReq[Qty per REP],0),_xlpm.km,0),_xlpm.kst,_xlfn._xlws.FILTER(TRIM(tblReq[Stage]&""),_xlpm.km,""),_xlpm.krec,SUMIFS(L_Rec,L_Var,_xlpm.kv,L_Stage,_xlpm.kst,L_Code,_xlpm.kcodes),_xlpm.kal,SUMIFS(L_Alloc,L_Var,_xlpm.kv,L_Stage,_xlpm.kst,L_Code,_xlpm.kcodes),_xlpm.kneed,IF(_xlpm.krec+_xlpm.kr*_xlpm.kq-_xlpm.kal>0,_xlpm.krec+_xlpm.kr*_xlpm.kq-_xlpm.kal,0),_xlpm.kdt,IF(ISNUMBER($C$6),$C$6,RptDate),_xlpm.knote,$C$13&"",_xlpm.kblock,OR(_xlpm.kv="",_xlpm.knv=0,_xlpm.kn=0,_xlpm.kr<0,AND(ISNUMBER(_xlpm.kf),_xlpm.kt<_xlpm.kf)),_xlpm.rkey,IFERROR(Rv_Key&"",""),_xlpm.rmat,IFERROR(Rv_Mat&"",""),_xlpm.rqty,IFERROR(--Rv_Qty,0),_xlpm.rrel,IFERROR(--Rv_Rel,0),_xlpm.rent,IFERROR(Rv_Entry&"","x"),_xlpm.rcl,IFERROR(Rv_CLSD&"","Yes"),_xlpm.cmk,ISNUMBER(_xlfn.XMATCH(_xlpm.rmat,_xlpm.kcodes))*(_xlpm.rent="")*(_xlpm.rcl<>"Yes")*(_xlpm.rkey<>""),_xlpm.hasc,SUM(_xlpm.cmk)>0,_xlpm.cand,_xlfn.SORTBY(_xlfn._xlws.FILTER(_xlfn.HSTACK(_xlpm.rmat,_xlpm.rrel,_xlpm.rkey,_xlpm.rqty),_xlpm.cmk),_xlfn._xlws.FILTER(UPPER(_xlpm.rmat),_xlpm.cmk),1,_xlfn._xlws.FILTER(_xlpm.rrel,_xlpm.cmk),1,_xlfn._xlws.FILTER(_xlpm.rkey,_xlpm.cmk),1),_xlpm.cmt,INDEX(_xlpm.cand,,1),_xlpm.cqq,INDEX(_xlpm.cand,,4),_xlpm.cn,ROWS(_xlpm.cand),_xlpm.ccum,MMULT((_xlfn.SEQUENCE(_xlpm.cn)>=_xlfn.SEQUENCE(1,_xlpm.cn))*(_xlpm.cmt=TRANSPOSE(_xlpm.cmt)),_xlpm.cqq),_xlpm.cnd,_xlfn.XLOOKUP(_xlpm.cmt,_xlpm.kcodes,_xlpm.kneed,0),_xlpm.pick,IF(_xlpm.hasc,_xlfn._xlws.FILTER(_xlfn.EXPAND(_xlpm.cand,_xlpm.cn+1,,""),_xlfn.VSTACK((_xlpm.ccum-_xlpm.cqq)<_xlpm.cnd,FALSE),""),""),_xlpm.np,IF(ISERROR(INDEX(_xlpm.pick,1,1)),0,IF(INDEX(_xlpm.pick,1,1)="",0,ROWS(_xlpm.pick))),_xlpm.kid,"K"&TEXT(1+MAX(0,IFERROR(--MID(_xlfn._xlws.FILTER(tblLog[Entry ID]&"",LEFT(tblLog[Entry ID]&"",1)="K"),2,9),0)),"00000"),_xlpm.prow,_xlfn.HSTACK(_xlpm.kid,_xlpm.kdt,"Kitting Progress",_xlpm.kv,_xlpm.ks,_xlpm.ka,_xlpm.kr,IF(ISNUMBER(_xlpm.kf),_xlpm.kf,""),IF(ISNUMBER($C$12),$C$12,""),"","","","",_xlpm.knote),_xlpm.kone,_xlfn.SEQUENCE(MAX(_xlpm.np,1))^0,_xlpm.orow,_xlfn.HSTACK(IF(_xlpm.kone,_xlpm.kid),IF(_xlpm.kone,_xlpm.kdt),IF(_xlpm.kone,"COOIS order"),IF(_xlpm.kone,_xlpm.kv),IF(_xlpm.kone,_xlpm.ks),INDEX(_xlpm.pick,,1),IF(_xlpm.kone,""),IF(_xlpm.kone,""),IF(_xlpm.kone,""),INDEX(_xlpm.pick,,3),INDEX(_xlpm.pick,,4),IF(_xlpm.kone,""),IF(_xlpm.kone,""),IF(_xlpm.kone,"")),IF(_xlpm.kblock,"Nothing to paste - see Checks",IF(_xlpm.kr>0,IF(_xlpm.np>0,_xlfn.VSTACK(_xlpm.prow,_xlpm.orow),_xlpm.prow),IF(_xlpm.np>0,_xlpm.orow,"Nothing to paste - no REPs kitted and no orders needed"))))}

Sheet Kitting Log
B2: Kitting Log
B3: Every confirmed Kitting Progress entry and the COOIS orders allocated to it. Paste new rows from Record Kitting at the bottom. Never delete a row: to cancel an entry type Y in Void on any of its rows and give a reason.
A4: Columns A-N are typed or pasted. Grey columns (Order key, Active, Check) calculate automatically. Record type is "Kitting Progress" or "COOIS order".
A5: Entry ID | B5: Entry date | C5: Record type | D5: Variant ID | E5: Stage | F5: Assembly code | G5: REPs kitted | H5: REP from | I5: REP to | J5: Order | K5: Order qty | L5: Void | M5: Void reason | N5: Note | O5: Order key | P5: Active | Q5: Check
O6: =TRIM(tblLog[[#This Row],[Order]]&"") | P6: =IF(tblLog[[#This Row],[Entry ID]]="",IF(UPPER(TRIM(tblLog[[#This Row],[Void]]&""))="Y",0,1),IF(COUNTIFS(tblLog[Entry ID],tblLog[[#This Row],[Entry ID]],tblLog[Void],"Y")>0,0,1)) | Q6: =_xlfn.LET(_xlpm.cid,$A6&"",_xlpm.cty,UPPER(TRIM($C6&"")),_xlpm.cv,TRIM($D6&""),_xlpm.cs,TRIM($E6&""),_xlpm.ca,TRIM($F6&""),_xlpm.ck,$O6,_xlpm.cnv,COUNTIF(tblReq[Variant ID],_xlpm.cv),_xlpm.cns,COUNTIFS(tblReq[Variant ID],_xlpm.cv,tblReq[Stage],_xlpm.cs),_xlpm.cna,COUNTIFS(tblReq[Variant ID],_xlpm.cv,tblReq[Stage],_xlpm.cs,tblReq[Assembly code],_xlpm.ca),_xlpm.cnva,COUNTIFS(tblReq[Variant ID],_xlpm.cv,tblReq[Assembly code],_xlpm.ca),_xlpm.cdup,COUNTIFS(tblLog[Order key],_xlpm.ck,tblLog[Record type],"COOIS order",tblLog[Active],1),_xlpm.cri,_xlfn.XMATCH(_xlpm.ck,Rv_Key),_xlpm.crm,IF(ISNUMBER(_xlpm.cri),INDEX(Rv_Mat,_xlpm.cri)&"",""),_xlpm.crq,IF(ISNUMBER(_xlpm.cri),N(INDEX(Rv_Qty,_xlpm.cri)),0),_xlpm.crc,IF(ISNUMBER(_xlpm.cri),INDEX(Rv_CLSD,_xlpm.cri)&"",""),_xlpm.creps,N($G6),_xlpm.cf,$H6,_xlpm.ct,IF(ISNUMBER($I6),$I6,$H6),_xlpm.casp,COUNTIFS(P_Var,_xlpm.cv,P_Valid,1)>0,IF(_xlpm.cid="","",IF($P6=0,"Void",IF(_xlpm.cty="COOIS ORDER",IF(_xlpm.ck="","Order number missing",IF(_xlpm.cdup>1,"Duplicate allocation - fix",IF(ISNA(_xlpm.cri),"Not in current COOIS - review",IF(UPPER(_xlpm.crm)<>UPPER(_xlpm.ca),"Material changed - review",IF(_xlpm.crc="Yes","CLSD - review",IF(ABS(_xlpm.crq-N($K6))>0.000000001,"Qty changed - review",IF(_xlpm.cnva=0,"Assembly not set up for variant","OK"))))))),IF(_xlpm.cty="KITTING PROGRESS",IF(_xlpm.cnv=0,"Assembly setup required",IF(_xlpm.cns=0,"Stage not set up for variant",IF(AND(_xlpm.ca<>"",_xlpm.cna=0),"Assembly not in this stage",IF(NOT(_xlpm.creps>0),"REPs kitted missing",IF(ISNUMBER(_xlpm.cf),IF(_xlpm.ct<_xlpm.cf,"REP range invalid",IF(AND(_xlpm.ca="",ABS(_xlpm.ct-_xlpm.cf+1-_xlpm.creps)>0.000000001),"REP range differs from REPs kitted",IF(_xlpm.casp,"OK","Variant not in current ASP - review"))),IF(_xlpm.casp,"OK","Variant not in current ASP - review")))))),"Record type not recognised")))))

Sheet Settings
B2: Settings and assembly requirements
B3: Yellow cells and the two tables can be edited. Add rows at the bottom of a table; it grows automatically.
N4: Kitting stages (report column order)
B5: General | N5: Stage | O5: Order | P5: Description
B6: Report date (leave blank = today) | N6: LASA | O6: 1 | P6: Laser assembly
B7: Kit lead (weeks before ASP week) | C7: 3 | N7: PSB | O7: 2 | P7: Pump sharing box
B8: ASP file loaded | C8: ASP GH SME AUG 2026.xlsx | N8: POB | O8: 3 | P8: Passive optical box
B9: ASP loaded on | N9: OPF | O9: 4 | P9: OPF assembly
B10: COOIS file loaded | C10: export.xlsx | N10: Boat | O10: 5 | P10: Boat assembly
B11: COOIS loaded on | N11: Erbium | O11: 6 | P11: Erbium assemblies and spools
B14: Assembly requirements (one row per assembly line, quantity per ONE repeater) | N14: To add a stage later (e.g. Internal Unit, Housing): add a row here with its order number, then add its assembly lines to the requirements table.
B15: Contract (Project), exact variant (ASP Friendly_name), stage, assembly code and quantity per repeater. A variant with no rows here shows "Assembly setup required". Quantities reconstructed from pasted tables are marked for verification.
B17: Project | C17: Variant ID | D17: Top code | E17: Fibre pairs | F17: Stage | G17: Assembly code | H17: Assembly description | I17: Qty per REP | J17: Source | K17: Verified by / date
B18: E2A | C18: E2A-R4P-T1-C | D18: 92ERP04548A++ | E18: 4 | F18: LASA | G18: 92YLS00548BAA | H18: R5B LASER ASSEMBLY 4P BOAT 1 - E2A | I18: 1 | J18: Per-REP table supplied 29 Oct 2026 - Verify against original kitting sheet
B19: E2A | C19: E2A-R4P-T1-C | D19: 92ERP04548A++ | E19: 4 | F19: PSB | G19: 91YAF03404AAA | H19: R5B PSB SUB ASSEMBLY 4P-4FP | I19: 1 | J19: Per-REP table supplied 29 Oct 2026 - Verify against original kitting sheet
B20: E2A | C20: E2A-R4P-T1-C | D20: 92ERP04548A++ | E20: 4 | F20: POB | G20: 92YWS04548AAA | H20: R5B 4FP POB LUMENTUM SUB ASSEMBLY - E2A | I20: 1 | J20: Per-REP table supplied 29 Oct 2026 - Verify against original kitting sheet
B21: E2A | C21: E2A-R4P-T1-C | D21: 92ERP04548A++ | E21: 4 | F21: OPF | G21: 92YFD04548BAA | H21: R5B OPF ASSEMBLY (4P-4FP) BOAT 1 - E2A | I21: 1 | J21: Per-REP table supplied 29 Oct 2026 - Verify against original kitting sheet
B22: E2A | C22: E2A-R4P-T1-C | D22: 92ERP04548A++ | E22: 4 | F22: Boat | G22: 92UAP04548BAA | H22: R5B BOAT 1 ASSY (4P-4FP) | I22: 1 | J22: Per-REP table supplied 29 Oct 2026 - Verify against original kitting sheet
B23: E2A | C23: E2A-R4P-T1-C | D23: 92ERP04548A++ | E23: 4 | F23: Erbium | G23: 92YRA01548AAA | H23: R5B ERBIUM ASSEMBLY POSITION 1 | I23: 1 | J23: Per-REP table supplied 29 Oct 2026 - Verify against original kitting sheet
B24: E2A | C24: E2A-R4P-T1-C | D24: 92ERP04548A++ | E24: 4 | F24: Erbium | G24: 92YRA02548AAA | H24: R5B ERBIUM ASSEMBLY POSITION 2 | I24: 1 | J24: Per-REP table supplied 29 Oct 2026 - Verify against original kitting sheet
B25: E2A | C25: E2A-R4P-T1-C | D25: 92ERP04548A++ | E25: 4 | F25: Erbium | G25: 92YRA03548AAA | H25: R5B ERBIUM ASSEMBLY POSITION 3 | I25: 1 | J25: Per-REP table supplied 29 Oct 2026 - Verify against original kitting sheet
B26: E2A | C26: E2A-R4P-T1-C | D26: 92ERP04548A++ | E26: 4 | F26: Erbium | G26: 92YRA04548AAA | H26: R5B ERBIUM ASSEMBLY POSITION 4 | I26: 1 | J26: Per-REP table supplied 29 Oct 2026 - Verify against original kitting sheet
B27: E2A | C27: E2A-R4P-T1-C | D27: 92ERP04548A++ | E27: 4 | F27: Erbium | G27: 92RRA00548AAA | H27: R5B ERBIUM SPOOL ASSEMBLY - E2A | I27: 8 | J27: Per-REP table supplied 29 Oct 2026 - Verify against original kitting sheet
B28: E2A | C28: E2A-R12P-T5-C | D28: 92ERP12548A++ | E28: 12 | F28: LASA | G28: 92YLS00548BAA | H28: R5B LASER ASSEMBLY 4P BOAT 1 - E2A | I28: 1 | J28: Reconstructed from pasted kitting table - Verify against original kitting sheet
B29: E2A | C29: E2A-R12P-T5-C | D29: 92ERP12548A++ | E29: 12 | F29: LASA | G29: 92YLS00548BBA | H29: R5B LASER ASSEMBLY 4P BOAT 2/3 - E2A | I29: 2 | J29: Reconstructed from pasted kitting table - Verify against original kitting sheet
... B57: Wamkelekile | C57: WKE-R24P-T1-C | D57: 92ERP24543A++ | E57: 24 | F57: Erbium | G57: 92RRA00543AAA | H57: R5B ERBIUM SPOOL ASSEMBLY - WKE | I57: 48 | J57: Reconstructed from pasted kitting table - Verify against original kitting sheet

Sheet COOIS Review
B2: COOIS Review | H2: =COUNTIFS(Rv_Review,"Not allocated")+COUNTIFS(Rv_Review,"Shared code - no contract allocation") | I2: orders for configured codes not yet allocated
B3: Read-only view of the pasted COOIS export: SAP status tokens beside the tracker's allocation. CNF alone is never treated as kitted. | H3: =COUNTIFS(Rv_Review,"CLSD - review")+COUNTIFS(Rv_Review,"Material changed - review") | I3: orders needing review (CLSD / material changed)
B4: CNF can be recorded before physical picking, so the tracker never reads CNF as kitted. CLSD is shown for review; its cause is not confirmed by the status alone.
A5: Order | B5: Material Number | C5: Material description | D5: Order qty | E5: Release date (actual) | F5: Delivered qty | G5: System Status | H5: PCNF | I5: CNF | J5: DLV | K5: CLSD | L5: TECO | M5: Settings rows using code | N5: Allocated entry | O5: Allocated variant | P5: Review
A6: {=_xlfn.LET(_xlpm.craw,COOIS!$A$2:$O$20001,_xlpm.ckz,TRIM(INDEX(_xlpm.craw,,1)&""),_xlpm.ckeep,_xlpm.ckz<>"",_xlpm.cr,_xlfn._xlws.FILTER(_xlpm.craw,_xlpm.ckeep),_xlpm.ckk,_xlfn._xlws.FILTER(_xlpm.ckz,_xlpm.ckeep),_xlpm.cmat,TRIM(INDEX(_xlpm.cr,,3)&""),_xlpm.cst," "&UPPER(TRIM(INDEX(_xlpm.cr,,15)&""))&" ",_xlpm.cnv,COUNTIF(tblReq[Assembly code],_xlpm.cmat),_xlpm.clk,TRIM(tblLog[Order]&""),_xlpm.clm,(tblLog[Record type]="COOIS order")*(tblLog[Active]=1)*(_xlpm.clk<>""),_xlpm.cae,IFERROR(_xlfn.XLOOKUP(_xlpm.ckk,_xlfn._xlws.FILTER(_xlpm.clk,_xlpm.clm),_xlfn._xlws.FILTER(tblLog[Entry ID]&"",_xlpm.clm),""),""),_xlpm.cav,IFERROR(_xlfn.XLOOKUP(_xlpm.ckk,_xlfn._xlws.FILTER(_xlpm.clk,_xlpm.clm),_xlfn._xlws.FILTER(tblLog[Variant ID]&"",_xlpm.clm),""),""),_xlpm.caa,IFERROR(_xlfn.XLOOKUP(_xlpm.ckk,_xlfn._xlws.FILTER(_xlpm.clk,_xlpm.clm),_xlfn._xlws.FILTER(TRIM(tblLog[Assembly code]&""),_xlpm.clm),""),""),_xlpm.ccl,IF(ISNUMBER(SEARCH(" CLSD ",_xlpm.cst)),"Yes",""),_xlpm.crev,IF(_xlpm.ccl="Yes","CLSD - review",IF(_xlpm.cnv=0,"Code not in Settings",IF(_xlpm.cae="",IF(_xlpm.cnv>1,"Shared code - no contract allocation","Not allocated"),IF(UPPER(_xlpm.caa)<>UPPER(_xlpm.cmat),"Material changed - review","Allocated")))),_xlfn.HSTACK(_xlpm.ckk,_xlpm.cmat,INDEX(_xlpm.cr,,4)&"",IFERROR(--INDEX(_xlpm.cr,,7),0),IF(INDEX(_xlpm.cr,,9)="","",INDEX(_xlpm.cr,,9)),IFERROR(--INDEX(_xlpm.cr,,10),0),TRIM(INDEX(_xlpm.cr,,15)&""),IF(ISNUMBER(SEARCH(" PCNF ",_xlpm.cst)),"Yes",""),IF(ISNUMBER(SEARCH(" CNF ",_xlpm.cst)),"Yes",""),IF(ISNUMBER(SEARCH(" DLV ",_xlpm.cst)),"Yes",""),IF(ISNUMBER(SEARCH(" CLSD ",_xlpm.cst)),"Yes",""),IF(ISNUMBER(SEARCH(" TECO ",_xlpm.cst)),"Yes",""),_xlpm.cnv,_xlpm.cae,_xlpm.cav,_xlpm.crev))}

Sheet ASP
A1: Export time | B1: PLAN_VERSION_SWAN | C1: Project Id | D1: Project Name | E1: Product | F1: Planning code | G1: Prod Id | H1: Friendly_name | I1: Seabed Temp | J1: Body Type | K1: Nber FP | L1: System Qty | M1: Planned Qty | N1: Prod. progress | O1: ISO Week of DR2M_CALCULATED | P1: ISO Week of DR2M_DEMAND_DATE | Q1: 26 W30 | R1: 26 W31 | S1: 26 W32 | T1: 26 W33 | U1: 26 W34 | V1: 26 W35 | W1: 26 W36 | X1: 26 W37 | Y1: 26 W38 | Z1: 26 W39 | AA1: 26 W40 | AB1: 26 W41 | AC1: 26 W42 | AD1: 26 W43 | AE1: 26 W44 | AF1: 26 W45 | AG1: 26 W46 | AH1: 26 W47 | AI1: 26 W48 | AJ1: 26 W49 | AK1: 26 W50 | AL1: 26 W51 | AM1: 26 W52 | AN1: 26 W53 | AO1: 27 W1 | AP1: 27 W2 | AQ1: 27 W3 | AR1: 27 W4 | AS1: 27 W5 | AT1: 27 W6 | AU1: 27 W7 | AV1: 27 W8 | AW1: 27 W9 | AX1: 27 W10 | AY1: 27 W11 | AZ1: 27 W12 | BA1: 27 W13 | BB1: 27 W14 | BC1: 27 W15 | BD1: 27 W16 | BE1: 27 W17 | BF1: 27 W18 | BG1: 27 W19 | BH1: 27 W20 | BI1: 27 W21 | BJ1: 27 W22 | BK1: 27 W23 | BL1: 27 W24 | BM1: 27 W25 | BN1: 27 W26 | BO1: 27 W27 | BP1: 27 W28 | BQ1: 27 W29 | BR1: 27 W30 | BS1: 27 W31 | BT1: 27 W32 | BU1: 27 W33 | BV1: 27 W34 | BW1: 27 W35 | BX1: 27 W36 | BY1: 27 W37 | BZ1: 27 W38 | CA1: 27 W39 | CB1: 27 W40 | CC1: 27 W41 | CD1: 27 W42 | CE1: 27 W43 | CF1: 27 W44 | CG1: 27 W45 | CH1: 27 W46 | CI1: 27 W47 | CJ1: 27 W48 | CK1: 27 W49 | CL1: 27 W50 | CM1: 27 W51 | CN1: 27 W52 | CO1: 28 W1 | CP1: 28 W2 | CQ1: 28 W3 | CR1: 28 W4 | CS1: 28 W5 | CT1: 28 W6 | CU1: 28 W7 | CV1: 28 W8 | CW1: 28 W9 | CX1: 28 W10 | CY1: 28 W11 | CZ1: 28 W12 | DA1: 28 W13 | DB1: 28 W14 | DC1: 28 W15 | DD1: 28 W16 | DE1: 28 W17 | DF1: 28 W18 | DG1: 28 W19 | DH1: 28 W20 | DI1: 28 W21 | DJ1: 28 W22 | DK1: 28 W23 | DL1: 28 W24 | DM1: 28 W25 | DN1: 28 W26 | DO1: 28 W27 | DP1: 28 W28 | DQ1: 28 W29 | DR1: 28 W30 | DS1: 28 W31 | DT1: 28 W32 | DU1: 28 W33 | DV1: 28 W34 | DW1: 28 W35 | DX1: 28 W36 | DY1: 28 W37 | DZ1: 28 W38 | EA1: 28 W39 | EB1: 28 W40 | EC1: 28 W41 | ED1: 28 W42 | EE1: 28 W43 | EF1: 28 W44 | EG1: 28 W45 | EH1: 28 W46 | EI1: 28 W47 | EJ1: 28 W48 | EK1: 28 W49 | EL1: 28 W50 | EM1: 28 W51 | EN1: 28 W52 | EO1: 29 W1 | EP1: 29 W2 | EQ1: 29 W3 | ER1: 29 W4 | ES1: 29 W5 | ET1: 29 W6 | EU1: 29 W7 | EV1: 29 W8 | EW1: 29 W9 | EX1: 29 W10 | EY1: 29 W11 | EZ1: 29 W12 | FA1: 29 W13 | FB1: 29 W14 | FC1: 29 W15 | FD1: 29 W16 | FE1: 29 W17 | FF1: 29 W18 | FG1: 29 W19 | FH1: 29 W20 | FI1: 29 W21 | FJ1: 29 W22 | FK1: 29 W23 | FL1: 29 W24 | FM1: 29 W25 | FN1: 29 W26 | FO1: 29 W27 | FP1: 29 W28 | FQ1: 29 W29 | FR1: 29 W30 | FS1: 29 W31 | FT1: 29 W32 | FU1: 29 W33 | FV1: 29 W34 | FW1: 29 W35 | FX1: 29 W36 | FY1: 29 W37 | FZ1: 29 W38 | GA1: 29 W39 | GB1: 29 W40 | GC1: 29 W41 | GD1: 29 W42 | GE1: 29 W43 | GF1: 29 W44 | GG1: 29 W45 | GH1: 29 W46 | GI1: 29 W47 | GJ1: 29 W48 | GK1: 29 W49 | GL1: 29 W50 | GM1: 29 W51 | GN1: 29 W52 | GO1: 30 W1 | GP1: 30 W2 | GQ1: 30 W3 | GR1: 30 W4 | GS1: 30 W5 | GT1: 30 W6 | GU1: 30 W7 | GV1: 30 W8 | GW1: 30 W9 | GX1: 30 W10 | GY1: 30 W11 | GZ1: 30 W12 | HA1: 30 W13 | HB1: 30 W14 | HC1: 30 W15 | HD1: 30 W16 | HE1: 30 W17 | HF1: 30 W18 | HG1: 30 W19 | HH1: 30 W20 | HI1: 30 W21 | HJ1: 30 W22 | HK1: 30 W23 | HL1: 30 W24 | HM1: 30 W25 | HN1: 30 W26 | HO1: 30 W27 | HP1: 30 W28 | HQ1: 30 W29 | HR1: 30 W30 | HS1: 30 W31 | HT1: 30 W32 | HU1: 30 W33 | HV1: 30 W34 | HW1: 30 W35 | HX1: 30 W36 | HY1: 30 W37 | HZ1: 30 W38 | IA1: 30 W39 | IB1: 30 W40 | IC1: 30 W41 | ID1: 30 W42 | IE1: 30 W43 | IF1: 30 W44 | IG1: 30 W45 | IH1: 30 W46 | II1: 30 W47 | IJ1: 30 W48 | IK1: 30 W49 | IL1: 30 W50 | IM1: 30 W51 | IN1: 30 W52 | IO1: 31 W1 | IP1: 31 W2 | IQ1: 31 W3 | IR1: 31 W4 | IS1: 31 W5 | IT1: 31 W6 | IU1: 31 W7 | IV1: 31 W8 | IW1: 31 W9 | IX1: 31 W10 | IY1: 31 W11 | IZ1: 31 W12 | JA1: 31 W13 | JB1: 31 W14 | JC1: 31 W15 | JD1: 31 W16 | JE1: 31 W17 | JF1: 31 W18 | JG1: 31 W19 | JH1: 31 W20 | JI1: 31 W21 | JJ1: 31 W22 | JK1: 31 W23 | JL1: 31 W24 | JM1: 31 W25 | JN1: 31 W26 | JO1: 31 W27 | JP1: 31 W28 | JQ1: 31 W29 | JR1: 31 W30 | JS1: 31 W31 | JT1: 31 W32 | JU1: 31 W33 | JV1: 31 W34 | JW1: 31 W35 | JX1: 31 W36 | JY1: 31 W37 | JZ1: 31 W38 | KA1: 31 W39 | KB1: 31 W40 | KC1: 31 W41 | KD1: 31 W42 | KE1: 31 W43 | KF1: 31 W44 | KG1: 31 W45 | KH1: 31 W46 | KI1: 31 W47 | KJ1: 31 W48 | KK1: 31 W49 | KL1: 31 W50 | KM1: 31 W51 | KN1: 31 W52 | KO1: 32 W1 | KP1: 32 W2 | KQ1: 32 W3 | KR1: 32 W4 | KS1: 32 W5 | KT1: 32 W6 | KU1: 32 W7 | KV1: 32 W8 | KW1: 32 W9 | KX1: 32 W10 | KY1: 32 W11 | KZ1: 32 W12 | LA1: 32 W13 | LB1: 32 W14 | LC1: 32 W15 | LD1: 32 W16 | LE1: 32 W17 | LF1: 32 W18 | LG1: 32 W19 | LH1: 32 W20 | LI1: 32 W21 | LJ1: 32 W22 | LK1: 32 W23 | LL1: 32 W24 | LM1: 32 W25 | LN1: 32 W26 | LO1: 32 W27 | LP1: 32 W28 | LQ1: 32 W29 | LR1: 32 W30 | LS1: 32 W31 | LT1: 32 W32 | LU1: 32 W33 | LV1: 32 W34 | LW1: 32 W35 | LX1: 32 W36 | LY1: 32 W37 | LZ1: 32 W38 | MA1: 32 W39 | MB1: 32 W40 | MC1: 32 W41 | MD1: 32 W42 | ME1: 32 W43 | MF1: 32 W44 | MG1: 32 W45 | MH1: 32 W46 | MI1: 32 W47 | MJ1: 32 W48 | MK1: 32 W49 | ML1: 32 W50 | MM1: 32 W51 | MN1: 32 W52 | MO1: 32 W53 | MP1: 33 W1 | MQ1: 33 W2 | MR1: 33 W3 | MS1: 33 W4 | MT1: 33 W5 | MU1: 33 W6 | MV1: 33 W7 | MW1: 33 W8 | MX1: 33 W9 | MY1: 33 W10 | MZ1: 33 W11 | NA1: 33 W12 | NB1: 33 W13 | NC1: 33 W14 | ND1: 33 W15 | NE1: 33 W16 | NF1: 33 W17 | NG1: 33 W18 | NH1: 33 W19 | NI1: 33 W20 | NJ1: 33 W21 | NK1: 33 W22 | NL1: 33 W23 | NM1: 33 W24 | NN1: 33 W25 | NO1: 33 W26 | NP1: 33 W27 | NQ1: 33 W28 | NR1: 33 W29 | NS1: 33 W30 | NT1: 33 W31 | NU1: 33 W32 | NV1: 33 W33 | NW1: 33 W34 | NX1: 33 W35 | NY1: 33 W36 | NZ1: 33 W37 | OA1: 33 W38 | OB1: 33 W39 | OC1: 33 W40 | OD1: 33 W41 | OE1: 33 W42 | OF1: 33 W43 | OG1: 33 W44 | OH1: 33 W45 | OI1: 33 W46 | OJ1: 33 W47 | OK1: 33 W48 | OL1: 33 W49 | OM1: 33 W50 | ON1: 33 W51 | OO1: 33 W52 | OP1: 34 W1 | OQ1: 34 W2 | OR1: 34 W3 | OS1: 34 W4 | OT1: 34 W5 | OU1: 34 W6 | OV1: 34 W7 | OW1: 34 W8 | OX1: 34 W9 | OY1: 34 W10 | OZ1: 34 W11 | PA1: 34 W12 | PB1: 34 W13 | PC1: 34 W14 | PD1: 34 W15 | PE1: 34 W16 | PF1: 34 W17 | PG1: 34 W18 | PH1: 34 W19 | PI1: 34 W20 | PJ1: 34 W21 | PK1: 34 W22 | PL1: 34 W23 | PM1: 34 W24 | PN1: 34 W25 | PO1: 34 W26 | PP1: 34 W27 | PQ1: 34 W28 | PR1: 34 W29 | PS1: 34 W30 | PT1: 34 W31 | PU1: 34 W32 | PV1: 34 W33 | PW1: 34 W34 | PX1: 34 W35 | PY1: 34 W36 | PZ1: 34 W37 | QA1: 34 W38 | QB1: 34 W39 | QC1: 34 W40 | QD1: 34 W41 | QE1: 34 W42 | QF1: 34 W43 | QG1: 34 W44 | QH1: 34 W45 | QI1: 34 W46 | QJ1: 34 W47 | QK1: 34 W48 | QL1: 34 W49 | QM1: 34 W50 | QN1: 34 W51 | QO1: 34 W52

Sheet COOIS
A1: Order | B1: Order Type | C1: Material Number | D1: Material description | E1: Plant | F1: Batch | G1: Order quantity (GMEIN) | H1: Unit of measure (=GMEIN) | I1: Release date (actual) | J1: Delivered quantity (GMEIN) | K1: Created on | L1: Entered by | M1: Change date | N1: Last changed by | O1: System Status | P1: Planned opening date | Q1: Basic start date | R1: Basic finish date | S1: Firming indicator | T1: Results Analysis Key | U1: Processing group | V1: Requesting co. code | W1: Address Number | X1: Change Number | Y1: Changed at | Z1: Request. cost center | AA1: Priority | AB1: User Status | AC1: Request ID | AD1: Reservation/Purc.req | AE1: Expl. date rtg/BOM | AF1: Order category | AG1: Variance Key | AH1: Accounting Indicator | AI1: Exact break times | AJ1: Av.chk: committ.diff. | AK1: Av.chk: committ.fact. (PROZENT) | AL1: Company Code | AM1: Cost collector key | AN1: CO processing | AO1: Identical object | AP1: Update costs | AQ1: Apportionment Struct | AR1: Sequence number | AS1: MRP controller | AT1: Time created | AU1: Equity type | AV1: Production scheduler | AW1: SchedMargin key | AX1: Release period | AY1: Release date plan. | AZ1: Release date (scheduled) | BA1: Prog. release | BB1: Functional Area | BC1: Total scrap (GMEIN) | BD1: Confirmed finish date | BE1: Actual finish | BF1: Expected variance (GMEIN) | BG1: Forecast finish date | BH1: Prog.finish sched. | BI1: Actual finish date | BJ1: Scheduled finish date | BK1: Basic finish time | BL1: Scheduled fin. time | BM1: Business Area | BN1: Committed date | BO1: Forecast start date | BP1: Prog.start date | BQ1: Actual start time | BR1: Start date (sched) | BS1: ActualStartTime | BT1: Basic start time | BU1: Scheduled start time | BV1: Confirmed scrap (GMEIN) | BW1: Message Type | BX1: Confirmed quantity (GMEIN) | BY1: Investment profile | BZ1: Investment reason | CA1: JIB/JIBE Class | CB1: JIB/JIBE Subclass A | CC1: Costing Sheet | CD1: Version | CE1: Sales Order | CF1: Sales Order Item | CG1: Cstg variant actual | CH1: Cstg variant planned | CI1: Controlling Area | CJ1: Responsible CCtr | CK1: Settlement cost elem | CL1: Cost collector | CM1: Description | CN1: Type avail.chck | CO1: Proj. summ. MastData | CP1: Leading order | CQ1: Deletion flag | CR1: Long txt exists | CS1: Superior order | CT1: Production line | CU1: Planning ID 2 | CV1: ExpectYieldVariance (GMEIN) | CW1: Av.chk.messages | CX1: No planned costs | CY1: Change indicator | CZ1: Joint Venture Object Type | DA1: Routing change number | DB1: Routing valid from | DC1: Cost collector | DD1: Explosion date | DE1: Planner group | DF1: Routing group cnt. | DG1: Routing appl. | DH1: Routing material | DI1: Task list unit (=PLNME) | DJ1: Routing group | DK1: Task List Type | DL1: Routing lot size to (PLNME) | DM1: Routing lot size frm (PLNME) | DN1: Planning plant | DO1: Outline finish date | DP1: Finish | DQ1: Outline start date | DR1: Start | DS1: Item (SD) | DT1: Item (SD) | DU1: Profit Center | DV1: Max. problem class | DW1: Production Process No | DX1: Collective order | DY1: WBS Element | DZ1: Process category | EA1: Percent (=PROZENT) | EB1: Inspection Lot | EC1: Identification | ED1: Recovery Indicator | EE1: Reduction indicator | EF1: Reference order | EG1: Av.chk.result | EH1: Revision Level | EI1: Sales Document | EJ1: Rework qty (GMEIN) | EK1: Reservation | EL1: Refurbishment order | EM1: Confirmation number | EN1: BOM change number | EO1: Run schedule header | EP1: Base Unit of Measure (=SBMEH) | EQ1: BOM base quantity (SBMEH) | ER1: Controlling area | ES1: BOM valid from | ET1: Prod.Sched.Profile | EU1: Float after prod. | EV1: SchedFloatAfterProd. | EW1: Scale | EX1: BOM lot size to (SBMEH) | EY1: BOM lot size from (SBMEH) | EZ1: Special Stock | FA1: Location plant | FB1: Split status | FC1: Status Profile | FD1: BOM alternative | FE1: BOM usage | FF1: BOM material | FG1: BOM number | FH1: BOM status | FI1: BOM category | FJ1: Object ID | FK1: Scheduling note | FL1: Scheduling type | FM1: Scheduled on | FN1: Long Text Language | FO1: Envir. investment | FP1: Estimated costs (WAERS) | FQ1: Production Version | FR1: Committed qty (GMEIN) | FS1: Joint Venture | FT1: Float before prod. | FU1: SchedFloatBeforeProd. | FV1: Version | FW1: Currency | FX1: Overhead key

Sheet Calc
A1: Calculations - nothing to type on this sheet. Every result here can be traced to the ASP, COOIS, Settings or Kitting Log. | P1: ASP header | Q1: {=IF(ASP!$Q$1:$ALL$1="","",ASP!$Q$1:$ALL$1&"")}
P2: ASP week Monday | Q2: {=_xlfn.LET(_xlpm.wh,TRIM(ASP!$Q$1:$ALL$1&""),_xlpm.wy,2000+VALUE(LEFT(_xlpm.wh,FIND(" ",_xlpm.wh)-1)),_xlpm.ww,VALUE(MID(_xlpm.wh,FIND("W",UPPER(_xlpm.wh))+1,3)),_xlpm.wj,DATE(_xlpm.wy,1,4),IFERROR(_xlpm.wj-WEEKDAY(_xlpm.wj,2)+1+7*(_xlpm.ww-1),""))}
P3: Kit week Monday | Q3: {=_xlfn.LET(_xlpm.wm,IFERROR(Q2:ALL2+0,-1),IF(_xlpm.wm<0,"",_xlpm.wm-7*KitLead))}
P4: Kit week | Q4: {=_xlfn.LET(_xlpm.wd,IFERROR(Q3:ALL3+0,-1),IF(_xlpm.wd<0,"",RIGHT(YEAR(_xlpm.wd+3),2)&" W"&_xlfn.ISOWEEKNUM(_xlpm.wd)))}
BA6: Lists for dropdowns
A7: ASP row | B7: Project Id | C7: Project Name | D7: Product | E7: Planning code | F7: Prod Id | G7: Variant ID | H7: Seabed Temp | I7: Body Type | J7: Nber FP | K7: System Qty | L7: Planned Qty | M7: Prod. progress | N7: DR2M calc | O7: DR2M demand | P7: Weekly plan total | Q7: Due to kit by end of week | R7: Due to kit before this week | S7: Due to kit next 4 weeks | T7: Row in use | U7: Valid variant | V7: Requirement lines | W7: Built before plan | X7: Complete kits | Y7: Partly kitted | Z7: Remaining to kit | AA7: Progress | AB7: Due this week | AC7: Behind | AD7: Units without COOIS order | AE7: Top code differs | AF7: Status | AH7: Variant ID | AI7: Stage | AJ7: Stage order | AK7: Assembly code | AL7: Assembly description | AM7: Qty per REP | AN7: Recorded units | AO7: Allocated units | AP7: Covered units | AQ7: Units without COOIS order | AR7: Allocated beyond recorded | AS7: Complete REPs (line) | AT7: Started REPs (line) | AU7: Planned REPs | AV7: Units still to kit | AW7: Unallocated COOIS qty | AX7: Settings rows using code | BA7: Products | BB7: Projects | BC7: Variants (all) | BD7: Configured variants | BE7: Stages for entry | BF7: Codes for entry
A8: {=_xlfn.LET(_xlpm.pinfo,ASP!$C$2:$P$1000,_xlpm.pblk,IFERROR(--AspWeeks,0),_xlpm.pkm,WkKitMon,_xlpm.pone,_xlfn.SEQUENCE(COLUMNS(_xlpm.pblk),1,1,0),_xlfn.HSTACK(_xlfn.SEQUENCE(ROWS(_xlpm.pinfo),1,2),IF(_xlpm.pinfo="","",_xlpm.pinfo),MMULT(_xlpm.pblk,_xlpm.pone),MMULT(_xlpm.pblk,TRANSPOSE(--(_xlpm.pkm<=ThisMon))),MMULT(_xlpm.pblk,TRANSPOSE(--(_xlpm.pkm<ThisMon))),MMULT(_xlpm.pblk,TRANSPOSE((_xlpm.pkm>ThisMon)*(_xlpm.pkm<=ThisMon+28)))))} | T8: {=_xlfn.LET(_xlpm.qfr,TRIM($G$8:$G$1006&""),_xlpm.qpr,$D$8:$D$1006&"",_xlpm.qok,($B$8:$B$1006&$C$8:$C$1006&_xlpm.qpr&_xlpm.qfr&$F$8:$F$1006)<>"",_xlpm.qva,(_xlpm.qfr<>"")*(UPPER(_xlpm.qfr)<>"NA")*(UPPER(_xlpm.qfr)<>"N/A"),_xlpm.qnl,IF(_xlpm.qva,COUNTIF(tblReq[Variant ID],_xlpm.qfr),0),_xlpm.qsy,IFERROR(--$K$8:$K$1006,0),_xlpm.qpl,IFERROR(--$L$8:$L$1006,0),_xlpm.qcm,_xlfn.MINIFS(L_CovReps,L_Var,_xlpm.qfr),_xlpm.qcz,IF(_xlpm.qnl>0,_xlpm.qcm,0),_xlpm.qpa,_xlfn.MAXIFS(L_StartReps,L_Var,_xlpm.qfr)-_xlpm.qcz,_xlpm.qde,$Q$8:$Q$1006,_xlpm.qdb,$R$8:$R$1006,_xlpm.qmx,IF(_xlpm.qcz>_xlpm.qdb,_xlpm.qcz,_xlpm.qdb),_xlpm.qdu,IF(_xlpm.qde-_xlpm.qmx>0,_xlpm.qde-_xlpm.qmx,0),_xlpm.qbe,IF(_xlpm.qdb-_xlpm.qcz>0,_xlpm.qdb-_xlpm.qcz,0),_xlpm.qtp,IFERROR(_xlfn.XLOOKUP(_xlpm.qfr,tblReq[Variant ID],TRIM(tblReq[Top code]&"")),""),_xlpm.qtd,(_xlpm.qnl>0)*(UPPER(_xlpm.qtp)<>UPPER(TRIM($F$8:$F$1006&""))),_xlpm.qst,IF(_xlpm.qok=0,"",IF(_xlpm.qva=0,"No variant ID in ASP",IF(_xlpm.qnl=0,"Assembly setup required",IF(_xlpm.qtd,"Top code differs - review",IF(_xlpm.qpl<=0,"No plan quantity",IF(_xlpm.qcz>=_xlpm.qpl,"All kitted",IF(_xlpm.qbe>0,"Kit behind",IF(_xlpm.qdu>0,"Kit due this week","On track")))))))),_xlfn.HSTACK(--_xlpm.qok,_xlpm.qva,_xlpm.qnl,_xlpm.qsy-_xlpm.qpl,IF(_xlpm.qnl>0,_xlpm.qcm,""),IF(_xlpm.qnl>0,_xlpm.qpa,""),IF(_xlpm.qnl>0,IF(_xlpm.qpl-_xlpm.qcz>0,_xlpm.qpl-_xlpm.qcz,0),""),IF((_xlpm.qnl>0)*(_xlpm.qpl>0),_xlpm.qcz/IF(_xlpm.qpl=0,1,_xlpm.qpl),"not available"),IF(_xlpm.qnl>0,_xlpm.qdu,""),IF(_xlpm.qnl>0,_xlpm.qbe,""),IF(_xlpm.qnl>0,SUMIFS(L_Short,L_Var,_xlpm.qfr),""),--_xlpm.qtd,_xlpm.qst))} | AH8: {=_xlfn.LET(_xlpm.lv,TRIM(tblReq[Variant ID]&""),_xlpm.ls,TRIM(tblReq[Stage]&""),_xlpm.lc,TRIM(tblReq[Assembly code]&""),_xlpm.lq,IFERROR(--tblReq[Qty per REP],0),_xlpm.lok,_xlpm.lv<>"",_xlpm.lso,IFERROR(_xlfn.XLOOKUP(_xlpm.ls,tblStages[Stage],tblStages[Order]),""),_xlpm.lrw,SUMIFS(tblLog[REPs kitted],tblLog[Record type],"Kitting Progress",tblLog[Variant ID],_xlpm.lv,tblLog[Stage],_xlpm.ls,tblLog[Assembly code],"",tblLog[Active],1),_xlpm.lrl,SUMIFS(tblLog[REPs kitted],tblLog[Record type],"Kitting Progress",tblLog[Variant ID],_xlpm.lv,tblLog[Stage],_xlpm.ls,tblLog[Assembly code],_xlpm.lc,tblLog[Active],1),_xlpm.lrec,(_xlpm.lrw+_xlpm.lrl)*_xlpm.lq,_xlpm.lal,SUMIFS(tblLog[Order qty],tblLog[Record type],"COOIS order",tblLog[Variant ID],_xlpm.lv,tblLog[Assembly code],_xlpm.lc,tblLog[Active],1),_xlpm.lcov,IF(_xlpm.lrec<_xlpm.lal,_xlpm.lrec,_xlpm.lal),_xlpm.lcr,IF(_xlpm.lq>0,INT(_xlpm.lcov/IF(_xlpm.lq=0,1,_xlpm.lq)+0.000000001),0),_xlpm.lsr,IF(_xlpm.lq>0,-INT(-_xlpm.lcov/IF(_xlpm.lq=0,1,_xlpm.lq)+0.000000001),0),_xlpm.lpl,SUMIFS(P_Planned,P_Var,_xlpm.lv),_xlpm.lav,SUMIFS(Rv_Qty,Rv_Mat,_xlpm.lc,Rv_Entry,"",Rv_CLSD,""),_xlfn._xlws.FILTER(_xlfn.EXPAND(_xlfn.HSTACK(_xlpm.lv,_xlpm.ls,_xlpm.lso,_xlpm.lc,tblReq[Assembly description]&"",_xlpm.lq,_xlpm.lrec,_xlpm.lal,_xlpm.lcov,_xlpm.lrec-_xlpm.lcov,_xlpm.lal-_xlpm.lcov,_xlpm.lcr,_xlpm.lsr,_xlpm.lpl,IF(_xlpm.lpl*_xlpm.lq-_xlpm.lcov>0,_xlpm.lpl*_xlpm.lq-_xlpm.lcov,0),_xlpm.lav,COUNTIF(tblReq[Assembly code],_xlpm.lc)),ROWS(_xlpm.lv)+1,,""),_xlfn.VSTACK(_xlpm.lok,FALSE),""))} | BA8: {=IFERROR(_xlfn._xlws.SORT(_xlfn.UNIQUE(_xlfn._xlws.FILTER(P_Product,(P_Product<>"")*(P_RowOK=1)))),"REPEATERS")} | BB8: {=IFERROR(_xlfn.VSTACK("All",_xlfn._xlws.SORT(_xlfn.UNIQUE(_xlfn._xlws.FILTER(P_ProjName,(UPPER(P_Product)=UPPER(Dashboard!$C$5))*(P_ProjName<>""))))),"All")} | BC8: {=IFERROR(_xlfn.VSTACK("All",_xlfn._xlws.SORT(_xlfn.UNIQUE(_xlfn._xlws.FILTER(P_Var,(UPPER(P_Product)=UPPER(Dashboard!$C$5))*(P_Valid=1)*((Dashboard!$F$5="All")+(Dashboard!$F$5="")+(P_ProjName=Dashboard!$F$5)>0))))),"All")} | BD8: {=IFERROR(_xlfn._xlws.SORT(_xlfn.UNIQUE(_xlfn._xlws.FILTER(TRIM(tblReq[Variant ID]&""),TRIM(tblReq[Variant ID]&"")<>""))),"(none)")} | BE8: {=_xlfn.LET(_xlpm.es,_xlfn.SORTBY(tblStages[Stage],tblStages[Order]),_xlfn._xlws.FILTER(_xlpm.es,COUNTIFS(tblReq[Variant ID],'Record Kitting'!$C$7,tblReq[Stage],_xlpm.es)>0,_xlpm.es))} | BF8: {=_xlfn.VSTACK("",_xlfn._xlws.FILTER(tblReq[Assembly code],(tblReq[Variant ID]='Record Kitting'!$C$7)*(tblReq[Stage]='Record Kitting'!$C$8),""))}
